Workbook

Sheet 문서 개요
A2: 《Hero Influence》 전투 데이터 테이블
B4: 수정 날짜 | C4: 버전 | D4: 담당자 | E4: 수정 내역 | F4: 비고
B5: 46108 | C5: V1.0 | D5: 강현재 | E5: 아군 및 적군 유닛 임시 스테이터스 기입, 직업 스킬 기획
B6: 46114 | C6: V1.1 | D6: 강현재 | E6: 성장 시스템 및 테이블 필드 정의
B7: 46115 | C7: V1.2 | D7: 강현재 | E7: 무기 및 무기 스킬 콘텐츠
B8: 46119 | C8: V1.3 | D8: 강현재 | E8: 1. 복수 스킬 타깃 판정용 필드 추가: 스킬 복수 대상, 스킬 복수 대상 타입, 스킬 복수 대상 수 2. 적군 유닛 시트 및 필드 정의 추가: 경험치, 드롭 아이템 인덱스, 드롭 수량, 드롭 확률
B9: 46120 | C9: V2.0 | D9: 강현재 | E9: 1. 유닛 수 추가 → 단계별 스테이터스 정의 2. 스탯 시뮬레이터 재생성
B10: 46121 | C10: V2.1 | D10: 강현재 | E10: 3. 성장 시스템 수정 (유닛/유닛 그룹 분화 반영) 4. 적군 유닛 → 적군 유닛 그룹 개편 5. 1:1 전투 시뮬레이터
B11: 46125 | C11: V3.1 | D11: 강현재 | E11: 적 파티 AI 시트 추가
B12: 46132 | C12: V4.0 | D12: 강현재 | E12: I.P 시스템 추가 및 이에 따른 아군 유닛 스테이터스 구조 변경 1) 유닛-유닛그룹-파티 → 유닛-파티 구조 복귀 2) 성장 시스템 개편 3) 아군 유닛, 적군 유닛, 스탯 시뮬레이터, 전투 시뮬레이터 반영 및 기초 밸런스 4) 적군 파티 AI 간략화
B13: 46133 | C13: V4.1 | D13: 강현재 | E13: 스킬 코스트 추가
B14: 46133 | C14: V4.2 | D14: 강현재 | E14: 스킬 사정거리 라인 추가
B15: 46141 | C15: V4.3 | D15: 강현재 | E15: 적군 AI 시트 보류 용어 수정
B16: 46149 | C16: V4.4 | D16: 강현재 | E16: 1) 적 시트 스킬 사정거리 라인 추가 2) 아군 유닛 시트 레벨별 스테이터스 추가 3) 직업 스킬 효과 부활 2 추가 4) 열 전체 스킬용 복수 대상 타깃 번호 9번 추가
... B22: 46196 | C22: V7.2 | D22: 강현재 | E22: 자동 결과 공식 추가
A24: 1. 문서 목적
B25: 본 문서는 《Hero Influence》의 전투 시스템 구현 및 밸런싱에 필요한 핵심 데이터를 정의하는 것을 목적으로 한다. 1) 전투 시스템 구현에 필요한 데이터 기준을 정리한다. 2) 성장, 스킬, 무기, I.P 등 전투 관련 구조를 데이터 테이블 형태로 관리한다. 3) 전투 시뮬레이션과 밸런스 조정에 필요한 공통 참조 기준을 제공한다.
A27: 2. 문서 기획 의도
B28: 본 데이터 테이블은 전투 밸런스를 통해 플레이어의 진행 동선을 유도하고, 전투 중심 플레이와 자원 확보 중심 플레이 사이의 선택을 제공하여 전략적 판단의 재미를 강화한다. 1) 전투 난이도와 보상 구조를 조정하여, 플레이어가 기획된 동선과 성장 흐름을 따라가도록 유도한다. 2) 전투 중심 플레이와 자원 확보 중심 플레이의 효율을 비교할 수 있도록 하여, 플레이어가 어떤 방식으로 성장할지 판단하도록 한다. 3) 스킬 강화, 무기 강화, I.P 사용에 따른 전투 성능 변화를 조정하여, 자원 투자 선택이 전투 결과에 유의미하게 반영되도록 한다. 4) 전투 시뮬레이션을 통해 특정 플레이 방식이 과도하게 유리하거나 불리해지지 않도록 밸런스를 검증한다.
A30: 3. 문서 범위
B31: 1) 스테이터스 정의 및 계산 규칙 | E31: ‘스테이터스’ 시트
B32: 2) 성장 시스템 정의, 랭크별 스테이터스 증가 규칙, 필요 경험치 | E32: ‘성장 시스템’ 시트
B33: 3) 아군 직업별 기본 스테이터스 및 레벨별 스테이터스 | E33: ‘아군 유닛’ 시트
B34: 4) 적군 스테이터스, 스킬, 보상 경험치 | E34: ‘적군 유닛’ 시트
B35: 5) 직업 스킬 데이터 및 스킬 레벨별 계수 | E35: ‘직업 스킬’ 시트
B36: 6) 무기 데이터, 무기 레벨별 보너스 스테이터스, 무기 스킬 레벨별 계수 | E36: ‘무기’ 시트
B37: 7) 랭크별 스테이터스 변동 계산 | E37: ‘스탯 시뮬레이터’ 시트
B38: 8) 전투 대미지 및 전투 결과 계산 | E38: ‘전투 시뮬레이터’ 시트
A40: 4. 문서 대상
B41: 본 문서는 다음 인원을 대상으로 한다. 1) 전투 시스템 기획자 2) 전투 시스템 프로그래머 3) 밸런스 담당 기획자

Sheet 스테이터스
A2: 1. 유닛 단위 정의
B3: 1) 유닛
B4: 유닛(Unit)은 전투에서 직접 행동하는 최소 단위이며 (V2.0-3.0의 유닛-유닛 그룹-파티 구조에서 V1.0의 유닛-파티 구조로 복귀한다), 각 유닛은 랭크(기존 레벨 개념)에 따라 성장하는 독립적인 스테이터스(체력, 공격력, 방어력, 치명타율, 반격률, 피해 경감률, 스피드)와 호감도(기존 유닛수 대체)를 가진다. 유닛은 클래스에 따라 외형 및 보유 스킬, 역할이 구분된다.
B6: 2) 파티
B7: 파티는 2×3 슬롯으로 구성되며, 프로토타입 기준으로 플레이어 파티는 4개의 유닛 + 2개의 빈 슬롯으로 구성된다. 인카운터 전투는 1:1 파티 단위로 수행된다. 각 유닛의 유닛 공격력과 유닛 체력, 유닛 방어력을 합산해 파티 전투력을 표시한다. 필드 이동 시 파티 단위로 이동하게 된다.
A9: 2. 단위별 스테이터스
B10: 1) 유닛 스테이터스
B11: 스테이터스명 | C11: 설명 | D11: 규칙
B12: 유닛 랭크 | C12: 유닛이 경험치를 통해 올릴 수 있는 등급 A-Z 사이 대문자 알파벳으로 표시한다. 유닛이 다음 랭크에 도달할 때마다 다음 중 일부 효과가 적용된다. (구체적인 성장 공식 및 랭크별 받는 효과는 성장 시스템 시트 참조) 1. 일부 유닛 스테이터스(최대 체력, 공격력, 방어력)에 랭크업 보정치를 추가 2. 특정 랭크에 신규 직업 스킬 습득 3. 특정 랭크마다 유닛 최대 I.P 증가 | D12: 매 랭크 업 시, 유닛 스테이터스 증가 Lv1 직업 스킬 (기본 스킬) Lv2 최대 I.P 증가 Lv3 직업 스킬 Lv4 최대 I.P 증가 Lv5 직업 스킬 Lv6 최대 I.P 증가 Lv7 직업 스킬 Lv8 최대 I.P 증가 Lv9 최대 I.P 증가 Lv10 직업 스킬 Lv11 최대 I.P 증가 Lv12 직업 스킬 Lv13 최대 I.P 증가 Lv14 최대 I.P 증가 Lv15 직업 스킬
B13: 유닛 체력 | C13: 유닛이 생존하기 위해 지닌 체력 | D13: * 유닛 최대 체력 > 0 * 유닛 최대 체력 > 유닛 현재 체력 * 유닛 현재 체력이 0일 경우 리타이어 상태 전환
B14: 유닛 공격력 | C14: 유닛이 지닌 공격력, 유닛 대미지 계산에 사용된다 | D14: * 기본 피해량 = (공격 유닛 공격력 - 피격 유닛 방어력) × 스킬 계수 × 유닛 I.P 보정
B15: 유닛 방어력 | C15: 유닛이 지닌 방어력, 유닛 대미지 계산에 사용된다
B16: 유닛 I.P | C16: I.P(Influence)는 각 유닛이 보유하는 전투 자원으로, 시민의 지지를 통해 형성된 전투력의 크기를 나타낸다. 호감도는 유닛 단위로 개별 관리되며, 전투 및 탐사 과정에서 증가하거나 감소한다. 현재 호감도는 해당 유닛의 전투 성능에 직접적으로 영향을 주며, 스킬 계수에 반영된다. | D16: * 유닛 최대 호감도 > 유닛 현재 호감도 * 기본 유닛 호감도 100(현재)/200(최대) * 호감도 계수 = 현재 호감도 / 100 예시) 기본 I.P 100일 때 호감도 보정 100% 0일 때 호감도 보정 0%, 200일 때 호감도 보정 200% * 유닛 현재 호감도가 0일 경우, 호감도 소모 스킬 사용 불가
B17: 치명타율 | C17: 유닛이 공격했을 때, 치명타가 발생할 확률 | D17: * 치명타 발생시, 주는 대미지 증가: 기본 피해량의 150% 대미지 증가 * 치명타율 최대 70%
B18: 반격율 | C18: 전열 유닛이 공격을 받았을 때 반격할 확률 | D18: * 반격 발생시, 상대에게 반격자 공격력의 50% 대미지 증가 * 반격률 최대 70%
B19: 피해 경감율 | C19: 후열 유닛이 공격을 받았을 때 대미지를 경감시킬 확률 | D19: * 피해 경감 발생 시, 받는 피해량을 50% 감소 * 피해경감율 최대 70%
B20: 스피드 | C20: 전투 시 유닛의 행동 순서를 1차적으로 정하기 위한 기준값 | D20: * 0 ~ 4 범위 내 정수
B22: 2) 파티 스테이터스 (인카운트 전투 진입 전 적군 파티의 전투력을 가늠하기 위해 사용)
B23: 스테이터스명 | C23: 설명 | D23: 규칙
B24: 파티 체력 | C24: 파티 내 모든 유닛의 현재 체력 합 | D24: * 모든 유닛의 현재 유닛 체력 합 × 파티 체력 계수(기본값 1)
B25: 파티 공격력 | C25: 파티 내 모든 유닛의 공격력 합, 탐험 필드 내 NPC간 전투에서 필드 기본 피해량 계산에 사용된다 | D25: * 모든 유닛의 현재 유닛 공격력 합 × 파티 공격력 계수(기본값 1)
B26: 파티 방어력 | C26: 파티 내 모든 유닛의 방어력 합 | D26: * 모든 유닛의 현재 유닛 방어력 합 × 파티 방어력 계수(기본값 1)
B27: 파티 전투력 | C27: 플레이어가 상대와 자신의 전력차를 가늠해 볼 수 있도록 파티 내 유닛들의 강함을 숫자로 표기 | D27: * 파티 전투력 = 파티 체력 + 파티 공격력 + 파티 방어력

Sheet 성장 시스템
A2: 1. 성장 시스템 방향성
B3: 《Hero Influence》의 전투는 게임의 핵심인 4X (탐험, 확장, 성장, 섬멸) 진행 중 발생하는 턴제 전투가 전체 게임 흐름을 크게 끊지 않도록 하는 것을 목표로 한다. 이에 따라 성장 시스템은 다음 4가지 방향성을 가진다. 1) 초반에는 1~2회, 중후반에는 2~3회의 인카운터 전투를 통해 유닛이 랭크업하도록 설계 2) 전투 템포를 유지하기 위해 체력 및 방어력의 성장률은 완만하게 설계 3) 공격력이 체력보다 상대적으로 빠르게 성장하도록 설계 4) 클래스 간 역할 구분은 유지하되, 모든 클래스가 전열과 후열 모두에서 정밀의 코어용 가능하도록 설계 - 동일 랭크 적 기준, 최소 1회의 공격을 생존할 수 있도록 체력 및 체력 성장률 설계 - 동일 랭크 적 기준, 1회 공격 시 최소 피해량이 대상 최대 체력의 10~25% 이상이 되도록 설계 3) 유닛의 기본 전투 성능은 랭크에 따라 결정되지만, 실제 전투 결과에 미치는 영향은 I.P가 더 크게 작용하도록 설계
A5: 2. 랭크업 스테이터스 증가 규칙
B6: 1) 랭크업을 해도 수치가 변하지 않는 스테이터스는 다음과 같다. - 치명타율 - 반격률 - 피해 경감율 - 스피드 (상기 스테이터스는 랭크업으로는 증가하지 않으며, 장비 착용, 진형 효과, 스킬 효과 등으로만 변동) 2) 랭크업에 따라 수치가 증가하는 스테이터스는 다음과 같다. - 유닛 최대 체력 - 유닛 공격력 - 유닛 방어력 3) 유닛 랭크업 시, 유닛의 현재 체력은 최대 체력으로 회복된다. 4) 지정된 랭크 달성 직후, 최대 I.P가 증가한다. (오르는 랭크 시점 및 양은 전투 경험치 테이블 참조) 5) 유닛 시민 현재 호감도는 증가하지 않으며, 기존 수치를 그대로 유지한다.
A8: 3. 유닛 랭크업 추가 스테이터스
B9: 1) 유닛 스테이터스는 랭크가 오를 때마다 랭크업 기본 보정치 + 클래스별 추가 보정치가 추가된다. 2) 랭크업 추가 보정치는 클래스마다 오르는 스테이터스 수치가 다르나 올라가는 총합은 동일하다. 3) 예시 - F랭크 가디언, 최대 체력 10 - E랭크 가디언, 최대 체력 = 10 + 1 (기본 보정치) + 3 (추가 보정치) = 14 - D랭크 가디언, 최대 체력 = 14 + 1 + 3 = 18
B11: 기본 보정치 | C11: 유닛 최대 체력 | D11: 유닛 공격력 | E11: 유닛 방어력
C12: 1 | D12: 1 | E12: 1
B14: 클래스별 추가 보정치 | C14: 유닛 최대 체력 | D14: 유닛 공격력 | E14: 유닛 방어력
B15: 가디언 | C15: 2 | D15: 1 | E15: 0
B16: 블래스터 | C16: 0 | D16: 2 | E16: 0
B17: 스트라이커 | C17: 1 | D17: 1 | E17: 0
B18: 서포터 | C18: 1 | D18: 0 | E18: 1
B19: 파이터 | C19: 0 | D19: 1 | E19: 1
A21: 4. 경험치 획득 규칙
B22: 1) 경험치는 인카운트 전투 승리 시 획득한다. (전투 패배 시에는 획득하지 않는다.) 2) 얻는 총 경험치는 쓰러트린 모든 적의 경험치 합산이다. 3) 전투 승리 시 생존 상태의 모든 유닛은 총 경험치 ÷ 파티 내 전체 유닛 수(4) 만큼의 경험치를 균등하게 나눠 얻는다. 4) 딱 나눠 떨어지지 않을 경우, 남은 경험치는 누적 경험치가 가장 낮은 임의의 유닛에게 돌아간다. 5) 리타이어한 유닛 몫의 경험치는 상실된다. (의도: 특정 유닛을 의도적으로 리타이어 상태로 유지하여 경험치를 집중시키는 플레이를 방지하기 위함) 예시) 게임 시작 시 4인 파티 중 생존 유닛 3명 총 경험치: 30 A (생존): 7 B (생존): 7 C (생존): 9 (7 + 잔여 경함치 2) D (리타이어): 0 (경험치 7 상실)
S27: 빌런 수 최소값(2) → 랭크업당 2~6번 전투
S38: 빌런 수 평균값(4) → 랭크업당 1~3번 전투
R48: 빌런 수 최대값(5) → 랭크업당 1~2번 전투

Sheet 필드 정의
A2: 1. 인덱스
B3: 개발명 | C3: 필드명 | D3: 타입 | E3: 표기 규칙
B4: 아군 유닛 인덱스 | C4: ClassIndex | D4: int | E4: 1로 시작하는 다섯 자리 자연수로 표기, 예시) 10001
B5: 적군 유닛 인덱스 | C5: EnemyIndex | D5: int | E5: 2로 시작하는 다섯 자리 자연수로 표기, 예시) 20001
B6: 적군 파티 인덱스 | C6: EnemyArmyIndex | D6: int | E6: 3로 시작하는 다섯 자리 자연수로 표기, 예시) 30001
B7: 직업 스킬 인덱스 | C7: ClassSkillIndex | D7: int | E7: 네 자리 자연수로 표기, 예시) 1010 (맨 첫자리는 직업 코드: 1 가디언 2 스트라이커 3 위저드 4 서포터)
B8: 적군 스킬 인덱스 | C8: EnemySkillIndex | D8: int | E8: 2로 시작하는 여섯 자리 자연수로 표기, 예시) 210001
B9: 무기 인덱스 | C9: WeaponIndex | D9: int | E9: 3으로 시작하는 여섯 자리 자연수로 표기, 예시) 310001 (3 무기 + 1~3 장비 종류 + 0 + 1~9 직업 코드 + 01~99 인덱스)
B10: 무기 스킬 인덱스 | C10: WeaponSkillIndex | D10: int | E10: 3으로 시작하는 여섯 자리 자연수로 표기, 예시) 311010 (3 무기 + 1~3 장비 종류 + 1~9 직업 코드 + 001~999 인덱스)
A12: 2. 아군/적군 캐릭터 공통 스테이터스 (인카운트 전투 시 사용)
B13: 개발명 | C13: 필드명 | D13: 타입 | E13: 표기 규칙
B14: 유닛 최대 체력 | C14: UnitMaxHP | D14: int | E14: UnitMaxHP > 0
B15: 유닛 공격력 | C15: UnitATK | D15: int | E15: 999 > UnitATK > 0
B16: 유닛 방어력 | C16: UnitDEF | D16: int | E16: 999 > UnitDEF > 0
B17: 치명타율 | C17: CriticalRate | D17: int | E17: n % 단위로 표기, 70% ≥ CriticalRate
B18: 반격율 | C18: CounterRate | D18: int | E18: n % 단위로 표기, 70% ≥ CounterRate
B19: 피해 경감 확률 | C19: ReduceRate | D19: int | E19: n % 단위로 표기, 70% ≥ ReduceRate
B20: 스피드 | C20: Speed | D20: int | E20: 4 ≥ Speed ≥ 0
A22: 3. 스킬 공통 데이터
B23: 개발명 | C23: 필드명 | D23: 타입 | E23: 표기 규칙
B24: 스킬 효과 | C24: SkillEffect | D24: int | E24: 0 공격 스킬 (적군을 대상으로 함) 1 회복 스킬 (아군을 대상으로 함) 2 부활 스킬 (리타이어 상태의 아군을 대상으로 함)
B25: 스킬 사정거리 | C25: SkillRange | D25: int | E25: 0 근거리 스킬 1 원거리 스킬
B26: 스킬 사정거리 라인 | C26: SkillRangeLine | D26: int | E26: 0 전열 우선 (전열이 있을 경우 전열 공격) 1 전열/후열 선택 가능 2 후열 우선 (추후 확장 시, 3 전열만 4 후열만)
B27: 스킬 대상 | C27: SkillTarget | D27: int | E27: 0 단일 대상 1 복수 대상(한 열, 2인 등) 2 전체 대상 0일 경우, 스킬 대상 1명을 고른다 1일 경우, 범위는 스킬 설명에 따라 선택한다 2일 경우, 대상 선택 없이 바로 실행한다
B28: 스킬 복수 대상 | C28: SkillMultiTarget | D28: list<int> | E28: 스킬 대상(SkillTarget)이 1인 경우 사용 복수 대상 스킬이 선택된 최초 타깃(0)을 기준으로 한 추가 타깃 후보 위치 목록 (범위 내 유닛이 존재하는 칸만 유효 타깃으로 처리, 범위 밖 무시) 근거리 스킬의 최초 선택 타깃은 기존 전열 우선 규칙을 따른다. * 추가 타깃 포지션 번호 타깃 중복: 0, 상단: 1, 우상단: 2, 우측: 3, 우하단: 4, 하단: 5, 좌하단: 6, 좌측: 7, 좌상단: 8, 열 전체 9
B29: 스킬 복수 대상 타입 | C29: SkillMultiTargetType | D29: int | E29: 스킬 대상(SkillTarget)이 1인 경우 사용 0 추가 타깃 후보 전체 적용 1 추가 타깃 후보 중 n명 랜덤 선택 | G29: 8 | H29: 1 | I29: 2
B30: 스킬 복수 추가 대상 수 | C30: SkillMultiTargetCount | D30: int | E30: 스킬 복수 대상 타입(SkillMultiTargetType)이 1인 경우 사용 | G30: 7 | H30: 타깃(0) | I30: 3
B31: Lv○ 스킬 계수 | C31: SkillValue Lv○ | D31: float | E31: 공격 스킬: % 단위 표시 (예: 150%) 회복 스킬: 고정 수치 표시 | G31: 6 | H31: 5 | I31: 4
B32: Lv○ 추가 스킬 계수 | C32: SkillSubValue Lv○ | D32: float | E32: 스킬 대상(SkillTarget)이 1인 경우 사용 서로 다른 계수를 가진 복수 범위 스킬, 여러 번 공격하는 스킬 등에 사용 | G32: 열 전체 | H32: 9
B33: IP 코스트 | C33: IPCost | D33: int | E33: 스킬 사용에 필요한 IP 량
A35: 4. 아군 유닛
B36: 개발명 | C36: 필드명 | D36: 타입 | E36: 표기 규칙
B37: 아군 유닛 인덱스 | C37: ClassIndex | D37: int | E37: 1로 시작하는 다섯 자리 자연수로 표기, 예시) 10001
B38: 유닛명 | C38: UnitName | D38: string | E38: 히어로 이름
B39: 클래스명 | C39: ClassName | D39: string | E39: 서로 다른 스테이터스를 가진 직업군, 캐릭터 생성 시 선택
B40: 클래스 콘셉트 | C40: ClassConcept | D40: string | E40: 유닛 콘셉트 소개
B41: 히어로 타입 (보류) | C41: HeroType | D41: string | E41: 히어로 유형, 예시) 인간, 사이보그, 수인 등
B42: 캐릭터 공통 스테이터스
B43: 사용 가능 직업 스킬 | C43: ClassSkillIndexList | D43: list<int> | E43: 착용 가능한 직업 스킬 인덱스, 중괄호{} 내 공백 없이 숫자와 쉼표로 기입, 예시) 1010,1020,1030,1040,1050,1060,1070
B44: 사용 가능 무기 | C44: WeaponIndexList | D44: list<int> | E44: 착용 가능한 무기 인덱스, 중괄호{} 내 공백 없이 숫자와 쉼표로 기입, 예시) 310101,310102,310103,310104,310105,310106,310107
...

Sheet 직업 스킬(기획용)
A1: ClassSkillIndex | B1: Class | C1: ClassSkill AcquireRank | D1: ClassSkillName | E1: ClassSkillDescription | F1: IPCost | G1: ClassSkillEffect | H1: ClassSkillRange | I1: ClassSkillRangeLine | J1: ClassSkillTarget | K1: ClassSkillMultiTarget | L1: ClassSkill MultiTargetType | M1: ClassSkill MultiTargetCount | N1: ClassSkillValueLv1 | O1: ClassSkillSubValueLv1 | P1: ClassSkillValueLv2 | Q1: ClassSkillSubValueLv2 | R1: ClassSkillValueLv3 | S1: ClassSkillSubValueLv3 | T1: ClassSkillValueLv4 | U1: ClassSkillSubValueLv4
A2: 직업 스킬 인덱스 | B2: 직업명 | C2: 습득 랭크 | D2: 직업 스킬명 | E2: 직업 스킬 설명 | F2: IP 코스트 | G2: 직업 스킬 효과 (0 공격 1 회복 2 부활) | H2: 직업 스킬 사정거리 (0 근거리 1 원거리) | I2: 직업 스킬 사정거리 라인 0 전열 우선 (적 전열이 있을 경우 전열 공격) 1 전열/후열 선택 가능 2 후열 우선 | J2: 직업 스킬 대상 (0 단일 1 복수 2 전체) | K2: 직업 스킬 복수 대상 (스킬 대상 1일 경우) | L2: 직업 스킬 복수 대상 타입 (0 후보 전체 1 랜덤) (스킬 대상 1일 경우) | M2: 직업 스킬 복수 추가 대상 수 (스킬 대상 1일 경우) | N2: 직업 스킬 계수 Lv1 | O2: 직업 스킬 추가 계수 Lv1 | P2: 직업 스킬 계수 Lv2 | Q2: 직업 스킬 추가 계수 Lv2 | R2: 직업 스킬 계수 Lv3 | S2: 직업 스킬 추가 계수 Lv3 | T2: 직업 스킬 계수 Lv4 | U2: 직업 스킬 추가 계수 Lv4 | W2: 스킬 복수 대상
A3: 1010 | B3: 가디언 | C3: 1 | D3: 도발 베기 | E3: 적 1명에게 {ClassSkillValue} 대미지를 입히고, 1턴 동안 해당 대상이 단일 공격 시 자신을 공격하게 한다. (적 전열이 있을 경우, 전열 우선 공격) | F3: 0 | G3: 0 | H3: 0 | I3: 0 | J3: 0 | N3: 1 | P3: =IFERROR(IF(ROUND(N3*1.2,1)=0,"",ROUND(N3*1.2,1)),"") -> 1.2 | Q3: =IFERROR(IF(ROUND(O3*1.2,1)=0,"",ROUND(O3*1.2,1)),"") | R3: =IFERROR(IF(ROUND(P3*1.2,1)=0,"",ROUND(P3*1.2,1)),"") -> 1.4 | S3: =IFERROR(IF(ROUND(Q3*1.2,1)=0,"",ROUND(Q3*1.2,1)),"") | T3: =IFERROR(IF(ROUND(R3*1.2,1)=0,"",ROUND(R3*1.2,1)),"") -> 1.7 | U3: =IFERROR(IF(ROUND(S3*1.2,1)=0,"",ROUND(S3*1.2,1)),"") | W3: 8 | X3: 1 | Y3: 2
A4: 1020 | B4: 가디언 | C4: 3 | D4: 일렬 베기 | E4: 적 한 열에 {ClassSkillValue} 대미지를 입힌다. (적 전열이 있을 경우, 전열 우선 공격) | F4: 0 | G4: 0 | H4: 0 | I4: 0 | J4: 1 | K4: {9} | L4: 0 | N4: 0.8 | P4: =IFERROR(IF(ROUND(N4*1.2,1)=0,"",ROUND(N4*1.2,1)),"") -> 1 | Q4: =IFERROR(IF(ROUND(O4*1.2,1)=0,"",ROUND(O4*1.2,1)),"") | R4: =IFERROR(IF(ROUND(P4*1.2,1)=0,"",ROUND(P4*1.2,1)),"") -> 1.2 | S4: =IFERROR(IF(ROUND(Q4*1.2,1)=0,"",ROUND(Q4*1.2,1)),"") | T4: =IFERROR(IF(ROUND(R4*1.2,1)=0,"",ROUND(R4*1.2,1)),"") -> 1.4 | U4: =IFERROR(IF(ROUND(S4*1.2,1)=0,"",ROUND(S4*1.2,1)),"") | W4: 7 | X4: 타깃(0) | Y4: 3
A5: 1030 | B5: 가디언 | C5: 5 | D5: 관통 | E5: 전열의 적 한 명에게 {ClassSkillValue} 대미지를 입히고, 해당 후열에 있는 적 한 명에게 추가로 {ClassSkillSubValue} 대미지를 입힌다. (전열의 적이 없을 경우 후열의 적 한 명만을 공격) | F5: 0 | G5: 0 | H5: 0 | I5: 0 | J5: 0 | K5: {3} | L5: 0 | M5: 1 | N5: 0.6 | O5: 0.8 | P5: =IFERROR(IF(ROUND(N5*1.2,1)=0,"",ROUND(N5*1.2,1)),"") -> 0.7 | Q5: =IFERROR(IF(ROUND(O5*1.2,1)=0,"",ROUND(O5*1.2,1)),"") -> 1 | R5: =IFERROR(IF(ROUND(P5*1.2,1)=0,"",ROUND(P5*1.2,1)),"") -> 0.8 | S5: =IFERROR(IF(ROUND(Q5*1.2,1)=0,"",ROUND(Q5*1.2,1)),"") -> 1.2 | T5: =IFERROR(IF(ROUND(R5*1.2,1)=0,"",ROUND(R5*1.2,1)),"") -> 1 | U5: =IFERROR(IF(ROUND(S5*1.2,1)=0,"",ROUND(S5*1.2,1)),"") -> 1.4 | W5: 6 | X5: 5 | Y5: 4
A6: 1040 | B6: 가디언 | C6: 7 | D6: 광역 도발 | E6: 적 한 열에 {ClassSkillValue} 대미지를 입히고, 1턴 동안 모든 적이 단일 공격 시 자신을 공격하게 한다. (적 전열이 있을 경우, 전열 우선 공격) | F6: 0 | G6: 0 | H6: 0 | I6: 0 | J6: 1 | K6: {9} | L6: 0 | N6: 1.2 | P6: =IFERROR(IF(ROUND(N6*1.2,1)=0,"",ROUND(N6*1.2,1)),"") -> 1.4 | Q6: =IFERROR(IF(ROUND(O6*1.2,1)=0,"",ROUND(O6*1.2,1)),"") | R6: =IFERROR(IF(ROUND(P6*1.2,1)=0,"",ROUND(P6*1.2,1)),"") -> 1.7 | S6: =IFERROR(IF(ROUND(Q6*1.2,1)=0,"",ROUND(Q6*1.2,1)),"") | T6: =IFERROR(IF(ROUND(R6*1.2,1)=0,"",ROUND(R6*1.2,1)),"") -> 2 | U6: =IFERROR(IF(ROUND(S6*1.2,1)=0,"",ROUND(S6*1.2,1)),"") | W6: 열 전체 | X6: 9
A7: 1050 | B7: 가디언 | C7: 10 | D7: 돌파 | E7: 적 1명에게 {ClassSkillValue} 대미지를 입힌다. (후열에 있는 적도 공격 가능하다.) | F7: 0 | G7: 0 | H7: 0 | I7: 1 | J7: 0 | N7: 1.5 | P7: =IFERROR(IF(ROUND(N7*1.2,1)=0,"",ROUND(N7*1.2,1)),"") -> 1.8 | Q7: =IFERROR(IF(ROUND(O7*1.2,1)=0,"",ROUND(O7*1.2,1)),"") | R7: =IFERROR(IF(ROUND(P7*1.2,1)=0,"",ROUND(P7*1.2,1)),"") -> 2.2 | S7: =IFERROR(IF(ROUND(Q7*1.2,1)=0,"",ROUND(Q7*1.2,1)),"") | T7: =IFERROR(IF(ROUND(R7*1.2,1)=0,"",ROUND(R7*1.2,1)),"") -> 2.6 | U7: =IFERROR(IF(ROUND(S7*1.2,1)=0,"",ROUND(S7*1.2,1)),"")
A8: 1060 | B8: 가디언 | C8: 12 | D8: 쌍렬 베기 | E8: 적 전열과 후열의 모든 적에게 {ClassSkillValue} 대미지를 준다. | F8: 0 | G8: 0 | H8: 0 | I8: 1 | J8: 2 | N8: 0.8 | P8: =IFERROR(IF(ROUND(N8*1.2,1)=0,"",ROUND(N8*1.2,1)),"") -> 1 | Q8: =IFERROR(IF(ROUND(O8*1.2,1)=0,"",ROUND(O8*1.2,1)),"") | R8: =IFERROR(IF(ROUND(P8*1.2,1)=0,"",ROUND(P8*1.2,1)),"") -> 1.2 | S8: =IFERROR(IF(ROUND(Q8*1.2,1)=0,"",ROUND(Q8*1.2,1)),"") | T8: =IFERROR(IF(ROUND(R8*1.2,1)=0,"",ROUND(R8*1.2,1)),"") -> 1.4 | U8: =IFERROR(IF(ROUND(S8*1.2,1)=0,"",ROUND(S8*1.2,1)),"")
A9: 1070 | B9: 가디언 | C9: 15 | D9: 불굴 | E9: 자신의 체력이 낮을수록 적 1명에게 높은 대미지를 입힌다. (기본 100% + 최대 체력 대비 현재 체력 20%가 낮아질 때마다 40% 추가, 최대 {ClassSkillValue}) | F9: 0 | G9: 0 | H9: 0 | I9: 0 | J9: 0 | N9: 1.8 | P9: 2.2 | Q9: =IFERROR(IF(ROUND(O9*1.2,1)=0,"",ROUND(O9*1.2,1)),"") | R9: 2.6 | S9: =IFERROR(IF(ROUND(Q9*1.2,1)=0,"",ROUND(Q9*1.2,1)),"") | T9: 3 | U9: =IFERROR(IF(ROUND(S9*1.2,1)=0,"",ROUND(S9*1.2,1)),"")
A10: 2010 | B10: 블래스터 | C10: 1 | D10: 파이어볼 | E10: 적 1명에게 {ClassSkillValue} 대미지를 입힌다. | F10: 0 | G10: 0 | H10: 1 | I10: 1 | J10: 0 | N10: 1 | P10: =IFERROR(IF(ROUND(N10*1.2,1)=0,"",ROUND(N10*1.2,1)),"") -> 1.2 | Q10: =IFERROR(IF(ROUND(O10*1.2,1)=0,"",ROUND(O10*1.2,1)),"") | R10: =IFERROR(IF(ROUND(P10*1.2,1)=0,"",ROUND(P10*1.2,1)),"") -> 1.4 | S10: =IFERROR(IF(ROUND(Q10*1.2,1)=0,"",ROUND(Q10*1.2,1)),"") | T10: =IFERROR(IF(ROUND(R10*1.2,1)=0,"",ROUND(R10*1.2,1)),"") -> 1.7 | U10: =IFERROR(IF(ROUND(S10*1.2,1)=0,"",ROUND(S10*1.2,1)),"")
A11: 2020 | B11: 블래스터 | C11: 3 | D11: 번개 확산 | E11: 적 한 열에 {ClassSkillValue} 대미지를 입힌다. | F11: 0 | G11: 0 | H11: 1 | I11: 1 | J11: 1 | K11: {9} | L11: 0 | N11: 0.6 | P11: =IFERROR(IF(ROUND(N11*1.2,1)=0,"",ROUND(N11*1.2,1)),"") -> 0.7 | Q11: =IFERROR(IF(ROUND(O11*1.2,1)=0,"",ROUND(O11*1.2,1)),"") | R11: =IFERROR(IF(ROUND(P11*1.2,1)=0,"",ROUND(P11*1.2,1)),"") -> 0.8 | S11: =IFERROR(IF(ROUND(Q11*1.2,1)=0,"",ROUND(Q11*1.2,1)),"") | T11: =IFERROR(IF(ROUND(R11*1.2,1)=0,"",ROUND(R11*1.2,1)),"") -> 1 | U11: =IFERROR(IF(ROUND(S11*1.2,1)=0,"",ROUND(S11*1.2,1)),"")
A12: 2030 | B12: 블래스터 | C12: 5 | D12: 마력 집중 | E12: 적 한 명에게 {ClassSkillValue} 대미지를 입힌다. 다음 자신의 턴 1턴을 건너뛴다. | F12: 0 | G12: 0 | H12: 1 | I12: 1 | J12: 0 | N12: 1.8 | P12: =IFERROR(IF(ROUND(N12*1.2,1)=0,"",ROUND(N12*1.2,1)),"") -> 2.2 | Q12: =IFERROR(IF(ROUND(O12*1.2,1)=0,"",ROUND(O12*1.2,1)),"") | R12: =IFERROR(IF(ROUND(P12*1.2,1)=0,"",ROUND(P12*1.2,1)),"") -> 2.6 | S12: =IFERROR(IF(ROUND(Q12*1.2,1)=0,"",ROUND(Q12*1.2,1)),"") | T12: =IFERROR(IF(ROUND(R12*1.2,1)=0,"",ROUND(R12*1.2,1)),"") -> 3.1 | U12: =IFERROR(IF(ROUND(S12*1.2,1)=0,"",ROUND(S12*1.2,1)),"")
A13: 2040 | B13: 블래스터 | C13: 7 | D13: 연쇄 번개 | E13: 전열의 적 한 명에게 {ClassSkillValue} 대미지를 입히고, 인접한 적 한 명에게 추가로 {ClassSkillSubValue} 대미지를 입힌다. | F13: 0 | G13: 0 | H13: 1 | I13: 1 | J13: 0 | K13: {1,3,5} | L13: 1 | M13: 1 | N13: 0.6 | O13: 0.5 | P13: =IFERROR(IF(ROUND(N13*1.2,1)=0,"",ROUND(N13*1.2,1)),"") -> 0.7 | Q13: =IFERROR(IF(ROUND(O13*1.2,1)=0,"",ROUND(O13*1.2,1)),"") -> 0.6 | R13: =IFERROR(IF(ROUND(P13*1.2,1)=0,"",ROUND(P13*1.2,1)),"") -> 0.8 | S13: =IFERROR(IF(ROUND(Q13*1.2,1)=0,"",ROUND(Q13*1.2,1)),"") -> 0.7 | T13: =IFERROR(IF(ROUND(R13*1.2,1)=0,"",ROUND(R13*1.2,1)),"") -> 1 | U13: =IFERROR(IF(ROUND(S13*1.2,1)=0,"",ROUND(S13*1.2,1)),"") -> 0.8
A14: 2050 | B14: 블래스터 | C14: 10 | D14: 메테오 | E14: 적 전열과 후열의 모든 적에게 {ClassSkillValue}대미지를 준다. | F14: 0 | G14: 0 | H14: 1 | I14: 1 | J14: 2 | N14: 0.8 | P14: =IFERROR(IF(ROUND(N14*1.2,1)=0,"",ROUND(N14*1.2,1)),"") -> 1 | Q14: =IFERROR(IF(ROUND(O14*1.2,1)=0,"",ROUND(O14*1.2,1)),"") | R14: =IFERROR(IF(ROUND(P14*1.2,1)=0,"",ROUND(P14*1.2,1)),"") -> 1.2 | S14: =IFERROR(IF(ROUND(Q14*1.2,1)=0,"",ROUND(Q14*1.2,1)),"") | T14: =IFERROR(IF(ROUND(R14*1.2,1)=0,"",ROUND(R14*1.2,1)),"") -> 1.4 | U14: =IFERROR(IF(ROUND(S14*1.2,1)=0,"",ROUND(S14*1.2,1)),"")
A15: 2060 | B15: 블래스터 | C15: 12 | D15: 마력 폭발 | E15: 적 1명에게 체력이 높을수록 높은 대미지를 입힌다. (기본 {ClassSkillValue} + 적의 최대 체력 대비 현재 체력 10%가 낮아질 때마다 10% 감소, 최소 100%) | F15: 0 | G15: 0 | H15: 1 | I15: 1 | J15: 0 | N15: 1.5 | P15: =IFERROR(IF(ROUND(N15*1.2,1)=0,"",ROUND(N15*1.2,1)),"") -> 1.8 | Q15: =IFERROR(IF(ROUND(O15*1.2,1)=0,"",ROUND(O15*1.2,1)),"") | R15: =IFERROR(IF(ROUND(P15*1.2,1)=0,"",ROUND(P15*1.2,1)),"") -> 2.2 | S15: =IFERROR(IF(ROUND(Q15*1.2,1)=0,"",ROUND(Q15*1.2,1)),"") | T15: =IFERROR(IF(ROUND(R15*1.2,1)=0,"",ROUND(R15*1.2,1)),"") -> 2.6 | U15: =IFERROR(IF(ROUND(S15*1.2,1)=0,"",ROUND(S15*1.2,1)),"")
A16: 2070 | B16: 블래스터 | C16: 15 | D16: 붕괴 | E16: 이 공격을 맞는 적의 수가 적을수록 높은 대미지를 입힌다. (기본 100% + 전 진형의 빈 칸 하나당 20%, 최대 {ClassSkillValue}) | F16: 0 | G16: 0 | H16: 1 | I16: 1 | J16: 2 | N16: 1.4 | P16: 1.6 | Q16: =IFERROR(IF(ROUND(O16*1.2,1)=0,"",ROUND(O16*1.2,1)),"") | R16: 1.8 | S16: =IFERROR(IF(ROUND(Q16*1.2,1)=0,"",ROUND(Q16*1.2,1)),"") | T16: 2 | U16: =IFERROR(IF(ROUND(S16*1.2,1)=0,"",ROUND(S16*1.2,1)),"")
A17: 3010 | B17: 스트라이커 | C17: 1 | D17: 정밀 사격 | E17: 적 1명에게 {ClassSkillValue} 대미지를 입힌다. | F17: 0 | G17: 0 | H17: 1 | I17: 1 | J17: 0 | N17: 1 | P17: =IFERROR(IF(ROUND(N17*1.2,1)=0,"",ROUND(N17*1.2,1)),"") -> 1.2 | Q17: =IFERROR(IF(ROUND(O17*1.2,1)=0,"",ROUND(O17*1.2,1)),"") | R17: =IFERROR(IF(ROUND(P17*1.2,1)=0,"",ROUND(P17*1.2,1)),"") -> 1.4 | S17: =IFERROR(IF(ROUND(Q17*1.2,1)=0,"",ROUND(Q17*1.2,1)),"") | T17: =IFERROR(IF(ROUND(R17*1.2,1)=0,"",ROUND(R17*1.2,1)),"") -> 1.7 | U17: =IFERROR(IF(ROUND(S17*1.2,1)=0,"",ROUND(S17*1.2,1)),"")
A18: 3020 | B18: 스트라이커 | C18: 3 | D18: 전열 저격 | E18: 적 1명에게 {ClassSkillValue}대미지를 입힌다. 전열의 적을 공격 시, {ClassSkillValue}대미지로 계산한다. | F18: 0 | G18: 0 | H18: 1 | I18: 1 | J18: 0 | N18: 1.2 | P18: =IFERROR(IF(ROUND(N18*1.2,1)=0,"",ROUND(N18*1.2,1)),"") -> 1.4 | Q18: =IFERROR(IF(ROUND(O18*1.2,1)=0,"",ROUND(O18*1.2,1)),"") | R18: =IFERROR(IF(ROUND(P18*1.2,1)=0,"",ROUND(P18*1.2,1)),"") -> 1.7 | S18: =IFERROR(IF(ROUND(Q18*1.2,1)=0,"",ROUND(Q18*1.2,1)),"") | T18: =IFERROR(IF(ROUND(R18*1.2,1)=0,"",ROUND(R18*1.2,1)),"") -> 2 | U18: =IFERROR(IF(ROUND(S18*1.2,1)=0,"",ROUND(S18*1.2,1)),"")
A19: 3030 | B19: 스트라이커 | C19: 5 | D19: 후열 저격 | E19: 적 1명에게 {ClassSkillValue}대미지를 입힌다. 후열의 적을 공격 시 대미지 계산 전 회피율을 20% 내린다. | F19: 0 | G19: 0 | H19: 1 | I19: 1 | J19: 0 | N19: 1.4 | P19: =IFERROR(IF(ROUND(N19*1.2,1)=0,"",ROUND(N19*1.2,1)),"") -> 1.7 | Q19: =IFERROR(IF(ROUND(O19*1.2,1)=0,"",ROUND(O19*1.2,1)),"") | R19: =IFERROR(IF(ROUND(P19*1.2,1)=0,"",ROUND(P19*1.2,1)),"") -> 2 | S19: =IFERROR(IF(ROUND(Q19*1.2,1)=0,"",ROUND(Q19*1.2,1)),"") | T19: =IFERROR(IF(ROUND(R19*1.2,1)=0,"",ROUND(R19*1.2,1)),"") -> 2.4 | U19: =IFERROR(IF(ROUND(S19*1.2,1)=0,"",ROUND(S19*1.2,1)),"")
A20: 3040 | B20: 스트라이커 | C20: 7 | D20: 연속 사격 | E20: 적 1명에게 {ClassSkillValue}대미지를 두 번 입힌다. (치명타, 회피율 판정은 각각 계산한다.) | F20: 0 | G20: 0 | H20: 1 | I20: 1 | J20: 0 | K20: {0} | L20: 0 | N20: 0.8 | O20: 0.8 | P20: =IFERROR(IF(ROUND(N20*1.2,1)=0,"",ROUND(N20*1.2,1)),"") -> 1 | Q20: =IFERROR(IF(ROUND(O20*1.2,1)=0,"",ROUND(O20*1.2,1)),"") -> 1 | R20: =IFERROR(IF(ROUND(P20*1.2,1)=0,"",ROUND(P20*1.2,1)),"") -> 1.2 | S20: =IFERROR(IF(ROUND(Q20*1.2,1)=0,"",ROUND(Q20*1.2,1)),"") -> 1.2 | T20: =IFERROR(IF(ROUND(R20*1.2,1)=0,"",ROUND(R20*1.2,1)),"") -> 1.4 | U20: =IFERROR(IF(ROUND(S20*1.2,1)=0,"",ROUND(S20*1.2,1)),"") -> 1.4
A21: 3050 | B21: 스트라이커 | C21: 10 | D21: 급소 저격 | E21: 적 1명에게 {ClassSkillValue}대미지를 입힌다. 체력 80% 이하 대상 공격 시 대미지 계산 전 치명타 확률을 20% 올린다. | F21: 0 | G21: 0 | H21: 1 | I21: 1 | J21: 0 | N21: 1.6 | P21: =IFERROR(IF(ROUND(N21*1.2,1)=0,"",ROUND(N21*1.2,1)),"") -> 1.9 | Q21: =IFERROR(IF(ROUND(O21*1.2,1)=0,"",ROUND(O21*1.2,1)),"") | R21: =IFERROR(IF(ROUND(P21*1.2,1)=0,"",ROUND(P21*1.2,1)),"") -> 2.3 | S21: =IFERROR(IF(ROUND(Q21*1.2,1)=0,"",ROUND(Q21*1.2,1)),"") | T21: =IFERROR(IF(ROUND(R21*1.2,1)=0,"",ROUND(R21*1.2,1)),"") -> 2.8 | U21: =IFERROR(IF(ROUND(S21*1.2,1)=0,"",ROUND(S21*1.2,1)),"")
A22: 3060 | B22: 스트라이커 | C22: 12 | D22: 화살비 | E22: 적 전열과 후열의 모든 적에게 {ClassSkillValue}대미지를 준다. | F22: 0 | G22: 0 | H22: 1 | I22: 1 | J22: 2 | N22: 0.5 | P22: =IFERROR(IF(ROUND(N22*1.2,1)=0,"",ROUND(N22*1.2,1)),"") -> 0.6 | Q22: =IFERROR(IF(ROUND(O22*1.2,1)=0,"",ROUND(O22*1.2,1)),"") | R22: =IFERROR(IF(ROUND(P22*1.2,1)=0,"",ROUND(P22*1.2,1)),"") -> 0.7 | S22: =IFERROR(IF(ROUND(Q22*1.2,1)=0,"",ROUND(Q22*1.2,1)),"") | T22: =IFERROR(IF(ROUND(R22*1.2,1)=0,"",ROUND(R22*1.2,1)),"") -> 0.8 | U22: =IFERROR(IF(ROUND(S22*1.2,1)=0,"",ROUND(S22*1.2,1)),"")
A23: 3070 | B23: 스트라이커 | C23: 15 | D23: 최후의 일격 | E23: 적의 체력이 낮을 수록 높은 대미지를 입힌다. (기본 100% + 적의 최대 체력 대비 현재 체력 10%가 낮아질 때마다 10% 추가, 최대 {ClassSkillValue}) | F23: 0 | G23: 0 | H23: 1 | I23: 1 | J23: 0 | N23: 1.8 | P23: =IFERROR(IF(ROUND(N23*1.2,1)=0,"",ROUND(N23*1.2,1)),"") -> 2.2 | Q23: =IFERROR(IF(ROUND(O23*1.2,1)=0,"",ROUND(O23*1.2,1)),"") | R23: =IFERROR(IF(ROUND(P23*1.2,1)=0,"",ROUND(P23*1.2,1)),"") -> 2.6 | S23: =IFERROR(IF(ROUND(Q23*1.2,1)=0,"",ROUND(Q23*1.2,1)),"") | T23: =IFERROR(IF(ROUND(R23*1.2,1)=0,"",ROUND(R23*1.2,1)),"") -> 3.1 | U23: =IFERROR(IF(ROUND(S23*1.2,1)=0,"",ROUND(S23*1.2,1)),"")
A24: 4010 | B24: 서포터 | C24: 1 | D24: 힐 | E24: 아군 1명 체력 30% 회복, IP 10 고정 회복 | F24: 0 | G24: 1 | J24: 0 | P24: =IFERROR(IF(ROUND(N24*1.2,1)=0,"",ROUND(N24*1.2,1)),"") | Q24: =IFERROR(IF(ROUND(O24*1.2,1)=0,"",ROUND(O24*1.2,1)),"") | R24: =IFERROR(IF(ROUND(P24*1.2,1)=0,"",ROUND(P24*1.2,1)),"") | S24: =IFERROR(IF(ROUND(Q24*1.2,1)=0,"",ROUND(Q24*1.2,1)),"") | T24: =IFERROR(IF(ROUND(R24*1.2,1)=0,"",ROUND(R24*1.2,1)),"") | U24: =IFERROR(IF(ROUND(S24*1.2,1)=0,"",ROUND(S24*1.2,1)),"")
A25: 4020 | B25: 서포터 | C25: 3 | D25: 신성탄 | E25: 적 1명에게 {ClassSkillValue}대미지를 입히고, 입힌 대미지 만큼 아군의 1명의 IP 회복 (최대 20) | F25: 0 | G25: 0 | H25: 1 | I25: 1 | J25: 0 | N25: 0.8 | P25: =IFERROR(IF(ROUND(N25*1.2,1)=0,"",ROUND(N25*1.2,1)),"") -> 1 | Q25: =IFERROR(IF(ROUND(O25*1.2,1)=0,"",ROUND(O25*1.2,1)),"") | R25: =IFERROR(IF(ROUND(P25*1.2,1)=0,"",ROUND(P25*1.2,1)),"") -> 1.2 | S25: =IFERROR(IF(ROUND(Q25*1.2,1)=0,"",ROUND(Q25*1.2,1)),"") | T25: =IFERROR(IF(ROUND(R25*1.2,1)=0,"",ROUND(R25*1.2,1)),"") -> 1.4 | U25: =IFERROR(IF(ROUND(S25*1.2,1)=0,"",ROUND(S25*1.2,1)),"")
A26: 4030 | B26: 서포터 | C26: 5 | D26: 긴급 치유 | E26: 아군 1명의 체력을 회복한다. (기본 5 + 최대 체력 대비 현재 체력 20%가 낮아질 때마다 15 추가, 최대 50) | F26: 0 | G26: 1 | J26: 0 | P26: =IFERROR(IF(ROUND(N26*1.2,1)=0,"",ROUND(N26*1.2,1)),"") | Q26: =IFERROR(IF(ROUND(O26*1.2,1)=0,"",ROUND(O26*1.2,1)),"") | R26: =IFERROR(IF(ROUND(P26*1.2,1)=0,"",ROUND(P26*1.2,1)),"") | S26: =IFERROR(IF(ROUND(Q26*1.2,1)=0,"",ROUND(Q26*1.2,1)),"") | T26: =IFERROR(IF(ROUND(R26*1.2,1)=0,"",ROUND(R26*1.2,1)),"") | U26: =IFERROR(IF(ROUND(S26*1.2,1)=0,"",ROUND(S26*1.2,1)),"")
A27: 4040 | B27: 서포터 | C27: 7 | D27: 심판의 빛 | E27: 적 1명에게 {ClassSkillValue}대미지를 입히고 체력을 회복할 수 없게 한다. | F27: 0 | G27: 0 | H27: 1 | I27: 1 | J27: 0 | N27: 1 | P27: =IFERROR(IF(ROUND(N27*1.2,1)=0,"",ROUND(N27*1.2,1)),"") -> 1.2 | Q27: =IFERROR(IF(ROUND(O27*1.2,1)=0,"",ROUND(O27*1.2,1)),"") | R27: =IFERROR(IF(ROUND(P27*1.2,1)=0,"",ROUND(P27*1.2,1)),"") -> 1.4 | S27: =IFERROR(IF(ROUND(Q27*1.2,1)=0,"",ROUND(Q27*1.2,1)),"") | T27: =IFERROR(IF(ROUND(R27*1.2,1)=0,"",ROUND(R27*1.2,1)),"") -> 1.7 | U27: =IFERROR(IF(ROUND(S27*1.2,1)=0,"",ROUND(S27*1.2,1)),"")
A28: 4050 | B28: 서포터 | C28: 10 | D28: 광역 힐 | E28: 아군 1명의 체력을 10% 회복하고, 인접한 아군 1명의 체력을 10% 추가 회복한다. | F28: 0 | G28: 1 | J28: 0 | P28: =IFERROR(IF(ROUND(N28*1.2,1)=0,"",ROUND(N28*1.2,1)),"") | Q28: =IFERROR(IF(ROUND(O28*1.2,1)=0,"",ROUND(O28*1.2,1)),"") | R28: =IFERROR(IF(ROUND(P28*1.2,1)=0,"",ROUND(P28*1.2,1)),"") | S28: =IFERROR(IF(ROUND(Q28*1.2,1)=0,"",ROUND(Q28*1.2,1)),"") | T28: =IFERROR(IF(ROUND(R28*1.2,1)=0,"",ROUND(R28*1.2,1)),"") | U28: =IFERROR(IF(ROUND(S28*1.2,1)=0,"",ROUND(S28*1.2,1)),"")
A29: 4060 | B29: 서포터 | C29: 12 | D29: 신성 폭발 | E29: 적 전열과 후열의 모든 적에게 {ClassSkillValue}대미지를 준다. | F29: 0 | G29: 0 | H29: 1 | I29: 1 | J29: 2 | N29: 0.5 | P29: =IFERROR(IF(ROUND(N29*1.2,1)=0,"",ROUND(N29*1.2,1)),"") -> 0.6 | Q29: =IFERROR(IF(ROUND(O29*1.2,1)=0,"",ROUND(O29*1.2,1)),"") | R29: =IFERROR(IF(ROUND(P29*1.2,1)=0,"",ROUND(P29*1.2,1)),"") -> 0.7 | S29: =IFERROR(IF(ROUND(Q29*1.2,1)=0,"",ROUND(Q29*1.2,1)),"") | T29: =IFERROR(IF(ROUND(R29*1.2,1)=0,"",ROUND(R29*1.2,1)),"") -> 0.8 | U29: =IFERROR(IF(ROUND(S29*1.2,1)=0,"",ROUND(S29*1.2,1)),"")
A30: 4070 | B30: 서포터 | C30: 15 | D30: 기적 | E30: 사망한 아군 1명을 체력 20%로 부활시킨다. (한 전투당 한 번만 사용 가능) | F30: 0 | G30: 2 | J30: 0 | P30: =IFERROR(IF(ROUND(N30*1.2,1)=0,"",ROUND(N30*1.2,1)),"") | Q30: =IFERROR(IF(ROUND(O30*1.2,1)=0,"",ROUND(O30*1.2,1)),"") | R30: =IFERROR(IF(ROUND(P30*1.2,1)=0,"",ROUND(P30*1.2,1)),"") | S30: =IFERROR(IF(ROUND(Q30*1.2,1)=0,"",ROUND(Q30*1.2,1)),"") | T30: =IFERROR(IF(ROUND(R30*1.2,1)=0,"",ROUND(R30*1.2,1)),"") | U30: =IFERROR(IF(ROUND(S30*1.2,1)=0,"",ROUND(S30*1.2,1)),"")
A31: 5010 | B31: 파이터 | C31: 1 | D31: 정면 베기 | E31: 적 1명에게 {ClassSkillValue}대미지를 입힌다. 대상이 전열일 경우 {ClassSkillValue}+{ClassSkillSubValue} 대미지를 입힌다. (적 전열이 있을 경우, 전열 우선 공격) | F31: 0 | G31: 0 | H31: 0 | I31: 0 | J31: 0 | K31: {0} | L31: 0 | N31: 1 | O31: 0.2 | P31: =IFERROR(IF(ROUND(N31*1.2,1)=0,"",ROUND(N31*1.2,1)),"") -> 1.2 | Q31: =IFERROR(IF(ROUND(O31*1.2,1)=0,"",ROUND(O31*1.2,1)),"") -> 0.2 | R31: =IFERROR(IF(ROUND(P31*1.2,1)=0,"",ROUND(P31*1.2,1)),"") -> 1.4 | S31: =IFERROR(IF(ROUND(Q31*1.2,1)=0,"",ROUND(Q31*1.2,1)),"") -> 0.2 | T31: =IFERROR(IF(ROUND(R31*1.2,1)=0,"",ROUND(R31*1.2,1)),"") -> 1.7 | U31: =IFERROR(IF(ROUND(S31*1.2,1)=0,"",ROUND(S31*1.2,1)),"") -> 0.2
A32: 5020 | B32: 파이터 | C32: 3 | D32: 검기 | E32: 적 1명에게 {ClassSkillValue} 대미지를 입힌다. (후열 공격 가능) | F32: 0 | G32: 0 | H32: 2 | I32: 1 | J32: 0 | N32: 1.2 | P32: =IFERROR(IF(ROUND(N32*1.2,1)=0,"",ROUND(N32*1.2,1)),"") -> 1.4 | Q32: =IFERROR(IF(ROUND(O32*1.2,1)=0,"",ROUND(O32*1.2,1)),"") | R32: =IFERROR(IF(ROUND(P32*1.2,1)=0,"",ROUND(P32*1.2,1)),"") -> 1.7 | S32: =IFERROR(IF(ROUND(Q32*1.2,1)=0,"",ROUND(Q32*1.2,1)),"") | T32: =IFERROR(IF(ROUND(R32*1.2,1)=0,"",ROUND(R32*1.2,1)),"") -> 2 | U32: =IFERROR(IF(ROUND(S32*1.2,1)=0,"",ROUND(S32*1.2,1)),"")
A33: 5030 | B33: 파이터 | C33: 5 | D33: 후열 돌파 | E33: 적의 후열에 {ClassSkillValue}근접 대미지를 준다. 적의 후열이 없는 경우, 전열에 {ClassSkillSubValue}대미지를 준다. | F33: 0 | G33: 0 | H33: 0 | I33: 2 | J33: 1 | K33: {9} | L33: 0 | N33: 1.2 | O33: =N33*50% -> 0.6 | P33: =IFERROR(IF(ROUND(N33*1.2,1)=0,"",ROUND(N33*1.2,1)),"") -> 1.4 | Q33: =IFERROR(IF(ROUND(O33*1.2,1)=0,"",ROUND(O33*1.2,1)),"") -> 0.7 | R33: =IFERROR(IF(ROUND(P33*1.2,1)=0,"",ROUND(P33*1.2,1)),"") -> 1.7 | S33: =IFERROR(IF(ROUND(Q33*1.2,1)=0,"",ROUND(Q33*1.2,1)),"") -> 0.8 | T33: =IFERROR(IF(ROUND(R33*1.2,1)=0,"",ROUND(R33*1.2,1)),"") -> 2 | U33: =IFERROR(IF(ROUND(S33*1.2,1)=0,"",ROUND(S33*1.2,1)),"") -> 1
A34: 5040 | B34: 파이터 | C34: 7 | D34: 연속 베기 | E34: 적 1명에게 {ClassSkillValue}대미지를 두 번 입힌다. (적 전열이 있을 경우, 전열 우선 공격, 치명타, 회피율 판정은 각각 계산한다.) | F34: 0 | G34: 0 | H34: 0 | I34: 0 | J34: 1 | K34: {0} | L34: 0 | N34: 0.7 | O34: 0.7 | P34: =IFERROR(IF(ROUND(N34*1.2,1)=0,"",ROUND(N34*1.2,1)),"") -> 0.8 | Q34: =IFERROR(IF(ROUND(O34*1.2,1)=0,"",ROUND(O34*1.2,1)),"") -> 0.8 | R34: =IFERROR(IF(ROUND(P34*1.2,1)=0,"",ROUND(P34*1.2,1)),"") -> 1 | S34: =IFERROR(IF(ROUND(Q34*1.2,1)=0,"",ROUND(Q34*1.2,1)),"") -> 1 | T34: =IFERROR(IF(ROUND(R34*1.2,1)=0,"",ROUND(R34*1.2,1)),"") -> 1.2 | U34: =IFERROR(IF(ROUND(S34*1.2,1)=0,"",ROUND(S34*1.2,1)),"") -> 1.2
A35: 5050 | B35: 파이터 | C35: 10 | D35: 급소 찌르기 | E35: 적 1명에게 치명타 확률이 20% 높은 {ClassSkillValue}대미지를 입힌다. (적 전열이 있을 경우, 전열 우선 공격) | F35: 0 | G35: 0 | H35: 0 | I35: 0 | J35: 0 | N35: 1.5 | P35: =IFERROR(IF(ROUND(N35*1.2,1)=0,"",ROUND(N35*1.2,1)),"") -> 1.8 | Q35: =IFERROR(IF(ROUND(O35*1.2,1)=0,"",ROUND(O35*1.2,1)),"") | R35: =IFERROR(IF(ROUND(P35*1.2,1)=0,"",ROUND(P35*1.2,1)),"") -> 2.2 | S35: =IFERROR(IF(ROUND(Q35*1.2,1)=0,"",ROUND(Q35*1.2,1)),"") | T35: =IFERROR(IF(ROUND(R35*1.2,1)=0,"",ROUND(R35*1.2,1)),"") -> 2.6 | U35: =IFERROR(IF(ROUND(S35*1.2,1)=0,"",ROUND(S35*1.2,1)),"")
A36: 5060 | B36: 파이터 | C36: 12 | D36: 전술 베기 | E36: 적의 체력이 낮을 수록 높은 대미지를 입힌다. (기본 100% + 적의 최대 체력 대비 현재 체력 10%가 낮아질 때마다 10% 추가, 최대 {ClassSkillValue})(적 전열이 있을 경우, 전열 우선 공격) | F36: 0 | G36: 0 | H36: 0 | I36: 0 | J36: 0 | N36: 1.8 | P36: =IFERROR(IF(ROUND(N36*1.2,1)=0,"",ROUND(N36*1.2,1)),"") -> 2.2 | Q36: =IFERROR(IF(ROUND(O36*1.2,1)=0,"",ROUND(O36*1.2,1)),"") | R36: =IFERROR(IF(ROUND(P36*1.2,1)=0,"",ROUND(P36*1.2,1)),"") -> 2.6 | S36: =IFERROR(IF(ROUND(Q36*1.2,1)=0,"",ROUND(Q36*1.2,1)),"") | T36: =IFERROR(IF(ROUND(R36*1.2,1)=0,"",ROUND(R36*1.2,1)),"") -> 3.1 | U36: =IFERROR(IF(ROUND(S36*1.2,1)=0,"",ROUND(S36*1.2,1)),"")
A37: 5070 | B37: 파이터 | C37: 15 | D37: 결투 | E37: 적 1명에게 {ClassSkillValue}대미지를 입힌다. 아군과 적군이 각각 1명씩 남았을 경우 {ClassSkillValue}+{ClassSkillSubValue}대미지를 입힌다. | F37: 0 | G37: 0 | H37: 0 | I37: 0 | J37: 1 | K37: {0} | L37: 0 | N37: 1 | O37: 1.2 | P37: =IFERROR(IF(ROUND(N37*1.2,1)=0,"",ROUND(N37*1.2,1)),"") -> 1.2 | Q37: =IFERROR(IF(ROUND(O37*1.2,1)=0,"",ROUND(O37*1.2,1)),"") -> 1.4 | R37: =IFERROR(IF(ROUND(P37*1.2,1)=0,"",ROUND(P37*1.2,1)),"") -> 1.4 | S37: =IFERROR(IF(ROUND(Q37*1.2,1)=0,"",ROUND(Q37*1.2,1)),"") -> 1.7 | T37: =IFERROR(IF(ROUND(R37*1.2,1)=0,"",ROUND(R37*1.2,1)),"") -> 1.7 | U37: =IFERROR(IF(ROUND(S37*1.2,1)=0,"",ROUND(S37*1.2,1)),"") -> 2

Sheet 무기(기획용)
A1: WeaponIndex | B1: Class | C1: WeaponName | D1: WaeponDescription | E1: BonusMaxHPLv1 | F1: BonusMaxHPLv2 | G1: BonusMaxHPLv3 | H1: BonusMaxHPLv4 | I1: BonusMaxHPLv5 | J1: BonusATKLv1 | K1: BonusATKLv2 | L1: BonusATKLv3 | M1: BonusATKLv4 | N1: BonusATKLv5 | O1: BonusDEFLv1 | P1: BonusDEFLv2 | Q1: BonusDEFLv3 | R1: BonusDEFLv4 | S1: BonusDEFLv5 | T1: BonusCriticalRate | U1: BonusCounterRate | V1: BonusReduceRate | W1: BonusSpeed | X1: WeaponSkillIndex | Y1: WeaponSkillName | Z1: WeaponSkillDescription | AA1: IPCost | AB1: WeaponSkillEffect | AC1: WeaponSkillRange | AD1: WeaponSkillRangeLine | AE1: WeaponSkillTarget | AF1: WeaponSkillMultiTarget | AG1: WeaponSkill MultiTargetType | AH1: WeaponSkill MultiTargetCount | AI1: WeaponSkillValueLv1 | AJ1: WeaponSkillSubValueLv1 | AK1: WeaponSkillValueLv2 | AL1: WeaponSkillSubValueLv2 | AM1: WeaponSkillValueLv3 | AN1: WeaponSkillSubValueLv3
A2: 무기 인덱스 | B2: 직업 | C2: 무기명 | D2: 무기 설명 | E2: Lv1 최대 체력 증가량 | F2: Lv2 최대 체력 증가량 | G2: Lv3 최대 체력 증가량 | H2: Lv4 최대 체력 증가량 | I2: Lv5 최대 체력 증가량 | J2: Lv1 공격력 증가량 | K2: Lv2 공격력 증가량 | L2: Lv3 공격력 증가량 | M2: Lv4 공격력 증가량 | N2: Lv5 공격력 증가량 | O2: Lv1 방어력 증가량 | P2: Lv2 방어력 증가량 | Q2: Lv3 방어력 증가량 | R2: Lv4 방어력 증가량 | S2: Lv5 방어력 증가량 | T2: 치명타율 증가량 | U2: 반격율 증가량 | V2: 피해 경감 확률 증가량 | W2: 스피드 증가량 | X2: 무기 스킬 인덱스 | Y2: 무기 스킬명 | Z2: 무기 스킬 설명 | AA2: IP 코스트 | AB2: 무기 스킬 효과 (0 공격 1 회복 2 부활) | AC2: 무기 스킬 사정거리 (0 근거리 1 원거리) | AD2: 무기 스킬 사정거리 라인 0 전열 우선 (적 전열이 있을 경우 전열 공격) 1 전열/후열 선택 가능 2 후열 우선 | AE2: 무기 스킬 대상 (0 단일 1 복수 2 전체) | AF2: 무기 스킬 복수 대상 (스킬 대상 1일 경우) | AG2: 무기 스킬 복수 대상 타입 (0 후보 전체 1 랜덤) (스킬 대상 1일 경우) | AH2: 무기 스킬 복수 추가 대상 수 (스킬 대상 1일 경우) | AI2: 무기 스킬 계수 Lv1 | AJ2: 무기 스킬 추가 계수 Lv1 | AK2: 무기 스킬 계수 Lv2 | AL2: 무기 스킬 추가 계수 Lv2 | AM2: 무기 스킬 계수 Lv3 | AN2: 무기 스킬 추가 계수 Lv3 | AP2: 스킬 복수 대상
A3: 310101 | B3: 가디언 | C3: 하급 수호의 코어 | D3: 기본 제공 무기 | J3: 1 | K3: 2 | L3: 3 | M3: 4 | N3: 5 | X3: 311010 | Y3: 강타 | Z3: 적 유닛 1명에게 {WeaponSkillValue} 대미지를 준다. (전열 우선) | AA3: 10 | AB3: 0 | AC3: 0 | AD3: 0 | AE3: 0 | AI3: 1.5 | AK3: =IFERROR(IF(ROUND(AI3*1.2,1)=0,"",ROUND(AI3*1.2,1)),"") -> 1.8 | AL3: =IFERROR(IF(ROUND(AJ3*1.2,1)=0,"",ROUND(AJ3*1.2,1)),"") | AM3: =IFERROR(IF(ROUND(AK3*1.2,1)=0,"",ROUND(AK3*1.2,1)),"") -> 2.2 | AN3: =IFERROR(IF(ROUND(AL3*1.2,1)=0,"",ROUND(AL3*1.2,1)),"") | AP3: 8 | AQ3: 1 | AR3: 2
A4: 310102 | B4: 가디언 | C4: 중급 수호의 코어 | D4: 후열 특화 무기 | J4: 2 | K4: 3 | L4: 4 | M4: 5 | N4: 6 | T4: 0.15 | X4: 311020 | Y4: 기합 | Z4: 적 유닛 1명에게 기합을 날려 원거리 대미지 {WeaponSkillValue}를 준다. | AA4: 30 | AB4: 0 | AC4: 0 | AD4: 1 | AE4: 0 | AI4: 1.8 | AK4: =IFERROR(IF(ROUND(AI4*1.2,1)=0,"",ROUND(AI4*1.2,1)),"") -> 2.2 | AL4: =IFERROR(IF(ROUND(AJ4*1.2,1)=0,"",ROUND(AJ4*1.2,1)),"") | AM4: =IFERROR(IF(ROUND(AK4*1.2,1)=0,"",ROUND(AK4*1.2,1)),"") -> 2.6 | AN4: =IFERROR(IF(ROUND(AL4*1.2,1)=0,"",ROUND(AL4*1.2,1)),"") | AP4: 7 | AQ4: 타깃(0) | AR4: 3
A5: 310103 | B5: 가디언 | C5: 상급 수호의 코어 | D5: 최상급 무기 | J5: 3 | K5: 4 | L5: 5 | M5: 6 | N5: 7 | U5: 0.1 | X5: 311030 | Y5: 회전 베기 | Z5: 적 유닛 1명에게 {WeaponSkillValue} 대미지를 준다. (전열 우선) | AA5: 50 | AB5: 0 | AC5: 0 | AD5: 0 | AE5: 0 | AI5: 2.5 | AK5: =IFERROR(IF(ROUND(AI5*1.2,1)=0,"",ROUND(AI5*1.2,1)),"") -> 3 | AL5: =IFERROR(IF(ROUND(AJ5*1.2,1)=0,"",ROUND(AJ5*1.2,1)),"") | AM5: =IFERROR(IF(ROUND(AK5*1.2,1)=0,"",ROUND(AK5*1.2,1)),"") -> 3.6 | AN5: =IFERROR(IF(ROUND(AL5*1.2,1)=0,"",ROUND(AL5*1.2,1)),"") | AP5: 6 | AQ5: 5 | AR5: 4
A6: 310201 | B6: 블래스터 | C6: 하급 폭주의 코어 | D6: 기본 제공 무기 | J6: 1 | K6: 2 | L6: 3 | M6: 4 | N6: 5 | X6: 313010 | Y6: 매직 미사일 | Z6: 적 유닛 1명에게 {WeaponSkillValue} 대미지를 준다. | AA6: 10 | AB6: 0 | AC6: 1 | AD6: 1 | AE6: 0 | AI6: 1.5 | AK6: =IFERROR(IF(ROUND(AI6*1.2,1)=0,"",ROUND(AI6*1.2,1)),"") -> 1.8 | AL6: =IFERROR(IF(ROUND(AJ6*1.2,1)=0,"",ROUND(AJ6*1.2,1)),"") | AM6: =IFERROR(IF(ROUND(AK6*1.2,1)=0,"",ROUND(AK6*1.2,1)),"") -> 2.2 | AN6: =IFERROR(IF(ROUND(AL6*1.2,1)=0,"",ROUND(AL6*1.2,1)),"") | AP6: 열 전체 | AQ6: 9
A7: 310202 | B7: 블래스터 | C7: 중급 폭주의 코어 | D7: 전열 특화 무기 | J7: 2 | K7: 3 | L7: 4 | M7: 5 | N7: 6 | T7: 0.07 | U7: 0.07 | X7: 313020 | Y7: 더블 클로 | Z7: 적 1명에게 {WeaponSkillValue} 대미지를 주고, 인접한 적 1명에게 추가로 {WeaponSkillSubValue} 대미지를 준다. (근거리로 취급하나 후열 공격 가능) | AA7: 30 | AB7: 0 | AC7: 0 | AD7: 1 | AE7: 1 | AF7: {1,3,5} | AG7: 1 | AH7: 1 | AI7: 0.8 | AJ7: 0.8 | AK7: =IFERROR(IF(ROUND(AI7*1.2,1)=0,"",ROUND(AI7*1.2,1)),"") -> 1 | AL7: =IFERROR(IF(ROUND(AJ7*1.2,1)=0,"",ROUND(AJ7*1.2,1)),"") -> 1 | AM7: =IFERROR(IF(ROUND(AK7*1.2,1)=0,"",ROUND(AK7*1.2,1)),"") -> 1.2 | AN7: =IFERROR(IF(ROUND(AL7*1.2,1)=0,"",ROUND(AL7*1.2,1)),"") -> 1.2
A8: 310203 | B8: 블래스터 | C8: 상급 폭주의 코어 | D8: 최상급 무기 | J8: 3 | K8: 4 | L8: 5 | M8: 6 | N8: 7 | T8: 0.05 | V8: 0.05 | X8: 313030 | Y8: 마력 방출 | Z8: 적 모든 유닛에게 {WeaponSkillValue} 대미지를 준다. | AA8: 50 | AB8: 0 | AC8: 1 | AD8: 1 | AE8: 2 | AI8: 1.2 | AK8: =IFERROR(IF(ROUND(AI8*1.2,1)=0,"",ROUND(AI8*1.2,1)),"") -> 1.4 | AL8: =IFERROR(IF(ROUND(AJ8*1.2,1)=0,"",ROUND(AJ8*1.2,1)),"") | AM8: =IFERROR(IF(ROUND(AK8*1.2,1)=0,"",ROUND(AK8*1.2,1)),"") -> 1.7 | AN8: =IFERROR(IF(ROUND(AL8*1.2,1)=0,"",ROUND(AL8*1.2,1)),"")
A9: 310301 | B9: 스트라이커 | C9: 하급 정밀의 코어 | D9: 기본 제공 무기 | J9: 1 | K9: 2 | L9: 3 | M9: 4 | N9: 5 | X9: 312010 | Y9: 정밀 조준 | Z9: 적 유닛 1명에게 {WeaponSkillValue} 대미지를 준다. | AA9: 10 | AB9: 0 | AC9: 1 | AD9: 1 | AE9: 0 | AI9: 1.5 | AK9: =IFERROR(IF(ROUND(AI9*1.2,1)=0,"",ROUND(AI9*1.2,1)),"") -> 1.8 | AL9: =IFERROR(IF(ROUND(AJ9*1.2,1)=0,"",ROUND(AJ9*1.2,1)),"") | AM9: =IFERROR(IF(ROUND(AK9*1.2,1)=0,"",ROUND(AK9*1.2,1)),"") -> 2.2 | AN9: =IFERROR(IF(ROUND(AL9*1.2,1)=0,"",ROUND(AL9*1.2,1)),"")
A10: 310302 | B10: 스트라이커 | C10: 중급 정밀의 코어 | D10: 전열 특화 무기 | J10: 2 | K10: 3 | L10: 4 | M10: 5 | N10: 6 | U10: 0.15 | X10: 312020 | Y10: 숏보우 | Z10: 적 한 열의 적에게 화살을 발사하여 {WeaponSkillValue} 대미지를 준다 (전열 우선) | AA10: 30 | AB10: 0 | AC10: 0 | AD10: 0 | AE10: 1 | AF10: {9} | AG10: 0 | AI10: 1.2 | AK10: =IFERROR(IF(ROUND(AI10*1.2,1)=0,"",ROUND(AI10*1.2,1)),"") -> 1.4 | AL10: =IFERROR(IF(ROUND(AJ10*1.2,1)=0,"",ROUND(AJ10*1.2,1)),"") | AM10: =IFERROR(IF(ROUND(AK10*1.2,1)=0,"",ROUND(AK10*1.2,1)),"") -> 1.7 | AN10: =IFERROR(IF(ROUND(AL10*1.2,1)=0,"",ROUND(AL10*1.2,1)),"")
A11: 310303 | B11: 스트라이커 | C11: 상급 정밀의 코어 | D11: 최상급 무기 | J11: 3 | K11: 4 | L11: 5 | M11: 6 | N11: 7 | T11: 0.1 | X11: 312030 | Y11: 속사 | Z11: 적 유닛 한 명에게 {WeaponSkillValue} 대미지를 주는 화살을 두 발 발사한다. (확률 보정은 독립적으로 진행) | AA11: 50 | AB11: 0 | AC11: 1 | AD11: 1 | AE11: 0 | AI11: 1.2 | AJ11: 1.2 | AK11: =IFERROR(IF(ROUND(AI11*1.2,1)=0,"",ROUND(AI11*1.2,1)),"") -> 1.4 | AL11: =IFERROR(IF(ROUND(AJ11*1.2,1)=0,"",ROUND(AJ11*1.2,1)),"") -> 1.4 | AM11: =IFERROR(IF(ROUND(AK11*1.2,1)=0,"",ROUND(AK11*1.2,1)),"") -> 1.7 | AN11: =IFERROR(IF(ROUND(AL11*1.2,1)=0,"",ROUND(AL11*1.2,1)),"") -> 1.7
A12: 310401 | B12: 서포터 | C12: 하급 회복의 코어 | D12: 기본 제공 무기 | J12: 1 | K12: 2 | L12: 3 | M12: 4 | N12: 5 | X12: 314010 | Y12: 성광 | Z12: 적 유닛 1명에게 {WeaponSkillValue} 대미지를 준다. | AA12: 10 | AB12: 0 | AC12: 1 | AD12: 1 | AE12: 0 | AI12: 1.5 | AK12: =IFERROR(IF(ROUND(AI12*1.2,1)=0,"",ROUND(AI12*1.2,1)),"") -> 1.8 | AL12: =IFERROR(IF(ROUND(AJ12*1.2,1)=0,"",ROUND(AJ12*1.2,1)),"") | AM12: =IFERROR(IF(ROUND(AK12*1.2,1)=0,"",ROUND(AK12*1.2,1)),"") -> 2.2 | AN12: =IFERROR(IF(ROUND(AL12*1.2,1)=0,"",ROUND(AL12*1.2,1)),"")
A13: 310402 | B13: 서포터 | C13: 중급 회복의 코어 | D13: 공격 특화 무기 | J13: 5 | K13: 6 | L13: 7 | M13: 8 | N13: 9 | T13: 0.1 | X13: 314020 | Y13: 신성한 주먹 | Z13: 적 유닛 1명을 신성력을 두른 폭주의 코어로 근접 타격하여 {WeaponSkillValue} 대미지를 준다. (전열 우선) | AA13: 30 | AB13: 0 | AC13: 0 | AD13: 0 | AE13: 0 | AI13: 1.8 | AK13: =IFERROR(IF(ROUND(AI13*1.2,1)=0,"",ROUND(AI13*1.2,1)),"") -> 2.2 | AL13: =IFERROR(IF(ROUND(AJ13*1.2,1)=0,"",ROUND(AJ13*1.2,1)),"") | AM13: =IFERROR(IF(ROUND(AK13*1.2,1)=0,"",ROUND(AK13*1.2,1)),"") -> 2.6 | AN13: =IFERROR(IF(ROUND(AL13*1.2,1)=0,"",ROUND(AL13*1.2,1)),"")
A14: 310403 | B14: 서포터 | C14: 상급 회복의 코어 | D14: 최상급 무기 | J14: 3 | K14: 4 | L14: 5 | M14: 6 | N14: 7 | V14: 0.1 | X14: 314030 | Y14: 성스러운 일격 | Z14: 적 모든 유닛에게 {WeaponSkillValue} 대미지를 주고, 입힌 피해만큼 체력을 회복한다. | AA14: 50 | AB14: 0 | AC14: 1 | AD14: 1 | AE14: 2 | AI14: 1.5 | AK14: =IFERROR(IF(ROUND(AI14*1.2,1)=0,"",ROUND(AI14*1.2,1)),"") -> 1.8 | AL14: =IFERROR(IF(ROUND(AJ14*1.2,1)=0,"",ROUND(AJ14*1.2,1)),"") | AM14: =IFERROR(IF(ROUND(AK14*1.2,1)=0,"",ROUND(AK14*1.2,1)),"") -> 2.2 | AN14: =IFERROR(IF(ROUND(AL14*1.2,1)=0,"",ROUND(AL14*1.2,1)),"")
A15: 310501 | B15: 파이터 | C15: 하급 투쟁의 코어 | D15: 기본 제공 무기 | J15: 1 | K15: 2 | L15: 3 | M15: 4 | N15: 5 | X15: 315010 | Y15: 베어가르기 | Z15: 적 유닛 1명에게 {WeaponSkillValue} 대미지를 준다. (전열 우선) | AA15: 10 | AB15: 0 | AC15: 0 | AD15: 0 | AE15: 0 | AI15: 1.5 | AK15: =IFERROR(IF(ROUND(AI15*1.2,1)=0,"",ROUND(AI15*1.2,1)),"") -> 1.8 | AL15: =IFERROR(IF(ROUND(AJ15*1.2,1)=0,"",ROUND(AJ15*1.2,1)),"") | AM15: =IFERROR(IF(ROUND(AK15*1.2,1)=0,"",ROUND(AK15*1.2,1)),"") -> 2.2 | AN15: =IFERROR(IF(ROUND(AL15*1.2,1)=0,"",ROUND(AL15*1.2,1)),"")
A16: 310502 | B16: 파이터 | C16: 중급 투쟁의 코어 | D16: 후열 특화 무기 | J16: 2 | K16: 3 | L16: 4 | M16: 5 | N16: 6 | T16: 0.07 | V16: 0.07 | X16: 315020 | Y16: 환영 공격 | Z16: 자신이 후열일 경우 후열 공격이 가능하다. 근거리 공격 {WeaponSkillValue} 대미지를 준다. (후열이 아닌 경우 전열 우선) | AA16: 30 | AB16: 0 | AC16: 1 | AD16: 0 | AE16: 0 | AI16: 1.8 | AK16: =IFERROR(IF(ROUND(AI16*1.2,1)=0,"",ROUND(AI16*1.2,1)),"") -> 2.2 | AL16: =IFERROR(IF(ROUND(AJ16*1.2,1)=0,"",ROUND(AJ16*1.2,1)),"") | AM16: =IFERROR(IF(ROUND(AK16*1.2,1)=0,"",ROUND(AK16*1.2,1)),"") -> 2.6 | AN16: =IFERROR(IF(ROUND(AL16*1.2,1)=0,"",ROUND(AL16*1.2,1)),"")
A17: 310503 | B17: 파이터 | C17: 상급 투쟁의 코어 | D17: 최상급 무기 | J17: 3 | K17: 4 | L17: 5 | M17: 6 | N17: 7 | T17: 0.1 | X17: 315030 | Y17: 강습 | Z17: 적 유닛 1명에게 {WeaponSkillValue} 대미지를 준다. (전열 우선) | AA17: 50 | AB17: 0 | AC17: 0 | AD17: 0 | AE17: 0 | AI17: 2.5 | AK17: =IFERROR(IF(ROUND(AI17*1.2,1)=0,"",ROUND(AI17*1.2,1)),"") -> 3 | AL17: =IFERROR(IF(ROUND(AJ17*1.2,1)=0,"",ROUND(AJ17*1.2,1)),"") | AM17: =IFERROR(IF(ROUND(AK17*1.2,1)=0,"",ROUND(AK17*1.2,1)),"") -> 3.6 | AN17: =IFERROR(IF(ROUND(AL17*1.2,1)=0,"",ROUND(AL17*1.2,1)),"")

Sheet 스탯 시뮬
A1: 범례 | B1: 타 시트에서 가져오는 값
B2: 이 시트에서 바꾸는 값
B3: 이 시트에서 계산되는 값
B4: 고정치
A5: 1. 아군 유닛 스테이터스
B6: 파티 멤버 | C6: 캐릭터명 | D6: 캐릭터 콘셉트 | E6: 유닛 랭크 | F6: 랭크 표시 | G6: 최대 I.P | H6: 유닛 최대 체력 | I6: 유닛 공격력 | J6: 유닛 방어력 | K6: 치명타율 | L6: 반격율 | M6: 피해 경감률 | N6: 스피드
B7: 1 | C7: ='전투 시뮬'!C14 -> 저스티스 | D7: =IFERROR(VLOOKUP(C7,'아군 유닛'!C6:N9,3,FALSE),"") -> 평균적인 능력치를 지닌 근거리 히어로 | E7: ='전투 시뮬'!D14 -> 3 | F7: =IFERROR(VLOOKUP($E7,'성장 시스템'!#REF!,2,FALSE),"") | G7: =IFERROR(VLOOKUP(E7,'범례(시뮬용)'!$L$15:$M$29,2,FALSE),"") -> 140 | H7: =IFERROR(VLOOKUP($C$7,'아군 유닛'!$C$6:$N$9,COLUMN(A1)+3,FALSE),"") -> 6 | I7: =IFERROR(VLOOKUP($C$7,'아군 유닛'!$C$6:$N$9,COLUMN(B1)+3,FALSE),"") -> 9 | J7: =IFERROR(VLOOKUP($C$7,'아군 유닛'!$C$6:$N$9,COLUMN(C1)+3,FALSE),"") -> 5 | K7: =IFERROR(VLOOKUP($C$7,'아군 유닛'!$C$6:$N$9,COLUMN(D1)+3,FALSE),"") -> 0.15 | L7: =IFERROR(VLOOKUP($C$7,'아군 유닛'!$C$6:$N$9,COLUMN(E1)+3,FALSE),"") -> 0.15 | M7: =IFERROR(VLOOKUP($C$7,'아군 유닛'!$C$6:$N$9,COLUMN(F1)+3,FALSE),"") -> 0.15 | N7: =IFERROR(VLOOKUP($C$7,'아군 유닛'!$C$6:$N$9,COLUMN(G1)+3,FALSE),"") -> 2
B8: 2 | C8: ='전투 시뮬'!C15 -> 루미나 | D8: =IFERROR(VLOOKUP(C8,'아군 유닛'!C7:N10,3,FALSE),"") -> 다중 공격에 특화된 원거리 히어로 | E8: ='전투 시뮬'!D15 -> 3 | F8: =IFERROR(VLOOKUP($E8,'성장 시스템'!#REF!,2,FALSE),"") | G8: =IFERROR(VLOOKUP(E8,'범례(시뮬용)'!$L$15:$M$29,2,FALSE),"") -> 140 | H8: =IFERROR(VLOOKUP($C$8,'아군 유닛'!$C$6:$N$9,COLUMN(A2)+3,FALSE),"") -> 4 | I8: =IFERROR(VLOOKUP($C$8,'아군 유닛'!$C$6:$N$9,COLUMN(B2)+3,FALSE),"") -> 12 | J8: =IFERROR(VLOOKUP($C$8,'아군 유닛'!$C$6:$N$9,COLUMN(C2)+3,FALSE),"") -> 4 | K8: =IFERROR(VLOOKUP($C$8,'아군 유닛'!$C$6:$N$9,COLUMN(D2)+3,FALSE),"") -> 0.3 | L8: =IFERROR(VLOOKUP($C$8,'아군 유닛'!$C$6:$N$9,COLUMN(E2)+3,FALSE),"") -> 0.1 | M8: =IFERROR(VLOOKUP($C$8,'아군 유닛'!$C$6:$N$9,COLUMN(F2)+3,FALSE),"") -> 0.2 | N8: =IFERROR(VLOOKUP($C$8,'아군 유닛'!$C$6:$N$9,COLUMN(G2)+3,FALSE),"") -> 3
B9: 3 | C9: ='전투 시뮬'!C16 -> 블랙 불릿 | D9: =IFERROR(VLOOKUP(C9,'아군 유닛'!C8:N11,3,FALSE),"") -> 단일 공격에 특화된 원거리 히어로 | E9: ='전투 시뮬'!D16 -> 3 | F9: =IFERROR(VLOOKUP($E9,'성장 시스템'!#REF!,2,FALSE),"") | G9: =IFERROR(VLOOKUP(E9,'범례(시뮬용)'!$L$15:$M$29,2,FALSE),"") -> 140 | H9: =IFERROR(VLOOKUP($C$9,'아군 유닛'!$C$6:$N$9,COLUMN(A3)+3,FALSE),"") -> 6 | I9: =IFERROR(VLOOKUP($C$9,'아군 유닛'!$C$6:$N$9,COLUMN(B3)+3,FALSE),"") -> 12 | J9: =IFERROR(VLOOKUP($C$9,'아군 유닛'!$C$6:$N$9,COLUMN(C3)+3,FALSE),"") -> 2 | K9: =IFERROR(VLOOKUP($C$9,'아군 유닛'!$C$6:$N$9,COLUMN(D3)+3,FALSE),"") -> 0.2 | L9: =IFERROR(VLOOKUP($C$9,'아군 유닛'!$C$6:$N$9,COLUMN(E3)+3,FALSE),"") -> 0.05 | M9: =IFERROR(VLOOKUP($C$9,'아군 유닛'!$C$6:$N$9,COLUMN(F3)+3,FALSE),"") -> 0.1 | N9: =IFERROR(VLOOKUP($C$9,'아군 유닛'!$C$6:$N$9,COLUMN(G3)+3,FALSE),"") -> 2
B10: 4 | C10: ='전투 시뮬'!C17 -> 네코밍 | D10: =IFERROR(VLOOKUP(C10,'아군 유닛'!C9:N12,3,FALSE),"") -> 회복이 가능한 원거리 히어로 | E10: ='전투 시뮬'!D17 -> 2 | F10: =IFERROR(VLOOKUP($E10,'성장 시스템'!#REF!,2,FALSE),"") | G10: =IFERROR(VLOOKUP(E10,'범례(시뮬용)'!$L$15:$M$29,2,FALSE),"") -> 130 | H10: =IFERROR(VLOOKUP($C$10,'아군 유닛'!$C$6:$N$9,COLUMN(A4)+3,FALSE),"") -> 6 | I10: =IFERROR(VLOOKUP($C$10,'아군 유닛'!$C$6:$N$9,COLUMN(B4)+3,FALSE),"") -> 8 | J10: =IFERROR(VLOOKUP($C$10,'아군 유닛'!$C$6:$N$9,COLUMN(C4)+3,FALSE),"") -> 6 | K10: =IFERROR(VLOOKUP($C$10,'아군 유닛'!$C$6:$N$9,COLUMN(D4)+3,FALSE),"") -> 0.1 | L10: =IFERROR(VLOOKUP($C$10,'아군 유닛'!$C$6:$N$9,COLUMN(E4)+3,FALSE),"") -> 0.1 | M10: =IFERROR(VLOOKUP($C$10,'아군 유닛'!$C$6:$N$9,COLUMN(F4)+3,FALSE),"") -> 0.15 | N10: =IFERROR(VLOOKUP($C$10,'아군 유닛'!$C$6:$N$9,COLUMN(G4)+3,FALSE),"") -> 2
A12: 2. 유닛 레벨업 스테이터스
B13: 파티 멤버 | C13: 캐릭터명 | D13: 클래스 콘셉트 | E13: 유닛 랭크 | F13: 랭크 표시 | G13: 최대 I.P | H13: 랭크업 유닛 최대 체력 = 유닛 최대 체력 + 캐릭터 보정치 × 레벨 | I13: 랭크업 유닛 공격력 = 유닛 공격력 + 캐릭터 보정치 × 레벨 | J13: 랭크업 유닛 방어력 = 유닛 방어력 + 캐릭터 보정치 × 레벨
B14: 1 | C14: =$C$7 -> 저스티스 | D14: =$D$7 -> 평균적인 능력치를 지닌 근거리 히어로 | E14: =E7 -> 3 | F14: =IFERROR(VLOOKUP($E14,'성장 시스템'!#REF!,2,FALSE),"") | G14: =IFERROR(VLOOKUP(E14,'범례(시뮬용)'!$L$15:$M$29,2,FALSE),"") -> 140 | H14: =H7+'아군 유닛'!O6*($E14-1) -> 14 | I14: =I7+'아군 유닛'!P6*($E$14-1) -> 17 | J14: =J7+'아군 유닛'!Q6*($E$14-1) -> 9
B15: 2 | C15: =$C$8 -> 루미나 | D15: =$D$8 -> 다중 공격에 특화된 원거리 히어로 | E15: =E8 -> 3 | F15: =IFERROR(VLOOKUP($E15,'성장 시스템'!#REF!,2,FALSE),"") | G15: =IFERROR(VLOOKUP(E15,'범례(시뮬용)'!$L$15:$M$29,2,FALSE),"") -> 140 | H15: =H$8+'아군 유닛'!O7*($E$15-1) -> 12 | I15: =I$8+'아군 유닛'!P7*($E$15-1) -> 20 | J15: =J$8+'아군 유닛'!Q7*($E$15-1) -> 8
B16: 3 | C16: =$C$9 -> 블랙 불릿 | D16: =$D$9 -> 단일 공격에 특화된 원거리 히어로 | E16: =E9 -> 3 | F16: =IFERROR(VLOOKUP($E16,'성장 시스템'!#REF!,2,FALSE),"") | G16: =IFERROR(VLOOKUP(E16,'범례(시뮬용)'!$L$15:$M$29,2,FALSE),"") -> 140 | H16: =H$9+'아군 유닛'!O8*($E$16-1) -> 10 | I16: =I$9+'아군 유닛'!P8*($E$16-1) -> 24 | J16: =J$9+'아군 유닛'!Q8*($E$16-1) -> 6
B17: 4 | C17: =$C$10 -> 네코밍 | D17: =$D$10 -> 회복이 가능한 원거리 히어로 | E17: =E10 -> 2 | F17: =IFERROR(VLOOKUP($E17,'성장 시스템'!#REF!,2,FALSE),"") | G17: =IFERROR(VLOOKUP(E17,'범례(시뮬용)'!$L$15:$M$29,2,FALSE),"") -> 130 | H17: =H$10+'아군 유닛'!O9*($E$17-1) -> 11 | I17: =I$10+'아군 유닛'!P9*($E$17-1) -> 12 | J17: =J$10+'아군 유닛'!Q9*($E$17-1) -> 7
A19: 3. 유닛 무기 스테이터스
G20: 무기 추가 스테이터스
B21: 파티 멤버 | C21: 캐릭터명 | D21: 착용 무기 | E21: 무기 설명 | F21: 무기 레벨 | G21: 최대 체력 증가량 | H21: 공격력 증가량 | I21: 방어력 증가량 | J21: 치명타율 증가량 | K21: 반격율 증가량 | L21: 피해 경감 확률 증가량 | M21: 스피드 증가량
B22: 1 | C22: =$C$7 -> 저스티스 | D22: 하급 투쟁의 코어 | E22: =IFERROR(INDEX('무기(기획용)'!$D$3:$D$17,MATCH(D22,'무기(기획용)'!$C$3:$C$17,0)),"") -> 기본 제공 무기 | F22: 1 | G22: =IFERROR(INDEX('무기(기획용)'!$E$3:$I$17,MATCH($D22,'무기(기획용)'!$C$3:$C$17,0),F22),"") -> 0 | H22: =IFERROR(INDEX('무기(기획용)'!$J$3:$N$17,MATCH($D22,'무기(기획용)'!$C$3:$C$17,0),$F22),"") -> 1 | I22: =IFERROR(INDEX('무기(기획용)'!$O$3:$S$17,MATCH($D22,'무기(기획용)'!$C$3:$C$17,0),F22),"") -> 0 | J22: =IFERROR(INDEX('무기(기획용)'!T$3:T$17,MATCH($D22,'무기(기획용)'!$C$3:$C$17,0)),"") -> 0 | K22: =IFERROR(INDEX('무기(기획용)'!U$3:U$17,MATCH($D$22,'무기(기획용)'!$C$3:$C$17,0)),"") -> 0 | L22: =IFERROR(INDEX('무기(기획용)'!V$3:V$17,MATCH($D$22,'무기(기획용)'!$C$3:$C$17,0)),"") -> 0 | M22: =IFERROR(INDEX('무기(기획용)'!W$3:W$17,MATCH($D22,'무기(기획용)'!$C$3:$C$17,0)),"") -> 0
B23: 2 | C23: =$C$8 -> 루미나 | D23: 하급 폭주의 코어 | E23: =IFERROR(INDEX('무기(기획용)'!$D$3:$D$17,MATCH(D23,'무기(기획용)'!$C$3:$C$17,0)),"") -> 기본 제공 무기 | F23: 1 | G23: =IFERROR(INDEX('무기(기획용)'!$E$3:$I$17,MATCH($D23,'무기(기획용)'!$C$3:$C$17,0),F23),"") -> 0 | H23: =IFERROR(INDEX('무기(기획용)'!$J$3:$N$17,MATCH($D23,'무기(기획용)'!$C$3:$C$17,0),$F23),"") -> 1 | I23: =IFERROR(INDEX('무기(기획용)'!$O$3:$S$17,MATCH($D23,'무기(기획용)'!$C$3:$C$17,0),F23),"") -> 0 | J23: =IFERROR(INDEX('무기(기획용)'!T$3:T$17,MATCH($D$23,'무기(기획용)'!$C$3:$C$17,0)),"") -> 0 | K23: =IFERROR(INDEX('무기(기획용)'!U$3:U$17,MATCH($D$23,'무기(기획용)'!$C$3:$C$17,0)),"") -> 0 | L23: =IFERROR(INDEX('무기(기획용)'!V$3:V$17,MATCH($D$23,'무기(기획용)'!$C$3:$C$17,0)),"") -> 0 | M23: =IFERROR(INDEX('무기(기획용)'!W$3:W$17,MATCH($D$23,'무기(기획용)'!$C$3:$C$17,0)),"") -> 0
B24: 3 | C24: =$C$9 -> 블랙 불릿 | D24: 하급 정밀의 코어 | E24: =IFERROR(INDEX('무기(기획용)'!$D$3:$D$17,MATCH(D24,'무기(기획용)'!$C$3:$C$17,0)),"") -> 기본 제공 무기 | F24: 1 | G24: =IFERROR(INDEX('무기(기획용)'!$E$3:$I$17,MATCH($D24,'무기(기획용)'!$C$3:$C$17,0),F24),"") -> 0 | H24: =IFERROR(INDEX('무기(기획용)'!$J$3:$N$17,MATCH($D24,'무기(기획용)'!$C$3:$C$17,0),$F24),"") -> 1 | I24: =IFERROR(INDEX('무기(기획용)'!$O$3:$S$17,MATCH($D24,'무기(기획용)'!$C$3:$C$17,0),F24),"") -> 0 | J24: =IFERROR(INDEX('무기(기획용)'!T$3:T$17,MATCH($D$24,'무기(기획용)'!$C$3:$C$17,0)),"") -> 0 | K24: =IFERROR(INDEX('무기(기획용)'!U$3:U$17,MATCH($D$24,'무기(기획용)'!$C$3:$C$17,0)),"") -> 0 | L24: =IFERROR(INDEX('무기(기획용)'!V$3:V$17,MATCH($D$24,'무기(기획용)'!$C$3:$C$17,0)),"") -> 0 | M24: =IFERROR(INDEX('무기(기획용)'!W$3:W$17,MATCH($D$24,'무기(기획용)'!$C$3:$C$17,0)),"") -> 0
B25: 4 | C25: =$C$10 -> 네코밍 | D25: 하급 회복의 코어 | E25: =IFERROR(INDEX('무기(기획용)'!$D$3:$D$17,MATCH(D25,'무기(기획용)'!$C$3:$C$17,0)),"") -> 기본 제공 무기 | F25: 1 | G25: =IFERROR(INDEX('무기(기획용)'!$E$3:$I$17,MATCH($D25,'무기(기획용)'!$C$3:$C$17,0),F25),"") -> 0 | H25: =IFERROR(INDEX('무기(기획용)'!$J$3:$N$17,MATCH($D25,'무기(기획용)'!$C$3:$C$17,0),$F25),"") -> 1 | I25: =IFERROR(INDEX('무기(기획용)'!$O$3:$S$17,MATCH($D25,'무기(기획용)'!$C$3:$C$17,0),F25),"") -> 0 | J25: =IFERROR(INDEX('무기(기획용)'!T$3:T$17,MATCH($D$25,'무기(기획용)'!$C$3:$C$17,0)),"") -> 0 | K25: =IFERROR(INDEX('무기(기획용)'!U$3:U$17,MATCH($D$25,'무기(기획용)'!$C$3:$C$17,0)),"") -> 0 | L25: =IFERROR(INDEX('무기(기획용)'!V$3:V$17,MATCH($D$25,'무기(기획용)'!$C$3:$C$17,0)),"") -> 0 | M25: =IFERROR(INDEX('무기(기획용)'!W$3:W$17,MATCH($D$25,'무기(기획용)'!$C$3:$C$17,0)),"") -> 0
A27: 4. 유닛 스킬
B28: 파티 멤버 | C28: 캐릭터명 | D28: 유닛 레벨 | E28: 착용 직업 스킬 | F28: 착용 직업 스킬 설명 | G28: 착용 무기 | H28: 착용 무기 스킬 | I28: 착용 무기 스킬 설명
B29: 1 | C29: =$C$7 -> 저스티스 | D29: =$E$14 -> 3 | E29: 도발 베기 | F29: =IFERROR(VLOOKUP($E29,'직업 스킬(기획용)'!$D$3:$E$30,2,FALSE),"") -> 적 1명에게 {ClassSkillValue} 대미지를 입히고, 1턴 동안 해당 대상이 단일 공격 시 자신을 공격하게 한다. (적 전열이 있을 경우, 전열 우선 공격) | G29: =$D$22 -> 하급 투쟁의 코어 | H29: =IFERROR(INDEX('무기(기획용)'!Y$3:Y$17,MATCH($G29,'무기(기획용)'!$C$3:$C$17,0)),"") -> 베어가르기 | I29: =IFERROR(INDEX('무기(기획용)'!Z$3:Z$17,MATCH($H29,'무기(기획용)'!$Y$3:$Y$17,0)),"") -> 적 유닛 1명에게 {WeaponSkillValue} 대미지를 준다. (전열 우선)
B30: 2 | C30: =$C$8 -> 루미나 | D30: =$E$15 -> 3 | E30: 파이어볼 | F30: =IFERROR(VLOOKUP($E30,'직업 스킬(기획용)'!$D$3:$E$30,2,FALSE),"") -> 적 1명에게 {ClassSkillValue} 대미지를 입힌다. | G30: =$D$23 -> 하급 폭주의 코어 | H30: =IFERROR(INDEX('무기(기획용)'!Y$3:Y$17,MATCH($G30,'무기(기획용)'!$C$3:$C$17,0)),"") -> 매직 미사일 | I30: =IFERROR(INDEX('무기(기획용)'!Z$3:Z$17,MATCH($H30,'무기(기획용)'!$Y$3:$Y$17,0)),"") -> 적 유닛 1명에게 {WeaponSkillValue} 대미지를 준다.
B31: 3 | C31: =$C$9 -> 블랙 불릿 | D31: =$E$16 -> 3 | E31: 정밀 사격 | F31: =IFERROR(VLOOKUP($E31,'직업 스킬(기획용)'!$D$3:$E$30,2,FALSE),"") -> 적 1명에게 {ClassSkillValue} 대미지를 입힌다. | G31: =$D$24 -> 하급 정밀의 코어 | H31: =IFERROR(INDEX('무기(기획용)'!Y$3:Y$17,MATCH($G31,'무기(기획용)'!$C$3:$C$17,0)),"") -> 정밀 조준 | I31: =IFERROR(INDEX('무기(기획용)'!Z$3:Z$17,MATCH($H31,'무기(기획용)'!$Y$3:$Y$17,0)),"") -> 적 유닛 1명에게 {WeaponSkillValue} 대미지를 준다.
B32: 4 | C32: =$C$10 -> 네코밍 | D32: =$E$17 -> 2 | E32: 힐 | F32: =IFERROR(VLOOKUP($E32,'직업 스킬(기획용)'!$D$3:$E$30,2,FALSE),"") -> 아군 1명 체력 30% 회복, IP 10 고정 회복 | G32: =$D$25 -> 하급 회복의 코어 | H32: =IFERROR(INDEX('무기(기획용)'!Y$3:Y$17,MATCH($G32,'무기(기획용)'!$C$3:$C$17,0)),"") -> 성광 | I32: =IFERROR(INDEX('무기(기획용)'!Z$3:Z$17,MATCH($H32,'무기(기획용)'!$Y$3:$Y$17,0)),"") -> 적 유닛 1명에게 {WeaponSkillValue} 대미지를 준다.
A34: 5. 최종 스테이터스
E35: 캐릭터 최종 스테이터스
B36: 파티 멤버 | C36: 캐릭터명 | D36: 유닛 레벨 | E36: 최대 체력 | F36: 공격력 | G36: 방어력 | H36: 치명타율 | I36: 반격율 | J36: 피해 경감률 | K36: 스피드 | L36: 착용 직업 스킬 | M36: 착용 무기 | N36: 착용 무기 스킬
B37: 1 | C37: =$C$7 -> 저스티스 | D37: =$E$14 -> 3 | E37: =SUM(H14,G22) -> 14 | F37: =SUM(I14,H22) -> 18 | G37: =SUM(J14,I22) -> 9 | H37: =MIN(SUM(K7,J22),70%) -> 0.15 | I37: =MIN(SUM(L7,K22),70%) -> 0.15 | J37: =MIN(SUM(M7,L22),70%) -> 0.15 | K37: =SUM(N7,M22) -> 2 | L37: =$E$29 -> 도발 베기 | M37: =$D$22 -> 하급 투쟁의 코어 | N37: =$H$29 -> 베어가르기
B38: 2 | C38: =$C$8 -> 루미나 | D38: =$E$15 -> 3 | E38: =SUM(H15,G23) -> 12 | F38: =SUM(I15,H23) -> 21 | G38: =SUM(J15,I23) -> 8 | H38: =MIN(SUM(K8,J23),70%) -> 0.3 | I38: =MIN(SUM(L8,K23),70%) -> 0.1 | J38: =MIN(SUM(M8,L23),70%) -> 0.2 | K38: =SUM(N8,M23) -> 3 | L38: =$E$30 -> 파이어볼 | M38: =$D$23 -> 하급 폭주의 코어 | N38: =$H$30 -> 매직 미사일
B39: 3 | C39: =$C$9 -> 블랙 불릿 | D39: =$E$16 -> 3 | E39: =SUM(H16,G24) -> 10 | F39: =SUM(I16,H24) -> 25 | G39: =SUM(J16,I24) -> 6 | H39: =MIN(SUM(K9,J24),70%) -> 0.2 | I39: =MIN(SUM(L9,K24),70%) -> 0.05 | J39: =MIN(SUM(M9,L24),70%) -> 0.1 | K39: =SUM(N9,M24) -> 2 | L39: =$E$31 -> 정밀 사격 | M39: =$D$24 -> 하급 정밀의 코어 | N39: =$H$31 -> 정밀 조준
B40: 4 | C40: =$C$10 -> 네코밍 | D40: =$E$17 -> 2 | E40: =SUM(H17,G25) -> 11 | F40: =SUM(I17,H25) -> 13 | G40: =SUM(J17,I25) -> 7 | H40: =MIN(SUM(K10,J25),70%) -> 0.1 | I40: =MIN(SUM(L10,K25),70%) -> 0.1 | J40: =MIN(SUM(M10,L25),70%) -> 0.15 | K40: =SUM(N10,M25) -> 2 | L40: =$E$32 -> 힐 | M40: =$D$25 -> 하급 회복의 코어 | N40: =$H$32 -> 성광

Sheet 범례(시뮬용)
A1: 현재 클래스 | B1: 현재 랭크 | C1: 사용 가능 스킬1 | D1: 사용 가능 스킬2 | E1: 사용 가능 스킬3 | F1: 사용 가능 스킬4 | G1: 사용 가능 스킬5 | H1: 사용 가능 스킬6 | I1: 사용 가능 스킬7 | L1: 현재 클래스 | M1: 착용 가능 무기1 | N1: 착용 가능 무기2 | O1: 착용 가능 무기3
A2: ='스탯 시뮬'!C7 -> 저스티스 | B2: ='스탯 시뮬'!E14 -> 3 | C2: =IFERROR(INDEX($C$8:$I$114,$J2,COLUMN(A1))&"","") | D2: =IFERROR(INDEX($C$8:$I$114,$J2,COLUMN(B1))&"","") | E2: =IFERROR(INDEX($C$8:$I$114,$J2,COLUMN(C1))&"","") | F2: =IFERROR(INDEX($C$8:$I$114,$J2,COLUMN(D1))&"","") | G2: =IFERROR(INDEX($C$8:$I$114,$J2,COLUMN(E1))&"","") | H2: =IFERROR(INDEX($C$8:$I$114,$J2,COLUMN(F1))&"","") | I2: =IFERROR(INDEX($C$8:$I$114,$J2,COLUMN(G1))&"","") | J2: {=MATCH(1,($A$8:$A$114=$A2)*($B$8:$B$114=$B2),0)} -> #N/A | L2: =A2 -> 저스티스 | M2: =IFERROR(VLOOKUP($L2,$L$8:$O$12,COLUMN(A1)+1,FALSE),"") | N2: =IFERROR(VLOOKUP($L2,$L$8:$O$12,COLUMN(B1)+1,FALSE),"") | O2: =IFERROR(VLOOKUP($L2,$L$8:$O$12,COLUMN(C1)+1,FALSE),"")
A3: ='스탯 시뮬'!C8 -> 루미나 | B3: ='스탯 시뮬'!E15 -> 3 | C3: =IFERROR(INDEX($C$8:$I$114,$J3,COLUMN(A2))&"","") | D3: =IFERROR(INDEX($C$8:$I$114,$J3,COLUMN(B2))&"","") | E3: =IFERROR(INDEX($C$8:$I$114,$J3,COLUMN(C2))&"","") | F3: =IFERROR(INDEX($C$8:$I$114,$J3,COLUMN(D2))&"","") | G3: =IFERROR(INDEX($C$8:$I$114,$J3,COLUMN(E2))&"","") | H3: =IFERROR(INDEX($C$8:$I$114,$J3,COLUMN(F2))&"","") | I3: =IFERROR(INDEX($C$8:$I$114,$J3,COLUMN(G2))&"","") | J3: {=MATCH(1,($A$8:$A$114=$A3)*($B$8:$B$114=$B3),0)} -> #N/A | L3: =A3 -> 루미나 | M3: =IFERROR(VLOOKUP($L3,$L$8:$O$12,COLUMN(A2)+1,FALSE),"") | N3: =IFERROR(VLOOKUP($L3,$L$8:$O$12,COLUMN(B2)+1,FALSE),"") | O3: =IFERROR(VLOOKUP($L3,$L$8:$O$12,COLUMN(C2)+1,FALSE),"")
A4: ='스탯 시뮬'!C9 -> 블랙 불릿 | B4: ='스탯 시뮬'!E16 -> 3 | C4: =IFERROR(INDEX($C$8:$I$114,$J4,COLUMN(A3))&"","") | D4: =IFERROR(INDEX($C$8:$I$114,$J4,COLUMN(B3))&"","") | E4: =IFERROR(INDEX($C$8:$I$114,$J4,COLUMN(C3))&"","") | F4: =IFERROR(INDEX($C$8:$I$114,$J4,COLUMN(D3))&"","") | G4: =IFERROR(INDEX($C$8:$I$114,$J4,COLUMN(E3))&"","") | H4: =IFERROR(INDEX($C$8:$I$114,$J4,COLUMN(F3))&"","") | I4: =IFERROR(INDEX($C$8:$I$114,$J4,COLUMN(G3))&"","") | J4: {=MATCH(1,($A$8:$A$114=$A4)*($B$8:$B$114=$B4),0)} -> #N/A | L4: =A4 -> 블랙 불릿 | M4: =IFERROR(VLOOKUP($L4,$L$8:$O$12,COLUMN(A3)+1,FALSE),"") | N4: =IFERROR(VLOOKUP($L4,$L$8:$O$12,COLUMN(B3)+1,FALSE),"") | O4: =IFERROR(VLOOKUP($L4,$L$8:$O$12,COLUMN(C3)+1,FALSE),"")
A5: ='스탯 시뮬'!C10 -> 네코밍 | B5: ='스탯 시뮬'!E17 -> 2 | C5: =IFERROR(INDEX($C$8:$I$114,$J5,COLUMN(A4))&"","") | D5: =IFERROR(INDEX($C$8:$I$114,$J5,COLUMN(B4))&"","") | E5: =IFERROR(INDEX($C$8:$I$114,$J5,COLUMN(C4))&"","") | F5: =IFERROR(INDEX($C$8:$I$114,$J5,COLUMN(D4))&"","") | G5: =IFERROR(INDEX($C$8:$I$114,$J5,COLUMN(E4))&"","") | H5: =IFERROR(INDEX($C$8:$I$114,$J5,COLUMN(F4))&"","") | I5: =IFERROR(INDEX($C$8:$I$114,$J5,COLUMN(G4))&"","") | J5: {=MATCH(1,($A$8:$A$114=$A5)*($B$8:$B$114=$B5),0)} -> #N/A | L5: =A5 -> 네코밍 | M5: =IFERROR(VLOOKUP($L5,$L$8:$O$12,COLUMN(A4)+1,FALSE),"") | N5: =IFERROR(VLOOKUP($L5,$L$8:$O$12,COLUMN(B4)+1,FALSE),"") | O5: =IFERROR(VLOOKUP($L5,$L$8:$O$12,COLUMN(C4)+1,FALSE),"")
A7: 클래스명 | B7: 현재 랭크 | C7: 사용 가능 스킬1 | D7: 사용 가능 스킬2 | E7: 사용 가능 스킬3 | F7: 사용 가능 스킬4 | G7: 사용 가능 스킬5 | H7: 사용 가능 스킬6 | I7: 사용 가능 스킬7 | L7: 현재 클래스 | M7: 착용 가능 무기1 | N7: 착용 가능 무기2 | O7: 착용 가능 무기3
A8: 가디언 | B8: 1 | C8: 도발 베기 | L8: 가디언 | M8: 하급 수호의 코어 | N8: 중급 수호의 코어 | O8: 상급 수호의 코어
A9: 가디언 | B9: 2 | C9: 도발 베기 | L9: 스트라이커 | M9: 하급 정밀의 코어 | N9: 중급 정밀의 코어 | O9: 상급 정밀의 코어
A10: 가디언 | B10: 3 | C10: 도발 베기 | D10: 일렬 베기 | L10: 블래스터 | M10: 하급 폭주의 코어 | N10: 중급 폭주의 코어 | O10: 상급 폭주의 코어
A11: 가디언 | B11: 4 | C11: 도발 베기 | D11: 일렬 베기 | L11: 서포터 | M11: 하급 회복의 코어 | N11: 중급 회복의 코어 | O11: 상급 회복의 코어
A12: 가디언 | B12: 5 | C12: 도발 베기 | D12: 일렬 베기 | E12: 관통 | L12: 파이터 | M12: 하급 투쟁의 코어 | N12: 중급 투쟁의 코어 | O12: 상급 투쟁의 코어
A13: 가디언 | B13: 6 | C13: 도발 베기 | D13: 일렬 베기 | E13: 관통
A14: 가디언 | B14: 7 | C14: 도발 베기 | D14: 일렬 베기 | E14: 관통 | F14: 광역 도발 | L14: 랭크 | M14: 최대 호감도
A15: 가디언 | B15: 8 | C15: 도발 베기 | D15: 일렬 베기 | E15: 관통 | F15: 광역 도발 | L15: 1 | M15: 120
A16: 가디언 | B16: 9 | C16: 도발 베기 | D16: 일렬 베기 | E16: 관통 | F16: 광역 도발 | L16: 2 | M16: 130
A17: 가디언 | B17: 10 | C17: 도발 베기 | D17: 일렬 베기 | E17: 관통 | F17: 광역 도발 | G17: 돌파 | L17: 3 | M17: 140
A18: 가디언 | B18: 11 | C18: 도발 베기 | D18: 일렬 베기 | E18: 관통 | F18: 광역 도발 | G18: 돌파 | L18: 4 | M18: 150
A19: 가디언 | B19: 12 | C19: 도발 베기 | D19: 일렬 베기 | E19: 관통 | F19: 광역 도발 | G19: 돌파 | H19: 쌍렬 베기 | L19: 5 | M19: 160
A20: 가디언 | B20: 13 | C20: 도발 베기 | D20: 일렬 베기 | E20: 관통 | F20: 광역 도발 | G20: 돌파 | H20: 쌍렬 베기 | L20: 6 | M20: 170
A21: 가디언 | B21: 14 | C21: 도발 베기 | D21: 일렬 베기 | E21: 관통 | F21: 광역 도발 | G21: 돌파 | H21: 쌍렬 베기 | L21: 7 | M21: 180
A22: 가디언 | B22: 15 | C22: 도발 베기 | D22: 일렬 베기 | E22: 관통 | F22: 광역 도발 | G22: 돌파 | H22: 쌍렬 베기 | I22: 불굴 | L22: 8 | M22: 200
A23: 스트라이커 | B23: 1 | C23: 정밀 사격
A24: 스트라이커 | B24: 2 | C24: 정밀 사격
A25: 스트라이커 | B25: 3 | C25: 정밀 사격 | D25: 전열 저격
A26: 스트라이커 | B26: 4 | C26: 정밀 사격 | D26: 전열 저격
A27: 스트라이커 | B27: 5 | C27: 정밀 사격 | D27: 전열 저격 | E27: 후열 저격
A28: 스트라이커 | B28: 6 | C28: 정밀 사격 | D28: 전열 저격 | E28: 후열 저격
A29: 스트라이커 | B29: 7 | C29: 정밀 사격 | D29: 전열 저격 | E29: 후열 저격 | F29: 연속 사격
A30: 스트라이커 | B30: 8 | C30: 정밀 사격 | D30: 전열 저격 | E30: 후열 저격 | F30: 연속 사격
A31: 스트라이커 | B31: 9 | C31: 정밀 사격 | D31: 전열 저격 | E31: 후열 저격 | F31: 연속 사격
A32: 스트라이커 | B32: 10 | C32: 정밀 사격 | D32: 전열 저격 | E32: 후열 저격 | F32: 연속 사격 | G32: 급소 저격
A33: 스트라이커 | B33: 11 | C33: 정밀 사격 | D33: 전열 저격 | E33: 후열 저격 | F33: 연속 사격 | G33: 급소 저격
A34: 스트라이커 | B34: 12 | C34: 정밀 사격 | D34: 전열 저격 | E34: 후열 저격 | F34: 연속 사격 | G34: 급소 저격 | H34: 화살비
A35: 스트라이커 | B35: 13 | C35: 정밀 사격 | D35: 전열 저격 | E35: 후열 저격 | F35: 연속 사격 | G35: 급소 저격 | H35: 화살비
A36: 스트라이커 | B36: 14 | C36: 정밀 사격 | D36: 전열 저격 | E36: 후열 저격 | F36: 연속 사격 | G36: 급소 저격 | H36: 화살비
A37: 스트라이커 | B37: 15 | C37: 정밀 사격 | D37: 전열 저격 | E37: 후열 저격 | F37: 연속 사격 | G37: 급소 저격 | H37: 화살비 | I37: 최후의 일격
A38: 블래스터 | B38: 1 | C38: 파이어볼
A39: 블래스터 | B39: 2 | C39: 파이어볼
A40: 블래스터 | B40: 3 | C40: 파이어볼 | D40: 번개 확산
A41: 블래스터 | B41: 4 | C41: 파이어볼 | D41: 번개 확산
...

Sheet 전투 시뮬
A2: 1. 전투 시뮬레이터 목표 및 개요
B3: 본 시뮬레이터는 다대다 전투 환경에서 캐릭터별 전투 성능과 전투 소요 턴을 투쟁의 검증하기 위한 도구이다. 간소한 전투 대미지 계산을 위해 치명타율/반격율/회피율 등 부가 요소는 고려하지 않는다.
A5: 2. 대미지 계산 공식
B6: 기본 대미지는 공식은 1:1 전투 시뮬레이터와 동일하다. 1) 공격력과 방어력의 차이를 구한다. damageBase = 공격력 - 방어력 2) 스킬 계수를 곱한다. damageBase = damageBase × 스킬 계수 3) IP 보정치를 곱한다. damageBase = damageBase × (현재 IP / 100) 4) 계산 결과를 정수로 변환한다. 소수점이 발생할 경우, 소수 첫째 자리에서 반올림한다. (예: 14.4 → 14, 16.5 → 17) 최종 대미지는 다음 규칙을 따른다. 1) 기본 대미지가 2 미만일 경우, 2로 고정한다. (음수 포함) 2) 그 외의 경우, 기본 대미지를 그대로 사용한다.
A8: 3. 전투 시뮬레이터
B9: 범례 | C9: 타 시트에서 가져오는 값
C10: 이 시트에서 바꾸는 값
C11: 이 시트에서 계산되는 값
C12: 고정치 | G12: 최종 스테이터스
C13: 유닛명 | D13: 유닛 레벨 | E13: 최대 IP | F13: 현재 IP | G13: 최종 체력 | H13: 최종 공격력 | I13: 최종 방어력 | J13: 최종 치명타율 (미사용) | K13: 최종 반격율 (미사용) | L13: 최종 회피율 (미사용) | M13: 최종 스피드 (미사용) | N13: 스킬 계수
B14: Hero 01 | C14: 저스티스 | D14: 3 | E14: =VLOOKUP($D14,'범례(시뮬용)'!$L$15:$M$29,2,FALSE) -> 140 | F14: 100 | G14: ='스탯 시뮬'!E37 -> 14 | H14: ='스탯 시뮬'!F37 -> 18 | I14: ='스탯 시뮬'!G37 -> 9 | J14: ='스탯 시뮬'!H37 -> 0.15 | K14: ='스탯 시뮬'!I37 -> 0.15 | L14: ='스탯 시뮬'!J37 -> 0.15 | M14: ='스탯 시뮬'!K37 -> 2 | N14: 1
