Workbook

Sheet 문서 개요
A2: 《Hero Influence》 이벤트 데이터 테이블
B4: 수정 날짜 | C4: 버전 | D4: 담당자 | E4: 수정 내역 | F4: 비고
B5: 46246 | C5: V1.0 | D5: 윤태일 | E5: 자원 테이블에서 분리 이벤트 필드 정의 시트 추가 및 영문 필드명 보완
B6: 46265 | C6: V1.1 | D6: 윤태일 | E6: 소비형 수락, 취소 대사 추가
B7: 46266 | C7: V1.2 | D7: 윤태일 | E7: 특정 조건 전용 시트 추가 조건 필드 분리·필드 정의 동기화 ID·참조·표시 규칙 정리
B8: 46268 | C8: V1.3 | D8: 윤태일 | E8: 조건형 이벤트 1차 내용 작성
B9: 46272 | C9: V1.4 | D9: 윤태일 | E9: 테이블 오류 수정 조건형 진행 피드백 필드 추가
B10: 46279 | C10: V1.5 | D10: 윤태일 | E10: 이벤트 추가 데이터 초기값 생성
B11: 46280 | C11: V1.6 | D11: 윤태일 | E11: 아이디 방식 변경
B12: 46288 | C12: V1.61 | D12: 윤태일 | E12: 데이터 테이블 오류 수정
B13: 46294 | C13: V1.62 | D13: 윤태일 | E13: 데이터 테이블 오류 수정
B14: 46296 | C14: V1.63 | D14: 윤태일 | E14: 데이터 테이블 오류 수정
B15: 46296 | C15: V1.7 | D15: 윤태일 | E15: I.P 획득 밸런스 조절, 획득 계산기 시트 추가
B16: 46308 | C16: V1.8 | D16: 윤태일 | E16: 신규 NPC 유형(방송차량, 구급상자) 생성 및 이벤트 내용 추가
A18: 1. 문서 목적
B19: 본 문서는 월드 이벤트의 기본 정보와 유형별 진행 데이터를 관리하기 위한 데이터 테이블이다. 월드 이벤트는 소비형, 보상형, 선택형으로 구분한다.이벤트 구성과 수치 밸런스는 레벨디자인에서 입력·조정한다.
A21: 2. 문서 기획 의도
B22: 1) 플레이어가 제한된 턴과 이동 자원 안에서 이벤트 진행 여부를 고민하게 한다. 2) 이벤트 진행에 있어 흥미와 재미를 가질 수 있도록 한다. 3) 이벤트 진행으로 성장 밸런스가 적절히 되어야 한다.
A24: 3. 문서 범위
B25: 1) <탐사·월드이벤트 시스템>의 소비형, 보상형, 선택형 월드 이벤트 기본 정보 테이블화 2) 월드 이벤트별 구역, NPC, 표시 대사 및 발동 조건 테이블화 3) 소비형 이벤트의 소비 재화와 적용 효과 테이블화 4) 보상형 이벤트의 지급 재화·스테이터스와 지급 수치 테이블화 5) 선택형 이벤트의 선택지, 활성 조건, 기본 성공 확률 및 결과 안내 문구 테이블화 6) 선택지별 성공·실패 결과와 적용 대상, 효과 종류 및 적용 수치 연결 구조 구성 다음 내용은 본 문서에서 직접 다루지 않고 다른 문서의 내용을 참조한다. 1) 월드 이벤트의 발동, 진행, 취소, 완료 및 UI 출력 규칙 → 탐사·월드이벤트 시스템 2) 재화 종류, 획득 규칙 및 자원별 관리 기준 → H.I 자원 데이터 테이블 3) 월드 이벤트의 배치, 구성 및 수치 밸런스 → H.I 레벨 디자인 기획서 4) 유닛 개별 스테이터스 및 전투 계산 규칙 → H.I 전투 데이터 테이블
A27: 4. 문서 대상
B28: 1) 탐사/협회 시스템 기획자 2) 탐사 시스템 프로그래머 3) 밸런스 담당 기획자

Sheet 이벤트 필드 정의
A1: 이벤트 필드 정의
A3: 공통 - 이벤트 기본 필드
A4: 개발명 | B4: 필드명 | C4: 데이터 타입 | D4: 필수 여부 | E4: 기본값 | F4: 값·코드 범위 | G4: 참조·제약 | H4: 설명
A5: 월드 이벤트 id | B5: world_event_id | C5: string | D5: 필수 | E5: - | F5: [유형]_[발동]_[구역]_[3자리 번호] | G5: 시트 내 기본키 | H5: 이벤트 식별자. 예: C_NPC_01_001 / R_NPC_01_001 / S_NPC_01_001
A6: 구역명 | B6: zone_no | C6: int | D6: 필수 | E6: - | F6: 1 이상 | G6: H.I 레벨 디자인 기획서 | H6: 이벤트가 배치되는 구역 번호
A7: 월드 이벤트명 | B7: world_event_name | C7: string | D7: 조건부 | E7: null | F7: - | G7: 해당 필드가 있는 이벤트 시트 | H7: 기획 및 관리용 이벤트 이름. 선택형 NPC형 및 조건형 이벤트 시트에서 입력
A8: NPC | B8: npc_type | C8: int | D8: 필수 | E8: - | F8: 0 성인 남성 / 1 성인 여성 / 2 할머니 / 3 소년 / 4 방송 차량 / 5 구급상자 | G8: NPC 코드 | H8: 월드 UI에 표시할 NPC 종류
A9: 월드 이벤트 표시 대사 | B9: world_event_description | C9: string | D9: 필수 | E9: - | F9: - | G9: - | H9: 이벤트 발동 후 월드 UI에 표시하는 대사 또는 설명
A10: 비고 | B10: note | C10: string | D10: 선택 | E10: null | F10: - | G10: - | H10: 추가 기획 메모
A12: 특정 조건형 이벤트 - 발동 조건 필드
A13: 개발명 | B13: 필드명 | C13: 데이터 타입 | D13: 필수 여부 | E13: 기본값 | F13: 값·코드 범위 | G13: 참조·제약 | H13: 설명
A14: 발동 조건 종류 | B14: trigger_condition_type | C14: int | D14: 필수 | E14: - | F14: 0 재화 / 1 영웅 / 2 턴수 | G14: 조건형 이벤트 시트 | H14: 이벤트 발동 조건의 분류
A15: 발동 조건 대상 | B15: trigger_condition_target | C15: int | D15: 필수 | E15: - | F15: 재화 0~3 / 영웅 0~4 / 턴수 0 | G15: trigger_condition_type에 따라 해석 | H15: 비교할 재화·영웅 또는 턴수 대상
A16: 영웅 조건 스테이터스 | B16: trigger_condition_stat_type | C16: int | D16: 조건부 | E16: null | F16: 0 CurrentIP / 1 CurrentHP / 2 MaxIP / 3 MaxHP / 4 ATK | G16: trigger_condition_type=1일 때 사용 | H16: 영웅 조건에서 비교할 스테이터스
A17: 영웅 스테이터스 계산 방식 | B17: trigger_condition_calculation_type | C17: int | D17: 조건부 | E17: null | F17: 0 평균 / 1 총합 | G17: trigger_condition_target=4일 때 사용 | H17: 파티 전원 값을 계산하는 방식
A18: 비교 방식 | B18: trigger_condition_operator | C18: int | D18: 필수 | E18: - | F18: 0 이상 >= / 1 이하 <= / 2 같음 = | G18: 비교 코드 | H18: 현재값과 발동 조건값을 비교하는 방식
A19: 발동 조건값 | B19: trigger_condition_value | C19: int | D19: 필수 | E19: - | F19: 정수 | G19: 조건 종류·대상과 함께 입력 | H19: 이벤트 발동 여부를 판정하는 기준 수치
A21: 월드 이벤트 - 소비형(진행)
A22: 개발명 | B22: 필드명 | C22: 데이터 타입 | D22: 필수 여부 | E22: 기본값 | F22: 값·코드 범위 | G22: 참조·제약 | H22: 설명
A23: 이벤트 수락 대사 | B23: world_event_accept | C23: string | D23: 선택 | E23: null | F23: - | G23: 소비형 시트 | H23: 이벤트 수락 시 NPC가 표시하는 대사
A24: 이벤트 취소 대사 | B24: world_event_cancel | C24: string | D24: 선택 | E24: null | F24: - | G24: 소비형 시트 | H24: 이벤트 취소 시 NPC가 표시하는 대사
A25: 이벤트 진행 | B25: world_event_proceed | C25: string | D25: 필수 | E25: - | F25: - | G25: 소비형 시트 | H25: 진행 선택 버튼에 표시할 문구
A26: 이벤트 미진행 | B26: world_event_decline | C26: string | D26: 필수 | E26: - | F26: - | G26: 소비형 시트 | H26: 미진행 선택 버튼에 표시할 문구
A27: 결과 id | B27: result_id | C27: string | D27: 필수 | E27: - | F27: [유형]_[발동]_[구역]_[3자리 번호]_Result | G27: 소비형 (결과).result_id | H27: 수락 완료 시 적용할 소비형 결과 식별자
A29: 월드 이벤트 - 소비형(결과)
A30: 개발명 | B30: 필드명 | C30: 데이터 타입 | D30: 필수 여부 | E30: 기본값 | F30: 값·코드 범위 | G30: 참조·제약 | H30: 설명
A31: 월드 이벤트 id | B31: world_event_id | C31: string | D31: 필수 | E31: - | F31: - | G31: 소비형 NPC형 또는 조건형 world_event_id | H31: 결과가 소속된 소비형 이벤트를 직접 입력
A32: 결과 id | B32: result_id | C32: string | D32: 필수 | E32: - | F32: [유형]_[발동]_[구역]_[3자리 번호]_Result | G32: 해당 시트의 기본키 | H32: 소비형 결과를 구분하는 고유 식별자
A33: 소모 자원 1 종류 | B33: cost_resource_type_1 | C33: int | D33: 필수 | E33: - | F33: 0 자금 / 1 메달 / 2 수정 / 3 자재 | G33: H.I 자원 데이터 테이블 | H33: 첫 번째로 소비할 공용 재화 종류
A34: 소모 자원 1 자원량 | B34: cost_resource_amount_1 | C34: int | D34: 필수 | E34: - | F34: 0 이상 | G34: - | H34: 첫 번째 재화의 소비 수량
A35: 소모 자원 2 종류 | B35: cost_resource_type_2 | C35: int | D35: 선택 | E35: null | F35: 0 자금 / 1 메달 / 2 수정 / 3 자재 | G35: H.I 자원 데이터 테이블 | H35: 두 번째로 소비할 공용 재화 종류
A36: 소모 자원 2 자원량 | B36: cost_resource_amount_2 | C36: int | D36: 조건부 | E36: null | F36: 0 이상 | G36: cost_resource_type_2와 함께 입력 | H36: 두 번째 재화의 소비 수량
A37: 적용 스테이터스 1 종류 | B37: status_type_1 | C37: int | D37: 필수 | E37: - | F37: 0 CurrentIP / 1 CurrentHP / 2 MaxIP / 3 MaxHP / 4 ATK | G37: 스테이터스 코드 | H37: 이벤트 완료 시 적용할 첫 번째 스테이터스
A38: 적용 스테이터스 1 적용 수치 | B38: status_amount_per_event_1 | C38: int | D38: 필수 | E38: - | F38: 증가 + / 감소 - | G38: - | H38: 첫 번째 스테이터스의 적용 수치
A39: 적용 스테이터스 2 종류 | B39: status_type_2 | C39: int | D39: 선택 | E39: null | F39: 0 CurrentIP / 1 CurrentHP / 2 MaxIP / 3 MaxHP / 4 ATK | G39: 스테이터스 코드 | H39: 두 번째로 적용할 스테이터스
A40: 적용 스테이터스 2 적용 수치 | B40: status_amount_per_event_2 | C40: int | D40: 조건부 | E40: null | F40: 증가 + / 감소 - | G40: status_type_2와 함께 입력 | H40: 두 번째 스테이터스의 적용 수치
A42: 월드 이벤트 - 보상형
A43: 개발명 | B43: 필드명 | C43: 데이터 타입 | D43: 필수 여부 | E43: 기본값 | F43: 값·코드 범위 | G43: 참조·제약 | H43: 설명
A44: 이벤트 진행 | B44: world_event_proceed | C44: string | D44: 필수 | E44: - | F44: - | G44: 보상형 시트 | H44: 보상 확인 버튼에 표시할 문구
A45: 제공 재화/스테이터스 1 종류 | B45: reward_type_1 | C45: int | D45: 필수 | E45: - | F45: 0 CurrentIP / 1 Money / 2 Jam / 3 Medal / 4 Supply / 5 CurrentHP | G45: 자원·스테이터스 코드 | H45: 첫 번째 지급 대상 종류. CurrentIP는 파티 전원에게 적용하고, 재화는 공용 재화에 지급
...

Sheet 소비형 (NPC형)
A1: 월드 이벤트 id | B1: 구역명 | C1: NPC (0 성인 남성 / 1 성인 여성 / 2 할머니 / 3 소년 4 방송차량 / 5 구급상자 ) (월드 배치 확인용) | D1: 월드 이벤트 표시 대사 | E1: 이벤트 진행 | F1: 이벤트 미진행 | G1: 월드 이벤트 표시 수락 대사 | H1: 월드 이벤트 표시 취소 대사 | I1: 결과 ID | J1: 비고
A2: world_event_id | B2: zone_no | C2: npc_type | D2: world_event_description | E2: world_event_proceed | F2: world_event_decline | G2: world_event_accept | H2: world_event_cancel | I2: result_id | J2: note
A3: C_NPC_01_001 | B3: 1 | C3: 2 | D3: 우리 나비가 나무에서 내려오지 못하고 있어… 도와주게나… | E3: 물론이죠~! | F3: 지금은 바빠서;;; | G3: 고마워~ 나는 우리 나비 없으면 못살아 | H3: 어딜 그리 급히 가나… 나보다 먼저 가겠네 | I3: C_NPC_01_001_Result
A4: C_NPC_01_002 | B4: 1 | C4: 1 | D4: 이 짐을 집 앞까지만 옮겨 줄 수 있겠니? | E4: 어디까지 가면 되나요? | F4: 아니요 괜찮아요 | G4: 역시 히어로 믿음직하네 | H4: 시민도 안도와주는 히어로가 어딨나 | I4: C_NPC_01_002_Result
A5: C_NPC_01_003 | B5: 1 | C5: 0 | D5: 히어로는 일반인보다 강하다는데 여기 와서 테스트 해보겠나 | E5: 까짓거 함 해보죠! | F5: 어제 무리해서 오늘은 좀… | G5: 하하하! 역시는 히어로는 강하군 | H5: 겁쟁이 녀석들 그래서 빌런하고는 싸우겠나 | I5: C_NPC_01_003_Result
A6: C_NPC_01_004 | B6: 1 | C6: 3 | D6: 빌런들 제어하고 싶제 | E6: 그거… 어떻게 하는건데 | F6: 그런걸 할수있을리가 | G6: 안 알려주거지롱 | H6: 히어로가 제어할수있을리가 | I6: C_NPC_01_004_Result
A7: C_NPC_01_005 | B7: 1 | C7: 4 | D7: 싸다 싸! 광고 한 번이 타이어 보다 싸다! | E7: 진행 시켜! | F7: 타이어 보다 싼 광고는 좀.. | G7: 감사합니다! 히어로! | H7: 지금 바로 진행하면 두 번 더 해드릴께요! | I7: C_NPC_01_005_Result
A8: C_NPC_04_001 | B8: 4 | C8: 0 | D8: 히어로 이것을… 굉장한 물건이 있습니다. | E8: 그래봤자 히어로 잼에 10~11배! | F8: 평범하군 | G8: 아아아아앗! 히어로! 너무 강하다아아아아앗! | H8: 이럴 수가! | I8: C_NPC_04_001_Result
A9: C_NPC_04_002 | B9: 4 | C9: 2 | D9: 히어로 이거 먹으면서 힘내요 | E9: 좋은 단 맛이 납니다. 이거 | F9: 아니요 괜찮아요 | G9: 야채의 단맛일세 | H9: 하나만 먹고 가 | I9: C_NPC_04_002_Result
A10: C_NPC_04_003 | B10: 4 | C10: 1 | D10: 너무 힘들어요 도와주세요 | E10: 뭘 도와드리면 되나요 | F10: 잠시만 기다려주세요 | G10: 아 해결됐어요 고마워요 | H10: 아니 빨리 도와주세요 | I10: C_NPC_04_003_Result
A11: C_NPC_04_004 | B11: 4 | C11: 3 | D11: 유튜브 찍고 있는데 홍보해드릴께요 | E11: 안녕하세여! 저희는 ~~ | F11: 우리는 개인 방송을 할 수가 없어 | G11: 홍보해드렸으니 돈 받을께요 | H11: 괜찮아요 조금만 나오면 | I11: C_NPC_04_004_Result
A12: C_NPC_04_005 | B12: 4 | C12: 0 | D12: 1100원만 빌려주세요 | E12: 1100원이면 되나요? | F12: 1100원이요? 지금 돈이 없어서.. | G12: 네 그 정도면 충분해요. 감사합니다 | H12: 히어로가 돈도 없고.. | I12: C_NPC_04_005_Result

Sheet 소비형 (조건형)
A1: 월드 이벤트 id | B1: 발동 조건 종류 (0 재화 / 1 영웅 / 2 턴수) | C1: 발동 조건 대상 (발동 조건 종류에 따라 적용) 0 재화: 0 Money / 1 Medal / 2 Jam / 3 Supply 1 영웅: 0 저스티스 / 1 네코밍 / 2 블랙불릿 / 3 루미나 / 4 전체 2 턴수: 0 | D1: 영웅 조건 스테이터스 (발동 조건 대상이 영웅일 경우) 0 CurrentIP / 1 CurrentHP / 2 MaxIP / 3 MaxHP / 4 ATK | E1: 영웅 스테이터스 계산 방식 (전체일 경우) 0 평균 / 1 총합 | F1: 비교 방식 (0 이상 >= / 1 이하 <= / 2 같음 =) | G1: 발동 조건값 | H1: 월드 이벤트명 | I1: NPC 프로필 (0 성인 남성 / 1 성인 여성 / 2 할머니 / 3 소년 / 4 협회) | J1: 월드 이벤트 표시 대사 | K1: 월드 이벤트 표시 수락 대사 | L1: 월드 이벤트 표시 취소 대사 | M1: 이벤트 진행 | N1: 이벤트 미진행 | O1: 결과 ID | P1: 비고
A2: world_event_id | B2: trigger_condition_type | C2: trigger_condition_target | D2: trigger_condition_stat_type | E2: trigger_condition_calculation_type | F2: trigger_condition_operator | G2: trigger_condition_value | H2: world_event_name | I2: npc_type | J2: world_event_description | K2: world_event_accept | L2: world_event_cancel | M2: world_event_proceed | N2: world_event_decline | O2: result_id | P2: note
A3: C_IF_001 | B3: 0 | C3: 2 | F3: 0 | G3: 50 | H3: 보석이 반짝! | I3: 4 | J3: 우리 보석이 왜이리 많아졌지 좀 써도 되겠는데? | K3: 난 보석이 좋아! | L3: 그래 야껴써야지 | M3: 빨리쓰자! | N3: 아니! 그래도 아껴야지 | O3: C_IF_01_001_Result
A4: C_IF_002 | B4: 2 | C4: 0 | F4: 0 | G4: 31 | H4: 내일이 오면 | I4: 4 | J4: 내일이면 모든 것이 끝난다. 협회장 마지막 불싸지르기다! | K4: 끝까지 가는거야! | L4: 남겨진 이들을 위하여 | M4: 좋아! 다 불태우고 가는거야! | N4: 내가 없어도 협회는 있으니깐 남겨놔야지 | O4: C_IF_01_002_Result

Sheet 소비형 (결과)
A1: 월드 이벤트 id | B1: 결과 id | C1: 소모 자원 1 종류 (0 자금 / 1 메달 / 2 수정 / 3 자재) | D1: 소모 자원 1 자원량 | E1: 소모 자원 2 종류 (0 자금 / 1 메달 / 2 수정 / 3 자재) | F1: 소모 자원 2 자원량 | G1: 증가 스테이터스 1 종류 (0 CurrentIP / 1 CurrentHP / 2 MaxIP / 3 MaxHP / 4 ATK) | H1: 증가 스테이터스 1 증가량 | I1: 증가 스테이터스 2 종류 (0 CurrentIP / 1 CurrentHP / 2 MaxIP / 3 MaxHP / 4 ATK) | J1: 증가 스테이터스 2 증가량 | K1: 비고
A2: world_event_id | B2: result_id | C2: cost_resource_type_1 | D2: cost_resource_amount_1 | E2: cost_resource_type_2 | F2: cost_resource_amount_2 | G2: status_type_1 | H2: status_amount_per_event_1 | I2: status_type_2 | J2: status_amount_per_event_2 | K2: note
A3: C_NPC_01_001 | B3: C_NPC_01_001_Result | C3: 0 | D3: 300 | G3: 0 | H3: 3
A4: C_NPC_01_002 | B4: C_NPC_01_002_Result | C4: 0 | D4: 300 | G4: 1 | H4: 5 | I4: 0 | J4: 3
A5: C_NPC_01_003 | B5: C_NPC_01_003_Result | C5: 0 | D5: 400 | G5: 4 | H5: 3
A6: C_NPC_01_004 | B6: C_NPC_01_004_Result | C6: 1 | D6: 5 | G6: 1 | H6: 10
A7: C_NPC_01_005 | B7: C_NPC_01_005_Result | C7: 0 | D7: 300 | G7: 0 | H7: 4
A8: C_NPC_04_001 | B8: C_NPC_04_001_Result | C8: 0 | D8: 1300 | G8: 0 | H8: 4 | I8: 4 | J8: 5 | K8: 자본적으로 여유가 있다고 생각하는 유저를 위한 이벤트
A9: C_NPC_04_002 | B9: C_NPC_04_002_Result | C9: 1 | D9: 7 | G9: 1 | H9: 15
A10: C_NPC_04_003 | B10: C_NPC_04_003_Result | C10: 2 | D10: 7 | G10: 4 | H10: 5
A11: C_NPC_04_004 | B11: C_NPC_04_004_Result | C11: 0 | D11: 1000 | G11: 0 | H11: 4
A12: C_NPC_04_005 | B12: C_NPC_04_005_Result | C12: 0 | D12: 1100 | G12: 4 | H12: 3
A13: C_IF_001 | B13: C_IF_01_001_Result | C13: 2 | D13: 3 | G13: 4 | H13: 3
A14: C_IF_002 | B14: C_IF_01_002_Result | C14: 1 | D14: 10 | E14: 2 | F14: 10 | G14: 0 | H14: 10 | I14: 1 | J14: 10

Sheet 보상형 (NPC형)
A1: 월드 이벤트 id | B1: 구역명 | C1: NPC (0 성인 남성 / 1 성인 여성 / 2 할머니 / 3 소년 4 방송차량 / 5 구급상자 ) (월드 배치 확인용) | D1: 월드 이벤트 표시 대사 | E1: 이벤트 진행 | F1: 월드 이벤트 표시 수락 대사 | G1: 제공 재화/스테이터스 1 종류 (0 CurrentIP / 1 Money / 2 Jam / 3 Medal / 4 Supply / 5 CurrentHP) | H1: 제공 재화/스테이터스 1 제공량 | I1: 제공 재화/스테이터스 2 종류 (0 CurrentIP / 1 Money / 2 Jam / 3 Medal / 4 Supply / 5 CurrentHP) | J1: 제공 재화/스테이터스 2 제공량 | K1: 비고
A2: world_event_id | B2: zone_no | C2: npc_type | D2: world_event_description | E2: world_event_proceed | F2: world_event_accept | G2: reward_type_1 | H2: reward_amount_1 | I2: reward_type_2 | J2: reward_amount_2 | K2: note
A3: R_NPC_01_001 | B3: 1 | C3: 2 | D3: 아이구~ 내 새끼. 요즘 밥은 먹고 다니는거야? 이걸로 친구들이랑 맛있는 거 사먹어 | E3: 감사합니다~ ^^ | F3: 아유~ 귀여운 내 새끼 | G3: 1 | H3: 700
A4: R_NPC_01_002 | B4: 1 | C4: 0 | D4: 히어로가 진다는 건…. 나로선 상상조차 할 수 없어 | E4: 당연하지 우리는 최강인데 | F4: 역시 히어로 | G4: 3 | H4: 3
A5: R_NPC_01_003 | B5: 1 | C5: 3 | D5: 개성이 없는 시민이라도 히어로가 될 수 있을까요? | E5: 넌 히어로가 될수있다! | F5: 열심히 노력할께요 | G5: 0 | H5: 5
A6: R_NPC_01_004 | B6: 1 | C6: 5 | D6: (눈 앞에 구급 상자가 있다) | E6: 사용 해도 되는 건가 | F6: (구급 상사로 히어로의 마음은 충만해졌다) | G6: 5 | H6: 10
A7: R_NPC_04_001 | B7: 4 | C7: 1 | D7: 오래 동안 지켜봤어요. 힘든 상황에서도 물러서지 않는 모습 | E7: 기대에 부흥하겠습니다 | F7: 계속해서 지켜보겠습니다. | G7: 0 | H7: 6
A8: R_NPC_04_002 | B8: 4 | C8: 0 | D8: 싸우는 거 봤어요! 빌런 녀석들을 시원하게 날리는 거요! | E8: 하하하하. 감사합니다. | F8: 작지만 감사한 마음에 드리는 거에요 | G8: 1 | H8: 1500
A9: R_NPC_04_003 | B9: 4 | C9: 3 | D9: 빌런은 왜 계속 히어로랑 싸우는 걸까여 | E9: 세상 이치가 그래 | F9: 그런 녀석들은 아마 최약체 녀석들이겠지 | G9: 3 | H9: 5
A10: R_NPC_04_004 | B10: 4 | C10: 2 | D10: 길에서 예쁜 돌을 주웠는데 자꾸 빛이 나서 자네들이 좀 가지고 가 | E10: 저희가 처리해 드릴께요 | F10: 그래그래. 문제가 생겨도 다시 주지말고 | G10: 2 | H10: 5
A11: R_NPC_04_005 | B11: 4 | C11: 0 | D11: 제 기준에서 여러분들은 합격점이네요. 다소 아쉬운 점이 많지만 신인이라는 점을 감안하면… | E11: 뭐에 대한 합격이죠? | F11: 별 건 아니에요. 저만의 평가가 있으니깐요. | G11: 4 | H11: 5

Sheet 보상형 (조건형)
A1: 월드 이벤트 id | B1: 발동 조건 종류 (0 재화 / 1 영웅 / 2 턴수) | C1: 발동 조건 대상 (발동 조건 종류에 따라 적용) 0 재화: 0 Money / 1 Medal / 2 Jam / 3 Supply 1 영웅: 0 저스티스 / 1 네코밍 / 2 블랙불릿 / 3 루미나 / 4 전체 2 턴수: 0 | D1: 영웅 조건 스테이터스 (발동 조건 대상이 영웅일 경우) 0 CurrentIP / 1 CurrentHP / 2 MaxIP / 3 MaxHP / 4 ATK | E1: 영웅 스테이터스 계산 방식 (전체일 경우) 0 평균 / 1 총합 | F1: 비교 방식 (0 이상 >= / 1 이하 <= / 2 같음 =) | G1: 발동 조건값 | H1: 월드 이벤트명 | I1: NPC 프로필 (0 성인 남성 / 1 성인 여성 / 2 할머니 / 3 소년 / 4 협회) | J1: 월드 이벤트 표시 대사 | K1: 월드 이벤트 표시 수락 대사 | L1: 이벤트 진행 | M1: 제공 재화/스테이터스 1 종류 (0 CurrentIP / 1 Money / 2 Jam / 3 Medal / 4 Supply / 5 CurrentHP) | N1: 제공 재화/스테이터스 1 제공량 | O1: 제공 재화/스테이터스 1 종류 (0 CurrentIP / 1 Money / 2 Jam / 3 Medal / 4 Supply / 5 CurrentHP) | P1: 제공 재화/스테이터스 2 제공량 | Q1: 비고
A2: world_event_id | B2: trigger_condition_type | C2: trigger_condition_target | D2: trigger_condition_stat_type | E2: trigger_condition_calculation_type | F2: trigger_condition_operator | G2: trigger_condition_value | H2: world_event_name | I2: npc_type | J2: world_event_description | K2: world_event_accept | L2: world_event_proceed | M2: reward_type_1 | N2: reward_amount_1 | O2: reward_type_2 | P2: reward_amount_2 | Q2: note
A3: R_IF_001 | B3: 1 | C3: 4 | D3: 0 | E3: 0 | F3: 0 | G3: 20 | H3: 각광받는 히어로 | I3: 4 | J3: 요즘 너희들의 활약이 대단하다고 SNS에서 유명해지고 있어 | K3: 안돼!! 기사같은거 찾아보지말고 댓글도 보지마 알았지? | L3: 정말? 기사 찾아봐도 되나? | M3: 0 | N3: 5
A4: R_IF_002 | B4: 2 | C4: 0 | F4: 0 | G4: 12 | H4: 긴급 공지! | I4: 4 | J4: ※공지※ 오로라 시티의 협회장은 6일 내로 도시를 구하지 못하면 경질될 수 있음을 알립니다. | K4: 비상이다! 기간 내에 오로라 시티를 구하지 못하면 짤린다고 문자가 왔어! | L4: 힘내고 도시를 구해보자. | M4: 1 | N4: 1500 | O4: 3 | P4: 5

Sheet 선택형 (NPC형)
A1: 월드 이벤트 id | B1: 구역명 | C1: NPC (0 성인 남성 / 1 성인 여성 / 2 할머니 / 3 소년 4 방송차량 / 5 구급상자 ) (월드 배치 확인용) | D1: 월드 이벤트 표시 대사 | E1: 월드 이벤트 표시 취소 대사 | F1: 선택지 1 id | G1: 선택지 2 id | H1: 이벤트 미진행 | I1: 비고
A2: world_event_id | B2: zone_no | C2: npc_type | D2: world_event_description | E2: world_event_cancel | F2: choice_1_id | G2: choice_2_id | H2: world_event_decline | I2: note
A3: S_NPC_01_001 | B3: 1 | C3: 3 | D3: 나와 가위바위보를 해서 이기면 돈을 주겠다! | E3: 도망치는 거냐! 히어로! | F3: S_NPC_01_001_C1 | G3: S_NPC_01_001_C2 | H3: 난 가위바위보따위 하지 않아
A4: S_NPC_01_002 | B4: 1 | C4: 0 | D4: 히어로도 머리가 좋아야 하는 법! 상식 문제 하나 풀어보겠어? | E4: 모르는 건 죄가 아니지 | F4: S_NPC_01_002_C1 | G4: S_NPC_01_002_C2 | H4: 뭐가 뭔지 모르겠다
A5: S_NPC_01_003 | B5: 1 | C5: 1 | D5: 두 상자 중 하나에 진짜 보상이 들어 있지. 자, 어느 상자를 고르겠어? | E5: 언제든 기다려 주지 | F5: S_NPC_01_003_C1 | G5: S_NPC_01_003_C2 | H5: 지금은 고르지 않는다
A6: S_NPC_01_004 | B6: 1 | C6: 2 | D6: 수레가 완전히 고장 났어. 혹시 수리를 도와줄 수 있겠나? | E6: 지금 도움이 필요한데 | F6: S_NPC_01_004_C1 | G6: S_NPC_01_004_C2 | H6: 아직 때가 아니다
A7: S_NPC_01_005 | B7: 1 | C7: 3 | D7: 도와준 답례로 준비했어. 두 봉투 중 마음에 드는 하나를 골라. | E7: 하나만 고르라고 | F7: S_NPC_01_005_C1 | G7: S_NPC_01_005_C2 | H7: 3개 다 고른다
A8: S_NPC_04_001 | B8: 4 | C8: 1 | D8: 도주 중인 빌런들의 위치를 알아냈어. 어느 쪽으로 추적할 생각이지? | E8: 지금 중요한 순간에! | F8: S_NPC_04_001_C1 | G8: S_NPC_04_001_C2 | H8: 나중에 간다
A9: S_NPC_04_002 | B9: 4 | C9: 2 | D9: 실력을 점검해주지. 기본 훈련과 최고 난이도 훈련 중 하나를 골라라. | E9: 나약한 녀석들! | F9: S_NPC_04_002_C1 | G9: S_NPC_04_002_C2 | H9: 나중에 한다
A10: S_NPC_04_003 | B10: 4 | C10: 3 | D10: 안쪽에 거대한 수정 광맥이 있어. 다만 언제 무너질지는 장담 못 해. | E10: 지금 무너진다고! | F10: S_NPC_04_003_C1 | G10: S_NPC_04_003_C2 | H10: 아직 들어가지 않는다.
A11: S_NPC_04_004 | B11: 4 | C11: 0 | D11: 도적들이 물자를 훔쳐 갔어! 남은 물자를 지키거나 놈들을 추격해줘. | E11: 내 물건은!? | F11: S_NPC_04_004_C1 | G11: S_NPC_04_004_C2 | H11: 지금은 바쁘니 나중에
A12: S_NPC_04_005 | B12: 4 | C12: 1 | D12: 거래를 대신 맡아줄 사람이 필요해. 보수 조건은 자네가 고르게. | E12: 욕심이 너무 많군 | F12: S_NPC_04_005_C1 | G12: S_NPC_04_005_C2 | H12: 이걸로는 부족하다

Sheet 선택형 (조건형)
A1: 월드 이벤트 id | B1: 발동 조건 종류 (0 재화 / 1 영웅 / 2 턴수) | C1: 발동 조건 대상 (발동 조건 종류에 따라 적용) 0 재화: 0 Money / 1 Medal / 2 Jam / 3 Supply 1 영웅: 0 저스티스 / 1 네코밍 / 2 블랙불릿 / 3 루미나 / 4 전체 2 턴수: 0 | D1: 영웅 조건 스테이터스 (발동 조건 대상이 영웅일 경우) 0 CurrentIP / 1 CurrentHP / 2 MaxIP / 3 MaxHP / 4 ATK | E1: 영웅 스테이터스 계산 방식 (전체일 경우) 0 평균 / 1 총합 | F1: 비교 방식 (0 이상 >= / 1 이하 <= / 2 같음 =) | G1: 발동 조건값 | H1: 월드 이벤트명 | I1: NPC 프로필 (0 성인 남성 / 1 성인 여성 / 2 할머니 / 3 소년 / 4 협회) | J1: 월드 이벤트 표시 대사 | K1: 월드 이벤트 표시 취소 대사 | L1: 선택지 1 id | M1: 선택지 2 id | N1: 이벤트 미진행 | O1: 비고
A2: world_event_id | B2: trigger_condition_type | C2: trigger_condition_target | D2: trigger_condition_stat_type | E2: trigger_condition_calculation_type | F2: trigger_condition_operator | G2: trigger_condition_value | H2: world_event_name | I2: npc_type | J2: world_event_description | K2: world_event_cancel | L2: choice_1_id | M2: choice_2_id | N2: world_event_decline | O2: note
A3: S_IF_001 | B3: 2 | C3: 0 | F3: 2 | G3: 24 | H3: 이틀 남음 | I3: 4 | J3: (이틀 밖에 안남았다) | L3: S_IF_001_C1 | M3: S_IF_001_C2

Sheet 선택형 (선택지)
A1: 선택지 id | B1: 월드 이벤트 id (선택형 테이블 참조) | C1: 선택지 표시 문구 | D1: 활성 조건 유닛 (0 없음 / 1 저스티스 / 2 네코밍 / 3 블랙불릿 / 4 루미나 / 5 전체) | E1: 활성 조건 종류 (0 없음 / 1 재화 / 2 스테이터스) | F1: 활성 조건 대상 (조건 종류에 따라 적용) 0 없음 1 재화: 0 Money / 1 Medal / 2 Jam / 3 Supply 2 스테이터스: 0 CurrentIP / 1 CurrentHP / 2 MaxIP / 3 MaxHP / 4 ATK | G1: 계산 방식 (전체 일 경우) (0 평균 / 1 총합) | H1: 비교 방식 (0 이상 >= / 1 이하 <= / 2 같음 =) | I1: 활성 조건값 | J1: 확률 보정 유무 (0 없음 / 1 있음) 최종 = min(100, 기본 + CurrentIP × 0.5) | K1: 기본 성공 확률(%p) | L1: 성공 선택지 결과 id (선택결과 테이블 참조) | M1: 실패 선택지 결과 id (효과 없음: RESULT_NONE) | N1: 비고
A2: choice_id | B2: world_event_id | C2: choice_text | D2: enable_condition_unit | E2: enable_condition_type | F2: enable_condition_target | G2: enable_condition_calculation_type | H2: enable_condition_operator | I2: enable_condition_value | J2: use_ip_success_rate_bonus | K2: base_success_rate | L2: success_choice_result_id | M2: failure_choice_result_id | N2: note
A3: S_NPC_01_001_C1 | B3: S_NPC_01_001 | C3: 정정당당한 승부다! | D3: 0 | E3: 0 | F3: 0 | J3: 0 | K3: 33 | L3: S_NPC_01_001_C1_S | M3: S_NPC_01_001_C1_F
A4: S_NPC_01_001_C2 | B4: S_NPC_01_001 | C4: 내 가위는 주먹도 이긴다! | D4: 1 | E4: 2 | F4: 4 | H4: 0 | I4: 14 | J4: 1 | K4: 25 | L4: S_NPC_01_001_C2_S | M4: S_NPC_01_001_C2_F
A5: S_NPC_01_002_C1 | B5: S_NPC_01_002 | C5: 힌트를 하나 쓰겠습니다. | J5: 0 | K5: 70 | L5: S_NPC_01_002_C1_S | M5: S_NPC_01_002_C1_F
A6: S_NPC_01_002_C2 | B6: S_NPC_01_002 | C6: 힌트 없이 바로 맞히겠습니다. | J6: 1 | K6: 40 | L6: S_NPC_01_002_C2_S | M6: S_NPC_01_002_C2_F
A7: S_NPC_01_003_C1 | B7: S_NPC_01_003 | C7: 상자를 흔들어보고 고른다. | J7: 0 | K7: 70 | L7: S_NPC_01_003_C1_S | M7: S_NPC_01_003_C1_F
A8: S_NPC_01_003_C2 | B8: S_NPC_01_003 | C8: 내 감은 확실해. 바로 고른다. | J8: 1 | K8: 40 | L8: S_NPC_01_003_C2_S | M8: S_NPC_01_003_C2_F
A9: S_NPC_01_004_C1 | B9: S_NPC_01_004 | C9: 수레를 함께 수리한다. | J9: 0 | K9: 70 | L9: S_NPC_01_004_C1_S | M9: S_NPC_01_004_C1_F
A10: S_NPC_01_004_C2 | B10: S_NPC_01_004 | C10: 새 부품을 사서 완벽하게 고친다. | J10: 1 | K10: 40 | L10: S_NPC_01_004_C2_S | M10: S_NPC_01_004_C2_F
A11: S_NPC_01_005_C1 | B11: S_NPC_01_005 | C11: 두꺼워 보이는 봉투를 고른다. | J11: 0 | K11: 70 | L11: S_NPC_01_005_C1_S | M11: S_NPC_01_005_C1_F
A12: S_NPC_01_005_C2 | B12: S_NPC_01_005 | C12: 반짝이는 작은 상자를 고른다. | J12: 1 | K12: 40 | L12: S_NPC_01_005_C2_S | M12: S_NPC_01_005_C2_F
A13: S_NPC_04_001_C1 | B13: S_NPC_04_001 | C13: 확인된 이동 경로만 추적한다. | J13: 0 | K13: 60 | L13: S_NPC_04_001_C1_S | M13: S_NPC_04_001_C1_F
A14: S_NPC_04_001_C2 | B14: S_NPC_04_001 | C14: 놈의 은신처로 바로 쳐들어간다. | J14: 1 | K14: 30 | L14: S_NPC_04_001_C2_S | M14: S_NPC_04_001_C2_F
A15: S_NPC_04_002_C1 | B15: S_NPC_04_002 | C15: 기본 훈련부터 차근차근 받는다. | J15: 0 | K15: 60 | L15: S_NPC_04_002_C1_S | M15: S_NPC_04_002_C1_F
A16: S_NPC_04_002_C2 | B16: S_NPC_04_002 | C16: 최고 난이도 훈련에 도전한다. | J16: 1 | K16: 30 | L16: S_NPC_04_002_C2_S | M16: S_NPC_04_002_C2_F
... A22: S_NPC_04_005_C2 | B22: S_NPC_04_005 | C22: 보수 대신 메달을 걸고 추가 협상한다. | J22: 1 | K22: 30 | L22: S_NPC_04_005_C2_S | M22: S_NPC_04_005_C2_F
A23: S_IF_001_C1 | B23: S_IF_001 | C23: 지금이라도 도망쳐야 하나… | D23: 0 | E23: 0 | F23: 0 | J23: 0 | K23: 40 | L23: S_IF_001_C1_S | M23: S_IF_001_C1_F
A24: S_IF_001_C2 | B24: S_IF_001 | C24: 아니 책임지고 끝까지 해보자 | D24: 5 | E24: 2 | F24: 0 | G24: 1 | H24: 0 | I24: 55 | J24: 1 | K24: 25 | L24: S_IF_001_C2_S | M24: S_IF_001_C2_F

Sheet 선택형 (선택결과)
A1: 결과 그룹 id (선택지 테이블 참조) | B1: 월드 이벤트 표시 수락 대사 | C1: 적용 대상 (0 없음 / 1 재화 / 2 파티 전원) | D1: 효과 종류 (적용 대상에 따라 적용) 0 없음: 0 None 1 공용 재화: 0 Money / 1 Medal / 2 Jam / 3 Supply 2 파티 전원: 0 CurrentIP / 1 CurrentHP / 2 MaxIP / 3 MaxHP / 4 ATK | E1: 적용 수치 (획득·증가 + / 차감·패널티 -) | F1: 비고
A2: result_group_id | B2: world_event_accept | C2: target_scope | D2: effect_type | E2: effect_amount | F2: note
A3: S_NPC_01_001_C1_S | B3: 크윽! 졌다. | C3: 1 | D3: 0 | E3: 1000
A4: S_NPC_01_001_C2_S | B4: 말도안돼!! | C4: 1 | D4: 0 | E4: 1500
A5: S_NPC_01_001_C1_F | B5: 더 강해져서 돌아와라 | C5: 0 | D5: 0 | E5: 0
A6: S_NPC_01_001_C2_F | B6: 가위를 이기는 주먹같은게 있을리가! | C6: 1 | D6: 0 | E6: -500
A7: S_NPC_01_002_C1_S | B7: 힌트를 썼지만 정답은 정답이지! | C7: 1 | D7: 1 | E7: 3
A8: S_NPC_01_002_C2_S | B8: 정답! 히어로는 지식도 강하군! | C8: 1 | D8: 0 | E8: 1000
A9: S_NPC_01_002_C1_F | B9: 힌트까지 줬는데 이걸 틀리네… | C9: 0 | D9: 0 | E9: 0
A10: S_NPC_01_002_C2_F | B10: 참가비는 자동 결제되었습니다. | C10: 1 | D10: 0 | E10: -300
A11: S_NPC_01_003_C1_S | B11: 소리만 듣고 맞혔다고? 감 좋은데? | C11: 1 | D11: 2 | E11: 3
A12: S_NPC_01_003_C2_S | B12: 이걸 한 번에 맞히네. 오늘 폼 미쳤다. | C12: 1 | D12: 1 | E12: 5
A13: S_NPC_01_003_C1_F | B13: 빈 상자다. 그래도 잃은 건 없네. | C13: 0 | D13: 0 | E13: 0
A14: S_NPC_01_003_C2_F | B14: 틀렸으니 참가 기념 메달 하나만 받을게. | C14: 1 | D14: 1 | E14: -1
... A42: S_NPC_04_005_C2_F | B42: 강하게 나갔다가 신뢰만 잃어버렸군. | C42: 1 | D42: 1 | E42: -2
A43: S_IF_001_C1_S | B43: 도망은 무슨 끝까지 해야지 | C43: 1 | D43: 0 | E43: 500 | F43: 조건형 1 선택지 1성공
A44: S_IF_001_C2_S | B44: 이제는 더 이상 물러날 곳이 없다 | C44: 1 | D44: 1 | E44: 5 | F44: 조건형 1 선택지 2성공
A45: S_IF_001_C1_F | B45: 머뭇 걸릴 틈이 없다! | C45: 1 | D45: 0 | E45: -300 | F45: 조건형 1 선택지 1실패
A46: S_IF_001_C2_F | B46: 조금만 더 해보고 아니다 싶으면 포기하자 | C46: 1 | D46: 1 | E46: -1 | F46: 조건형 1 선택지 2실패

Sheet 획득 계산기
B2: 재화/효과 | C2: 소비형 증가량 | D2: 소비형 감소량 | E2: 보상형 획득 | F2: 선택형 성공 결과 | G2: 선택형 실패 결과 | H2: 총합 | I2: 비고
B3: 자금 | C3: =0 -> 0 | D3: =SUMIFS('소비형 (결과)'!$D$3:$D$1001,'소비형 (결과)'!$C$3:$C$1001,0)+SUMIFS('소비형 (결과)'!$F$3:$F$1001,'소비형 (결과)'!$E$3:$E$1001,0) -> 4700 | E3: =SUMIFS('보상형 (NPC형)'!$H$3:$H$1001,'보상형 (NPC형)'!$G$3:$G$1001,1)+SUMIFS('보상형 (NPC형)'!$J$3:$J$1001,'보상형 (NPC형)'!$I$3:$I$1001,1)+SUMIFS('보상형 (조건형)'!$N$3:$N$1000,'보상형 (조건형)'!$M$3:$M$1000,1)+SUMIFS('보상형 (조건형)'!$P$3:$P$1000,'보상형 (조건형)'!$O$3:$O$1000,1) -> 3700 | F3: =IF('선택형 (선택지)'!$L$3="",0,SUMIFS('선택형 (선택결과)'!$E$3:$E$1000,'선택형 (선택결과)'!$A$3:$A$1000,'선택형 (선택지)'!$L$3,'선택형 (선택결과)'!$C$3:$C$1000,1,'선택형 (선택결과)'!$D$3:$D$1000,0))+IF('선택형 (선택지)'!$L$4="",0,SUMIFS('선택형 (선택결과)'!$E$3:$E$1000,'선택형 (선택결과)'!$A$3:$A$1000,'선택형 (선택지)'!$L$4,'선택형 (선택결과)'!$C$3:$C$1000,1,'선택형 (선택결과)'!$D$3:$D$1000,0))+IF('선택형 (선택지)'!$L$5="",0,SUMIFS('선택형 (선택결과)'!$E$3:$E$1000,'선택형 (선택결과)'!$A$3:$A$1000,'선택형 (선택지)'!$L$5,'선택형 (선택결과)'!$C$3:$C$1000,1,'선택형 (선택결과)'!$D$3:$D$1000,0))+IF('선택형 (선택지)'!$L$6="",0,SUMIFS('선택형 (선택결과)'!$E$3:$E$1000,'선택형 (선택결과)'!$A$3:$A$1000,'선택형 (선택지)'!$L$6,'선택형 (선택결과)'!$C$3:$C$1000,1,'선택형 (선택결과)'!$D$3:$D$1000,0))+IF('선택형 (선택지)'!$L$7="",0,SUMIFS('선택형 (선택결과)'!$E$3:$E$1000,'선택형 (선택결과)'!$A$3:$A$1000,'선택형 (선택지)'!$L$7,'선택형 (선택결과)'!$C$3:$C$1000,1,'선택형 (선택결과)'!$D$3:$D$1000,0))+IF('선택형 (선택지)'!$L$8="",0,SUMIFS('선택형 (선택결과)'!$E$3:$E$1000,'선택형 (선택결과)'!$A$3:$A$1000,'선택형 (선택지)'!$L$8,'선택형 (선택결과)'!$C$3:$C$1000,1,'선택형 (선택결과)'!$D$3:$D$1000,0))+IF('선택형 (선택지)'!$L$9="",0,SUMIFS('선택형 (선택결과)'!$E$3:$E$1000,'선택형 (선택결과)'!$A$3:$A$1000,'선택형 (선택지)'!$L$9,'선택형 (선택결과)'!$C$3:$C$1000,1,'선택형 (선택결과)'!$D$3:$D$1000,0))+IF('선택형 (선택지)'!$L$10="",0,SUMIFS('선택형 (선택결과)'!$E$3:$E$1000,'선택형 (선택결과)'!$A$3:$A$1000,'선택형 (선택지)'!$L$10,'선택형 (선택결과)'!$C$3:$C$1000,1,'선택형 (선택결과)'!$D$3:$D$1000,0))+IF('선택형 (선택지)'!$L$11="",0,SUMIFS('선택형 (선택결과)'!$E$3:$E$1000,'선택형 (선택결과)'!$A$3:$A$1000,'선택형 (선택지)'!$L$11,'선택형 (선택결과)'!$C$3:$C$1000,1,'선택형 (선택결과)'!$D$3:$D$1000,0))+IF('선택형 (선택지)'!$L$12="",0,SUMIFS('선택형 (선택결과)'!$E$3:$E$1000,'선택형 (선택결과)'!$A$3:$A$1000,'선택형 (선택지)'!$L$12,'선택형 (선택결과)'!$C$3:$C$1000,1,'선택형 (선택결과)'!$D$3:$D$1000,0))+IF('선택형 (선택지)'!$L$13="",0,SUMIFS('선택형 (선택결과)'!$E$3:$E$1000,'선택형 (선택결과)'!$A$3:$A$1000,'선택형 (선택지)'!$L$13,'선택형 (선택결과)'!$C$3:$C$1000,1,'선택형 (선택결과)'!$D$3:$D$1000,0))+IF('선택형 (선택지)'!$L$14="",0,SUMIFS('선택형 (선택결과)'!$E$3:$E$1000,'선택형 (선택결과)'!$A$3:$A$1000,'선택형 (선택지)'!$L$14,'선택형 (선택결과)'!$C$3:$C$1000,1,'선택형 (선택결과)'!$D$3:$D$1000,0))+IF('선택형 (선택지)'!$L$15="",0,SUMIFS('선택형 (선택결과)'!$E$3:$E$1000,'선택형 (선택결과)'!$A$3:$A$1000,'선택형 (선택지)'!$L$15,'선택형 (선택결과)'!$C$3:$C$1000,1,'선택형 (선택결과)'!$D$3:$D$1000,0))+IF('선택형 (선택지)'!$L$16="",0,SUMIFS('선택형 (선택결과)'!$E$3:$E$1000,'선택형 (선택결과)'!$A$3:$A$1000,'선택형 (선택지)'!$L$16,'선택형 (선택결과)'!$C$3:$C$1000,1,'선택형 (선택결과)'!$D$3:$D$1000,0))+IF('선택형 (선택지)'!$L$17="",0,SUMIFS('선택형 (선택결과)'!$E$3:$E$1000,'선택형 (선택결과)'!$A$3:$A$1000,'선택형 (선택지)'!$L$17,'선택형 (선택결과)'!$C$3:$C$1000,1,'선택형 (선택결과)'!$D$3:$D$1000,0))+IF('선택형 (선택지)'!$L$18="",0,SUMIFS('선택형 (선택결과)'!$E$3:$E$1000,'선택형 (선택결과)'!$A$3:$A$1000,'선택형 (선택지)'!$L$18,'선택형 (선택결과)'!$C$3:$C$1000,1,'선택형 (선택결과)'!$D$3:$D$1000,0))+IF('선택형 (선택지)'!$L$19="",0,SUMIFS('선택형 (선택결과)'!$E$3:$E$1000,'선택형 (선택결과)'!$A$3:$A$1000,'선택형 (선택지)'!$L$19,'선택형 (선택결과)'!$C$3:$C$1000,1,'선택형 (선택결과)'!$D$3:$D$1000,0))+IF('선택형 (선택지)'!$L$20="",0,SUMIFS('선택형 (선택결과)'!$E$3:$E$1000,'선택형 (선택결과)'!$A$3:$A$1000,'선택형 (선택지)'!$L$20,'선택형 (선택결과)'!$C$3:$C$1000,1,'선택형 (선택결과)'!$D$3:$D$1000,0))+IF('선택형 (선택지)'!$L$21="",0,SUMIFS('선택형 (선택결과)'!$E$3:$E$1000,'선택형 (선택결과)'!$A$3:$A$1000,'선택형 (선택지)'!$L$21,'선택형 (선택결과)'!$C$3:$C$1000,1,'선택형 (선택결과)'!$D$3:$D$1000,0))+IF('선택형 (선택지)'!$L$22="",0,SUMIFS('선택형 (선택결과)'!$E$3:$E$1000,'선택형 (선택결과)'!$A$3:$A$1000,'선택형 (선택지)'!$L$22,'선택형 (선택결과)'!$C$3:$C$1000,1,'선택형 (선택결과)'!$D$3:$D$1000,0))+IF('선택형 (선택지)'!$L$23="",0,SUMIFS('선택형 (선택결과)'!$E$3:$E$1000,'선택형 (선택결과)'!$A$3:$A$1000,'선택형 (선택지)'!$L$23,'선택형 (선택결과)'!$C$3:$C$1000,1,'선택형 (선택결과)'!$D$3:$D$1000,0))+IF('선택형 (선택지)'!$L$24="",0,SUMIFS('선택형 (선택결과)'!$E$3:$E$1000,'선택형 (선택결과)'!$A$3:$A$1000,'선택형 (선택지)'!$L$24,'선택형 (선택결과)'!$C$3:$C$1000,1,'선택형 (선택결과)'!$D$3:$D$1000,0))+IF('선택형 (선택지)'!$L$25="",0,SUMIFS('선택형 (선택결과)'!$E$3:$E$1000,'선택형 (선택결과)'!$A$3:$A$1000,'선택형 (선택지)'!$L$25,'선택형 (선택결과)'!$C$3:$C$1000,1,'선택형 (선택결과)'!$D$3:$D$1000,0))+IF('선택형 (선택지)'!$L$26="",0,SUMIFS('선택형 (선택결과)'!$E$3:$E$1000,'선택형 (선택결과)'!$A$3:$A$1000,'선택형 (선택지)'!$L$26,'선택형 (선택결과)'!$C$3:$C$1000,1,'선택형 (선택결과)'!$D$3:$D$1000,0))+IF('선택형 (선택지)'!$L$27="",0,SUMIFS('선택형 (선택결과)'!$E$3:$E$1000,'선택형 (선택결과)'!$A$3:$A$1000,'선택형 (선택지)'!$L$27,'선택형 (선택결과)'!$C$3:$C$1000,1,'선택형 (선택결과)'!$D$3:$D$1000,0))+IF('선택형 (선택지)'!$L$28="",0,SUMIFS('선택형 (선택결과)'!$E$3:$E$1000,'선택형 (선택결과)'!$A$3:$A$1000,'선택형 (선택지)'!$L$28,'선택형 (선택결과)'!$C$3:$C$1000,1,'선택형 (선택결과)'!$D$3:$D$1000,0))+IF('선택형 (선택지)'!$L$29="",0,SUMIFS('선택형 (선택결과)'!$E$3:$E$1000,'선택형 (선택결과)'!$A$3:$A$1000,'선택형 (선택지)'!$L$29,'선택형 (선택결과)'!$C$3:$C$1000,1,'선택형 (선택결과)'!$D$3:$D$1000,0))+IF('선택형 (선택지)'!$L$30="",0,SUMIFS('선택형 (선택결과)'!$E$3:$E$1000,'선택형 (선택결과)'!$A$3:$A$1000,'선택형 (선택지)'!$L$30,'선택형 (선택결과)'!$C$3:$C$1000,1,'선택형 (선택결과)'!$D$3:$D$1000,0))+IF('선택형 (선택지)'!$L$31="",0,SUMIFS('선택형 (선택결과)'!$E$3:$E$1000,'선택형 (선택결과)'!$A$3:$A$1000,'선택형 (선택지)'!$L$31,'선택형 (선택결과)'!$C$3:$C$1000,1,'선택형 (선택결과)'!$D$3:$D$1000,0))+IF('선택형 (선택지)'!$L$32="",0,SUMIFS('선택형 (선택결과)'!$E$3:$E$1000,'선택형 (선택결과)'!$A$3:$A$1000,'선택형 (선택지)'!$L$32,'선택형 (선택결과)'!$C$3:$C$1000,1,'선택형 (선택결과)'!$D$3:$D$1000,0))+IF('선택형 (선택지)'!$L$33="",0,SUMIFS('선택형 (선택결과)'!$E$3:$E$1000,'선택형 (선택결과)'!$A$3:$A$1000,'선택형 (선택지)'!$L$33,'선택형 (선택결과)'!$C$3:$C$1000,1,'선택형 (선택결과)'!$D$3:$D$1000,0))+IF('선택형 (선택지)'!$L$34="",0,SUMIFS('선택형 (선택결과)'!$E$3:$E$1000,'선택형 (선택결과)'!$A$3:$A$1000,'선택형 (선택지)'!$L$34,'선택형 (선택결과)'!$C$3:$C$1000,1,'선택형 (선택결과)'!$D$3:$D$1000,0))+IF('선택형 (선택지)'!$L$35="",0,SUMIFS('선택형 (선택결과)'!$E$3:$E$1000,'선택형 (선택결과)'!$A$3:$A$1000,'선택형 (선택지)'!$L$35,'선택형 (선택결과)'!$C$3:$C$1000,1,'선택형 (선택결과)'!$D$3:$D$1000,0))+IF('선택형 (선택지)'!$L$36="",0,SUMIFS('선택형 (선택결과)'!$E$3:$E$1000,'선택형 (선택결과)'!$A$3:$A$1000,'선택형 (선택지)'!$L$36,'선택형 (선택결과)'!$C$3:$C$1000,1,'선택형 (선택결과)'!$D$3:$D$1000,0))+IF('선택형 (선택지)'!$L$37="",0,SUMIFS('선택형 (선택결과)'!$E$3:$E$1000,'선택형 (선택결과)'!$A$3:$A$1000,'선택형 (선택지)'!$L$37,'선택형 (선택결과)'!$C$3:$C$1000,1,'선택형 (선택결과)'!$D$3:$D$1000,0))+IF('선택형 (선택지)'!$L$38="",0,SUMIFS('선택형 (선택결과)'!$E$3:$E$1000,'선택형 (선택결과)'!$A$3:$A$1000,'선택형 (선택지)'!$L$38,'선택형 (선택결과)'!$C$3:$C$1000,1,'선택형 (선택결과)'!$D$3:$D$1000,0))+IF('선택형 (선택지)'!$L$39="",0,SUMIFS('선택형 (선택결과)'!$E$3:$E$1000,'선택형 (선택결과)'!$A$3:$A$1000,'선택형 (선택지)'!$L$39,'선택형 (선택결과)'!$C$3:$C$1000,1,'선택형 (선택결과)'!$D$3:$D$1000,0))+IF('선택형 (선택지)'!$L$40="",0,SUMIFS('선택형 (선택결과)'!$E$3:$E$1000,'선택형 (선택결과)'!$A$3:$A$1000,'선택형 (선택지)'!$L$40,'선택형 (선택결과)'!$C$3:$C$1000,1,'선택형 (선택결과)'!$D$3:$D$1000,0))+IF('선택형 (선택지)'!$L$41="",0,SUMIFS('선택형 (선택결과)'!$E$3:$E$1000,'선택형 (선택결과)'!$A$3:$A$1000,'선택형 (선택지)'!$L$41,'선택형 (선택결과)'!$C$3:$C$1000,1,'선택형 (선택결과)'!$D$3:$D$1000,0))+IF('선택형 (선택지)'!$L$42="",0,SUMIFS('선택형 (선택결과)'!$E$3:$E$1000,'선택형 (선택결과)'!$A$3:$A$1000,'선택형 (선택지)'!$L$42,'선택형 (선택결과)'!$C$3:$C$1000,1,'선택형 (선택결과)'!$D$3:$D$1000,0)) -> 9000 | G3: =IF('선택형 (선택지)'!$M$3="",0,SUMIFS('선택형 (선택결과)'!$E$3:$E$1000,'선택형 (선택결과)'!$A$3:$A$1000,'선택형 (선택지)'!$M$3,'선택형 (선택결과)'!$C$3:$C$1000,1,'선택형 (선택결과)'!$D$3:$D$1000,0))+IF('선택형 (선택지)'!$M$4="",0,SUMIFS('선택형 (선택결과)'!$E$3:$E$1000,'선택형 (선택결과)'!$A$3:$A$1000,'선택형 (선택지)'!$M$4,'선택형 (선택결과)'!$C$3:$C$1000,1,'선택형 (선택결과)'!$D$3:$D$1000,0))+IF('선택형 (선택지)'!$M$5="",0,SUMIFS('선택형 (선택결과)'!$E$3:$E$1000,'선택형 (선택결과)'!$A$3:$A$1000,'선택형 (선택지)'!$M$5,'선택형 (선택결과)'!$C$3:$C$1000,1,'선택형 (선택결과)'!$D$3:$D$1000,0))+IF('선택형 (선택지)'!$M$6="",0,SUMIFS('선택형 (선택결과)'!$E$3:$E$1000,'선택형 (선택결과)'!$A$3:$A$1000,'선택형 (선택지)'!$M$6,'선택형 (선택결과)'!$C$3:$C$1000,1,'선택형 (선택결과)'!$D$3:$D$1000,0))+IF('선택형 (선택지)'!$M$7="",0,SUMIFS('선택형 (선택결과)'!$E$3:$E$1000,'선택형 (선택결과)'!$A$3:$A$1000,'선택형 (선택지)'!$M$7,'선택형 (선택결과)'!$C$3:$C$1000,1,'선택형 (선택결과)'!$D$3:$D$1000,0))+IF('선택형 (선택지)'!$M$8="",0,SUMIFS('선택형 (선택결과)'!$E$3:$E$1000,'선택형 (선택결과)'!$A$3:$A$1000,'선택형 (선택지)'!$M$8,'선택형 (선택결과)'!$C$3:$C$1000,1,'선택형 (선택결과)'!$D$3:$D$1000,0))+IF('선택형 (선택지)'!$M$9="",0,SUMIFS('선택형 (선택결과)'!$E$3:$E$1000,'선택형 (선택결과)'!$A$3:$A$1000,'선택형 (선택지)'!$M$9,'선택형 (선택결과)'!$C$3:$C$1000,1,'선택형 (선택결과)'!$D$3:$D$1000,0))+IF('선택형 (선택지)'!$M$10="",0,SUMIFS('선택형 (선택결과)'!$E$3:$E$1000,'선택형 (선택결과)'!$A$3:$A$1000,'선택형 (선택지)'!$M$10,'선택형 (선택결과)'!$C$3:$C$1000,1,'선택형 (선택결과)'!$D$3:$D$1000,0))+IF('선택형 (선택지)'!$M$11="",0,SUMIFS('선택형 (선택결과)'!$E$3:$E$1000,'선택형 (선택결과)'!$A$3:$A$1000,'선택형 (선택지)'!$M$11,'선택형 (선택결과)'!$C$3:$C$1000,1,'선택형 (선택결과)'!$D$3:$D$1000,0))+IF('선택형 (선택지)'!$M$12="",0,SUMIFS('선택형 (선택결과)'!$E$3:$E$1000,'선택형 (선택결과)'!$A$3:$A$1000,'선택형 (선택지)'!$M$12,'선택형 (선택결과)'!$C$3:$C$1000,1,'선택형 (선택결과)'!$D$3:$D$1000,0))+IF('선택형 (선택지)'!$M$13="",0,SUMIFS('선택형 (선택결과)'!$E$3:$E$1000,'선택형 (선택결과)'!$A$3:$A$1000,'선택형 (선택지)'!$M$13,'선택형 (선택결과)'!$C$3:$C$1000,1,'선택형 (선택결과)'!$D$3:$D$1000,0))+IF('선택형 (선택지)'!$M$14="",0,SUMIFS('선택형 (선택결과)'!$E$3:$E$1000,'선택형 (선택결과)'!$A$3:$A$1000,'선택형 (선택지)'!$M$14,'선택형 (선택결과)'!$C$3:$C$1000,1,'선택형 (선택결과)'!$D$3:$D$1000,0))+IF('선택형 (선택지)'!$M$15="",0,SUMIFS('선택형 (선택결과)'!$E$3:$E$1000,'선택형 (선택결과)'!$A$3:$A$1000,'선택형 (선택지)'!$M$15,'선택형 (선택결과)'!$C$3:$C$1000,1,'선택형 (선택결과)'!$D$3:$D$1000,0))+IF('선택형 (선택지)'!$M$16="",0,SUMIFS('선택형 (선택결과)'!$E$3:$E$1000,'선택형 (선택결과)'!$A$3:$A$1000,'선택형 (선택지)'!$M$16,'선택형 (선택결과)'!$C$3:$C$1000,1,'선택형 (선택결과)'!$D$3:$D$1000,0))+IF('선택형 (선택지)'!$M$17="",0,SUMIFS('선택형 (선택결과)'!$E$3:$E$1000,'선택형 (선택결과)'!$A$3:$A$1000,'선택형 (선택지)'!$M$17,'선택형 (선택결과)'!$C$3:$C$1000,1,'선택형 (선택결과)'!$D$3:$D$1000,0))+IF('선택형 (선택지)'!$M$18="",0,SUMIFS('선택형 (선택결과)'!$E$3:$E$1000,'선택형 (선택결과)'!$A$3:$A$1000,'선택형 (선택지)'!$M$18,'선택형 (선택결과)'!$C$3:$C$1000,1,'선택형 (선택결과)'!$D$3:$D$1000,0))+IF('선택형 (선택지)'!$M$19="",0,SUMIFS('선택형 (선택결과)'!$E$3:$E$1000,'선택형 (선택결과)'!$A$3:$A$1000,'선택형 (선택지)'!$M$19,'선택형 (선택결과)'!$C$3:$C$1000,1,'선택형 (선택결과)'!$D$3:$D$1000,0))+IF('선택형 (선택지)'!$M$20="",0,SUMIFS('선택형 (선택결과)'!$E$3:$E$1000,'선택형 (선택결과)'!$A$3:$A$1000,'선택형 (선택지)'!$M$20,'선택형 (선택결과)'!$C$3:$C$1000,1,'선택형 (선택결과)'!$D$3:$D$1000,0))+IF('선택형 (선택지)'!$M$21="",0,SUMIFS('선택형 (선택결과)'!$E$3:$E$1000,'선택형 (선택결과)'!$A$3:$A$1000,'선택형 (선택지)'!$M$21,'선택형 (선택결과)'!$C$3:$C$1000,1,'선택형 (선택결과)'!$D$3:$D$1000,0))+IF('선택형 (선택지)'!$M$22="",0,SUMIFS('선택형 (선택결과)'!$E$3:$E$1000,'선택형 (선택결과)'!$A$3:$A$1000,'선택형 (선택지)'!$M$22,'선택형 (선택결과)'!$C$3:$C$1000,1,'선택형 (선택결과)'!$D$3:$D$1000,0))+IF('선택형 (선택지)'!$M$23="",0,SUMIFS('선택형 (선택결과)'!$E$3:$E$1000,'선택형 (선택결과)'!$A$3:$A$1000,'선택형 (선택지)'!$M$23,'선택형 (선택결과)'!$C$3:$C$1000,1,'선택형 (선택결과)'!$D$3:$D$1000,0))+IF('선택형 (선택지)'!$M$24="",0,SUMIFS('선택형 (선택결과)'!$E$3:$E$1000,'선택형 (선택결과)'!$A$3:$A$1000,'선택형 (선택지)'!$M$24,'선택형 (선택결과)'!$C$3:$C$1000,1,'선택형 (선택결과)'!$D$3:$D$1000,0))+IF('선택형 (선택지)'!$M$25="",0,SUMIFS('선택형 (선택결과)'!$E$3:$E$1000,'선택형 (선택결과)'!$A$3:$A$1000,'선택형 (선택지)'!$M$25,'선택형 (선택결과)'!$C$3:$C$1000,1,'선택형 (선택결과)'!$D$3:$D$1000,0))+IF('선택형 (선택지)'!$M$26="",0,SUMIFS('선택형 (선택결과)'!$E$3:$E$1000,'선택형 (선택결과)'!$A$3:$A$1000,'선택형 (선택지)'!$M$26,'선택형 (선택결과)'!$C$3:$C$1000,1,'선택형 (선택결과)'!$D$3:$D$1000,0))+IF('선택형 (선택지)'!$M$27="",0,SUMIFS('선택형 (선택결과)'!$E$3:$E$1000,'선택형 (선택결과)'!$A$3:$A$1000,'선택형 (선택지)'!$M$27,'선택형 (선택결과)'!$C$3:$C$1000,1,'선택형 (선택결과)'!$D$3:$D$1000,0))+IF('선택형 (선택지)'!$M$28="",0,SUMIFS('선택형 (선택결과)'!$E$3:$E$1000,'선택형 (선택결과)'!$A$3:$A$1000,'선택형 (선택지)'!$M$28,'선택형 (선택결과)'!$C$3:$C$1000,1,'선택형 (선택결과)'!$D$3:$D$1000,0))+IF('선택형 (선택지)'!$M$29="",0,SUMIFS('선택형 (선택결과)'!$E$3:$E$1000,'선택형 (선택결과)'!$A$3:$A$1000,'선택형 (선택지)'!$M$29,'선택형 (선택결과)'!$C$3:$C$1000,1,'선택형 (선택결과)'!$D$3:$D$1000,0))+IF('선택형 (선택지)'!$M$30="",0,SUMIFS('선택형 (선택결과)'!$E$3:$E$1000,'선택형 (선택결과)'!$A$3:$A$1000,'선택형 (선택지)'!$M$30,'선택형 (선택결과)'!$C$3:$C$1000,1,'선택형 (선택결과)'!$D$3:$D$1000,0))+IF('선택형 (선택지)'!$M$31="",0,SUMIFS('선택형 (선택결과)'!$E$3:$E$1000,'선택형 (선택결과)'!$A$3:$A$1000,'선택형 (선택지)'!$M$31,'선택형 (선택결과)'!$C$3:$C$1000,1,'선택형 (선택결과)'!$D$3:$D$1000,0))+IF('선택형 (선택지)'!$M$32="",0,SUMIFS('선택형 (선택결과)'!$E$3:$E$1000,'선택형 (선택결과)'!$A$3:$A$1000,'선택형 (선택지)'!$M$32,'선택형 (선택결과)'!$C$3:$C$1000,1,'선택형 (선택결과)'!$D$3:$D$1000,0))+IF('선택형 (선택지)'!$M$33="",0,SUMIFS('선택형 (선택결과)'!$E$3:$E$1000,'선택형 (선택결과)'!$A$3:$A$1000,'선택형 (선택지)'!$M$33,'선택형 (선택결과)'!$C$3:$C$1000,1,'선택형 (선택결과)'!$D$3:$D$1000,0))+IF('선택형 (선택지)'!$M$34="",0,SUMIFS('선택형 (선택결과)'!$E$3:$E$1000,'선택형 (선택결과)'!$A$3:$A$1000,'선택형 (선택지)'!$M$34,'선택형 (선택결과)'!$C$3:$C$1000,1,'선택형 (선택결과)'!$D$3:$D$1000,0))+IF('선택형 (선택지)'!$M$35="",0,SUMIFS('선택형 (선택결과)'!$E$3:$E$1000,'선택형 (선택결과)'!$A$3:$A$1000,'선택형 (선택지)'!$M$35,'선택형 (선택결과)'!$C$3:$C$1000,1,'선택형 (선택결과)'!$D$3:$D$1000,0))+IF('선택형 (선택지)'!$M$36="",0,SUMIFS('선택형 (선택결과)'!$E$3:$E$1000,'선택형 (선택결과)'!$A$3:$A$1000,'선택형 (선택지)'!$M$36,'선택형 (선택결과)'!$C$3:$C$1000,1,'선택형 (선택결과)'!$D$3:$D$1000,0))+IF('선택형 (선택지)'!$M$37="",0,SUMIFS('선택형 (선택결과)'!$E$3:$E$1000,'선택형 (선택결과)'!$A$3:$A$1000,'선택형 (선택지)'!$M$37,'선택형 (선택결과)'!$C$3:$C$1000,1,'선택형 (선택결과)'!$D$3:$D$1000,0))+IF('선택형 (선택지)'!$M$38="",0,SUMIFS('선택형 (선택결과)'!$E$3:$E$1000,'선택형 (선택결과)'!$A$3:$A$1000,'선택형 (선택지)'!$M$38,'선택형 (선택결과)'!$C$3:$C$1000,1,'선택형 (선택결과)'!$D$3:$D$1000,0))+IF('선택형 (선택지)'!$M$39="",0,SUMIFS('선택형 (선택결과)'!$E$3:$E$1000,'선택형 (선택결과)'!$A$3:$A$1000,'선택형 (선택지)'!$M$39,'선택형 (선택결과)'!$C$3:$C$1000,1,'선택형 (선택결과)'!$D$3:$D$1000,0))+IF('선택형 (선택지)'!$M$40="",0,SUMIFS('선택형 (선택결과)'!$E$3:$E$1000,'선택형 (선택결과)'!$A$3:$A$1000,'선택형 (선택지)'!$M$40,'선택형 (선택결과)'!$C$3:$C$1000,1,'선택형 (선택결과)'!$D$3:$D$1000,0))+IF('선택형 (선택지)'!$M$41="",0,SUMIFS('선택형 (선택결과)'!$E$3:$E$1000,'선택형 (선택결과)'!$A$3:$A$1000,'선택형 (선택지)'!$M$41,'선택형 (선택결과)'!$C$3:$C$1000,1,'선택형 (선택결과)'!$D$3:$D$1000,0))+IF('선택형 (선택지)'!$M$42="",0,SUMIFS('선택형 (선택결과)'!$E$3:$E$1000,'선택형 (선택결과)'!$A$3:$A$1000,'선택형 (선택지)'!$M$42,'선택형 (선택결과)'!$C$3:$C$1000,1,'선택형 (선택결과)'!$D$3:$D$1000,0)) -> -2500 | H3: =SUM(C3:G3) -> 14900
B4: 메달 | C4: =0 -> 0 | D4: =SUMIFS('소비형 (결과)'!$D$3:$D$1001,'소비형 (결과)'!$C$3:$C$1001,1)+SUMIFS('소비형 (결과)'!$F$3:$F$1001,'소비형 (결과)'!$E$3:$E$1001,1) -> 22 | E4: =SUMIFS('보상형 (NPC형)'!$H$3:$H$1001,'보상형 (NPC형)'!$G$3:$G$1001,3)+SUMIFS('보상형 (NPC형)'!$J$3:$J$1001,'보상형 (NPC형)'!$I$3:$I$1001,3)+SUMIFS('보상형 (조건형)'!$N$3:$N$1000,'보상형 (조건형)'!$M$3:$M$1000,3)+SUMIFS('보상형 (조건형)'!$P$3:$P$1000,'보상형 (조건형)'!$O$3:$O$1000,3) -> 13 | F4: =IF('선택형 (선택지)'!$L$3="",0,SUMIFS('선택형 (선택결과)'!$E$3:$E$1000,'선택형 (선택결과)'!$A$3:$A$1000,'선택형 (선택지)'!$L$3,'선택형 (선택결과)'!$C$3:$C$1000,1,'선택형 (선택결과)'!$D$3:$D$1000,1))+IF('선택형 (선택지)'!$L$4="",0,SUMIFS('선택형 (선택결과)'!$E$3:$E$1000,'선택형 (선택결과)'!$A$3:$A$1000,'선택형 (선택지)'!$L$4,'선택형 (선택결과)'!$C$3:$C$1000,1,'선택형 (선택결과)'!$D$3:$D$1000,1))+IF('선택형 (선택지)'!$L$5="",0,SUMIFS('선택형 (선택결과)'!$E$3:$E$1000,'선택형 (선택결과)'!$A$3:$A$1000,'선택형 (선택지)'!$L$5,'선택형 (선택결과)'!$C$3:$C$1000,1,'선택형 (선택결과)'!$D$3:$D$1000,1))+IF('선택형 (선택지)'!$L$6="",0,SUMIFS('선택형 (선택결과)'!$E$3:$E$1000,'선택형 (선택결과)'!$A$3:$A$1000,'선택형 (선택지)'!$L$6,'선택형 (선택결과)'!$C$3:$C$1000,1,'선택형 (선택결과)'!$D$3:$D$1000,1))+IF('선택형 (선택지)'!$L$7="",0,SUMIFS('선택형 (선택결과)'!$E$3:$E$1000,'선택형 (선택결과)'!$A$3:$A$1000,'선택형 (선택지)'!$L$7,'선택형 (선택결과)'!$C$3:$C$1000,1,'선택형 (선택결과)'!$D$3:$D$1000,1))+IF('선택형 (선택지)'!$L$8="",0,SUMIFS('선택형 (선택결과)'!$E$3:$E$1000,'선택형 (선택결과)'!$A$3:$A$1000,'선택형 (선택지)'!$L$8,'선택형 (선택결과)'!$C$3:$C$1000,1,'선택형 (선택결과)'!$D$3:$D$1000,1))+IF('선택형 (선택지)'!$L$9="",0,SUMIFS('선택형 (선택결과)'!$E$3:$E$1000,'선택형 (선택결과)'!$A$3:$A$1000,'선택형 (선택지)'!$L$9,'선택형 (선택결과)'!$C$3:$C$1000,1,'선택형 (선택결과)'!$D$3:$D$1000,1))+IF('선택형 (선택지)'!$L$10="",0,SUMIFS('선택형 (선택결과)'!$E$3:$E$1000,'선택형 (선택결과)'!$A$3:$A$1000,'선택형 (선택지)'!$L$10,'선택형 (선택결과)'!$C$3:$C$1000,1,'선택형 (선택결과)'!$D$3:$D$1000,1))+IF('선택형 (선택지)'!$L$11="",0,SUMIFS('선택형 (선택결과)'!$E$3:$E$1000,'선택형 (선택결과)'!$A$3:$A$1000,'선택형 (선택지)'!$L$11,'선택형 (선택결과)'!$C$3:$C$1000,1,'선택형 (선택결과)'!$D$3:$D$1000,1))+IF('선택형 (선택지)'!$L$12="",0,SUMIFS('선택형 (선택결과)'!$E$3:$E$1000,'선택형 (선택결과)'!$A$3:$A$1000,'선택형 (선택지)'!$L$12,'선택형 (선택결과)'!$C$3:$C$1000,1,'선택형 (선택결과)'!$D$3:$D$1000,1))+IF('선택형 (선택지)'!$L$13="",0,SUMIFS('선택형 (선택결과)'!$E$3:$E$1000,'선택형 (선택결과)'!$A$3:$A$1000,'선택형 (선택지)'!$L$13,'선택형 (선택결과)'!$C$3:$C$1000,1,'선택형 (선택결과)'!$D$3:$D$1000,1))+IF('선택형 (선택지)'!$L$14="",0,SUMIFS('선택형 (선택결과)'!$E$3:$E$1000,'선택형 (선택결과)'!$A$3:$A$1000,'선택형 (선택지)'!$L$14,'선택형 (선택결과)'!$C$3:$C$1000,1,'선택형 (선택결과)'!$D$3:$D$1000,1))+IF('선택형 (선택지)'!$L$15="",0,SUMIFS('선택형 (선택결과)'!$E$3:$E$1000,'선택형 (선택결과)'!$A$3:$A$1000,'선택형 (선택지)'!$L$15,'선택형 (선택결과)'!$C$3:$C$1000,1,'선택형 (선택결과)'!$D$3:$D$1000,1))+IF('선택형 (선택지)'!$L$16="",0,SUMIFS('선택형 (선택결과)'!$E$3:$E$1000,'선택형 (선택결과)'!$A$3:$A$1000,'선택형 (선택지)'!$L$16,'선택형 (선택결과)'!$C$3:$C$1000,1,'선택형 (선택결과)'!$D$3:$D$1000,1))+IF('선택형 (선택지)'!$L$17="",0,SUMIFS('선택형 (선택결과)'!$E$3:$E$1000,'선택형 (선택결과)'!$A$3:$A$1000,'선택형 (선택지)'!$L$17,'선택형 (선택결과)'!$C$3:$C$1000,1,'선택형 (선택결과)'!$D$3:$D$1000,1))+IF('선택형 (선택지)'!$L$18="",0,SUMIFS('선택형 (선택결과)'!$E$3:$E$1000,'선택형 (선택결과)'!$A$3:$A$1000,'선택형 (선택지)'!$L$18,'선택형 (선택결과)'!$C$3:$C$1000,1,'선택형 (선택결과)'!$D$3:$D$1000,1))+IF('선택형 (선택지)'!$L$19="",0,SUMIFS('선택형 (선택결과)'!$E$3:$E$1000,'선택형 (선택결과)'!$A$3:$A$1000,'선택형 (선택지)'!$L$19,'선택형 (선택결과)'!$C$3:$C$1000,1,'선택형 (선택결과)'!$D$3:$D$1000,1))+IF('선택형 (선택지)'!$L$20="",0,SUMIFS('선택형 (선택결과)'!$E$3:$E$1000,'선택형 (선택결과)'!$A$3:$A$1000,'선택형 (선택지)'!$L$20,'선택형 (선택결과)'!$C$3:$C$1000,1,'선택형 (선택결과)'!$D$3:$D$1000,1))+IF('선택형 (선택지)'!$L$21="",0,SUMIFS('선택형 (선택결과)'!$E$3:$E$1000,'선택형 (선택결과)'!$A$3:$A$1000,'선택형 (선택지)'!$L$21,'선택형 (선택결과)'!$C$3:$C$1000,1,'선택형 (선택결과)'!$D$3:$D$1000,1))+IF('선택형 (선택지)'!$L$22="",0,SUMIFS('선택형 (선택결과)'!$E$3:$E$1000,'선택형 (선택결과)'!$A$3:$A$1000,'선택형 (선택지)'!$L$22,'선택형 (선택결과)'!$C$3:$C$1000,1,'선택형 (선택결과)'!$D$3:$D$1000,1))+IF('선택형 (선택지)'!$L$23="",0,SUMIFS('선택형 (선택결과)'!$E$3:$E$1000,'선택형 (선택결과)'!$A$3:$A$1000,'선택형 (선택지)'!$L$23,'선택형 (선택결과)'!$C$3:$C$1000,1,'선택형 (선택결과)'!$D$3:$D$1000,1))+IF('선택형 (선택지)'!$L$24="",0,SUMIFS('선택형 (선택결과)'!$E$3:$E$1000,'선택형 (선택결과)'!$A$3:$A$1000,'선택형 (선택지)'!$L$24,'선택형 (선택결과)'!$C$3:$C$1000,1,'선택형 (선택결과)'!$D$3:$D$1000,1))+IF('선택형 (선택지)'!$L$25="",0,SUMIFS('선택형 (선택결과)'!$E$3:$E$1000,'선택형 (선택결과)'!$A$3:$A$1000,'선택형 (선택지)'!$L$25,'선택형 (선택결과)'!$C$3:$C$1000,1,'선택형 (선택결과)'!$D$3:$D$1000,1))+IF('선택형 (선택지)'!$L$26="",0,SUMIFS('선택형 (선택결과)'!$E$3:$E$1000,'선택형 (선택결과)'!$A$3:$A$1000,'선택형 (선택지)'!$L$26,'선택형 (선택결과)'!$C$3:$C$1000,1,'선택형 (선택결과)'!$D$3:$D$1000,1))+IF('선택형 (선택지)'!$L$27="",0,SUMIFS('선택형 (선택결과)'!$E$3:$E$1000,'선택형 (선택결과)'!$A$3:$A$1000,'선택형 (선택지)'!$L$27,'선택형 (선택결과)'!$C$3:$C$1000,1,'선택형 (선택결과)'!$D$3:$D$1000,1))+IF('선택형 (선택지)'!$L$28="",0,SUMIFS('선택형 (선택결과)'!$E$3:$E$1000,'선택형 (선택결과)'!$A$3:$A$1000,'선택형 (선택지)'!$L$28,'선택형 (선택결과)'!$C$3:$C$1000,1,'선택형 (선택결과)'!$D$3:$D$1000,1))+IF('선택형 (선택지)'!$L$29="",0,SUMIFS('선택형 (선택결과)'!$E$3:$E$1000,'선택형 (선택결과)'!$A$3:$A$1000,'선택형 (선택지)'!$L$29,'선택형 (선택결과)'!$C$3:$C$1000,1,'선택형 (선택결과)'!$D$3:$D$1000,1))+IF('선택형 (선택지)'!$L$30="",0,SUMIFS('선택형 (선택결과)'!$E$3:$E$1000,'선택형 (선택결과)'!$A$3:$A$1000,'선택형 (선택지)'!$L$30,'선택형 (선택결과)'!$C$3:$C$1000,1,'선택형 (선택결과)'!$D$3:$D$1000,1))+IF('선택형 (선택지)'!$L$31="",0,SUMIFS('선택형 (선택결과)'!$E$3:$E$1000,'선택형 (선택결과)'!$A$3:$A$1000,'선택형 (선택지)'!$L$31,'선택형 (선택결과)'!$C$3:$C$1000,1,'선택형 (선택결과)'!$D$3:$D$1000,1))+IF('선택형 (선택지)'!$L$32="",0,SUMIFS('선택형 (선택결과)'!$E$3:$E$1000,'선택형 (선택결과)'!$A$3:$A$1000,'선택형 (선택지)'!$L$32,'선택형 (선택결과)'!$C$3:$C$1000,1,'선택형 (선택결과)'!$D$3:$D$1000,1))+IF('선택형 (선택지)'!$L$33="",0,SUMIFS('선택형 (선택결과)'!$E$3:$E$1000,'선택형 (선택결과)'!$A$3:$A$1000,'선택형 (선택지)'!$L$33,'선택형 (선택결과)'!$C$3:$C$1000,1,'선택형 (선택결과)'!$D$3:$D$1000,1))+IF('선택형 (선택지)'!$L$34="",0,SUMIFS('선택형 (선택결과)'!$E$3:$E$1000,'선택형 (선택결과)'!$A$3:$A$1000,'선택형 (선택지)'!$L$34,'선택형 (선택결과)'!$C$3:$C$1000,1,'선택형 (선택결과)'!$D$3:$D$1000,1))+IF('선택형 (선택지)'!$L$35="",0,SUMIFS('선택형 (선택결과)'!$E$3:$E$1000,'선택형 (선택결과)'!$A$3:$A$1000,'선택형 (선택지)'!$L$35,'선택형 (선택결과)'!$C$3:$C$1000,1,'선택형 (선택결과)'!$D$3:$D$1000,1))+IF('선택형 (선택지)'!$L$36="",0,SUMIFS('선택형 (선택결과)'!$E$3:$E$1000,'선택형 (선택결과)'!$A$3:$A$1000,'선택형 (선택지)'!$L$36,'선택형 (선택결과)'!$C$3:$C$1000,1,'선택형 (선택결과)'!$D$3:$D$1000,1))+IF('선택형 (선택지)'!$L$37="",0,SUMIFS('선택형 (선택결과)'!$E$3:$E$1000,'선택형 (선택결과)'!$A$3:$A$1000,'선택형 (선택지)'!$L$37,'선택형 (선택결과)'!$C$3:$C$1000,1,'선택형 (선택결과)'!$D$3:$D$1000,1))+IF('선택형 (선택지)'!$L$38="",0,SUMIFS('선택형 (선택결과)'!$E$3:$E$1000,'선택형 (선택결과)'!$A$3:$A$1000,'선택형 (선택지)'!$L$38,'선택형 (선택결과)'!$C$3:$C$1000,1,'선택형 (선택결과)'!$D$3:$D$1000,1))+IF('선택형 (선택지)'!$L$39="",0,SUMIFS('선택형 (선택결과)'!$E$3:$E$1000,'선택형 (선택결과)'!$A$3:$A$1000,'선택형 (선택지)'!$L$39,'선택형 (선택결과)'!$C$3:$C$1000,1,'선택형 (선택결과)'!$D$3:$D$1000,1))+IF('선택형 (선택지)'!$L$40="",0,SUMIFS('선택형 (선택결과)'!$E$3:$E$1000,'선택형 (선택결과)'!$A$3:$A$1000,'선택형 (선택지)'!$L$40,'선택형 (선택결과)'!$C$3:$C$1000,1,'선택형 (선택결과)'!$D$3:$D$1000,1))+IF('선택형 (선택지)'!$L$41="",0,SUMIFS('선택형 (선택결과)'!$E$3:$E$1000,'선택형 (선택결과)'!$A$3:$A$1000,'선택형 (선택지)'!$L$41,'선택형 (선택결과)'!$C$3:$C$1000,1,'선택형 (선택결과)'!$D$3:$D$1000,1))+IF('선택형 (선택지)'!$L$42="",0,SUMIFS('선택형 (선택결과)'!$E$3:$E$1000,'선택형 (선택결과)'!$A$3:$A$1000,'선택형 (선택지)'!$L$42,'선택형 (선택결과)'!$C$3:$C$1000,1,'선택형 (선택결과)'!$D$3:$D$1000,1)) -> 33 | G4: =IF('선택형 (선택지)'!$M$3="",0,SUMIFS('선택형 (선택결과)'!$E$3:$E$1000,'선택형 (선택결과)'!$A$3:$A$1000,'선택형 (선택지)'!$M$3,'선택형 (선택결과)'!$C$3:$C$1000,1,'선택형 (선택결과)'!$D$3:$D$1000,1))+IF('선택형 (선택지)'!$M$4="",0,SUMIFS('선택형 (선택결과)'!$E$3:$E$1000,'선택형 (선택결과)'!$A$3:$A$1000,'선택형 (선택지)'!$M$4,'선택형 (선택결과)'!$C$3:$C$1000,1,'선택형 (선택결과)'!$D$3:$D$1000,1))+IF('선택형 (선택지)'!$M$5="",0,SUMIFS('선택형 (선택결과)'!$E$3:$E$1000,'선택형 (선택결과)'!$A$3:$A$1000,'선택형 (선택지)'!$M$5,'선택형 (선택결과)'!$C$3:$C$1000,1,'선택형 (선택결과)'!$D$3:$D$1000,1))+IF('선택형 (선택지)'!$M$6="",0,SUMIFS('선택형 (선택결과)'!$E$3:$E$1000,'선택형 (선택결과)'!$A$3:$A$1000,'선택형 (선택지)'!$M$6,'선택형 (선택결과)'!$C$3:$C$1000,1,'선택형 (선택결과)'!$D$3:$D$1000,1))+IF('선택형 (선택지)'!$M$7="",0,SUMIFS('선택형 (선택결과)'!$E$3:$E$1000,'선택형 (선택결과)'!$A$3:$A$1000,'선택형 (선택지)'!$M$7,'선택형 (선택결과)'!$C$3:$C$1000,1,'선택형 (선택결과)'!$D$3:$D$1000,1))+IF('선택형 (선택지)'!$M$8="",0,SUMIFS('선택형 (선택결과)'!$E$3:$E$1000,'선택형 (선택결과)'!$A$3:$A$1000,'선택형 (선택지)'!$M$8,'선택형 (선택결과)'!$C$3:$C$1000,1,'선택형 (선택결과)'!$D$3:$D$1000,1))+IF('선택형 (선택지)'!$M$9="",0,SUMIFS('선택형 (선택결과)'!$E$3:$E$1000,'선택형 (선택결과)'!$A$3:$A$1000,'선택형 (선택지)'!$M$9,'선택형 (선택결과)'!$C$3:$C$1000,1,'선택형 (선택결과)'!$D$3:$D$1000,1))+IF('선택형 (선택지)'!$M$10="",0,SUMIFS('선택형 (선택결과)'!$E$3:$E$1000,'선택형 (선택결과)'!$A$3:$A$1000,'선택형 (선택지)'!$M$10,'선택형 (선택결과)'!$C$3:$C$1000,1,'선택형 (선택결과)'!$D$3:$D$1000,1))+IF('선택형 (선택지)'!$M$11="",0,SUMIFS('선택형 (선택결과)'!$E$3:$E$1000,'선택형 (선택결과)'!$A$3:$A$1000,'선택형 (선택지)'!$M$11,'선택형 (선택결과)'!$C$3:$C$1000,1,'선택형 (선택결과)'!$D$3:$D$1000,1))+IF('선택형 (선택지)'!$M$12="",0,SUMIFS('선택형 (선택결과)'!$E$3:$E$1000,'선택형 (선택결과)'!$A$3:$A$1000,'선택형 (선택지)'!$M$12,'선택형 (선택결과)'!$C$3:$C$1000,1,'선택형 (선택결과)'!$D$3:$D$1000,1))+IF('선택형 (선택지)'!$M$13="",0,SUMIFS('선택형 (선택결과)'!$E$3:$E$1000,'선택형 (선택결과)'!$A$3:$A$1000,'선택형 (선택지)'!$M$13,'선택형 (선택결과)'!$C$3:$C$1000,1,'선택형 (선택결과)'!$D$3:$D$1000,1))+IF('선택형 (선택지)'!$M$14="",0,SUMIFS('선택형 (선택결과)'!$E$3:$E$1000,'선택형 (선택결과)'!$A$3:$A$1000,'선택형 (선택지)'!$M$14,'선택형 (선택결과)'!$C$3:$C$1000,1,'선택형 (선택결과)'!$D$3:$D$1000,1))+IF('선택형 (선택지)'!$M$15="",0,SUMIFS('선택형 (선택결과)'!$E$3:$E$1000,'선택형 (선택결과)'!$A$3:$A$1000,'선택형 (선택지)'!$M$15,'선택형 (선택결과)'!$C$3:$C$1000,1,'선택형 (선택결과)'!$D$3:$D$1000,1))+IF('선택형 (선택지)'!$M$16="",0,SUMIFS('선택형 (선택결과)'!$E$3:$E$1000,'선택형 (선택결과)'!$A$3:$A$1000,'선택형 (선택지)'!$M$16,'선택형 (선택결과)'!$C$3:$C$1000,1,'선택형 (선택결과)'!$D$3:$D$1000,1))+IF('선택형 (선택지)'!$M$17="",0,SUMIFS('선택형 (선택결과)'!$E$3:$E$1000,'선택형 (선택결과)'!$A$3:$A$1000,'선택형 (선택지)'!$M$17,'선택형 (선택결과)'!$C$3:$C$1000,1,'선택형 (선택결과)'!$D$3:$D$1000,1))+IF('선택형 (선택지)'!$M$18="",0,SUMIFS('선택형 (선택결과)'!$E$3:$E$1000,'선택형 (선택결과)'!$A$3:$A$1000,'선택형 (선택지)'!$M$18,'선택형 (선택결과)'!$C$3:$C$1000,1,'선택형 (선택결과)'!$D$3:$D$1000,1))+IF('선택형 (선택지)'!$M$19="",0,SUMIFS('선택형 (선택결과)'!$E$3:$E$1000,'선택형 (선택결과)'!$A$3:$A$1000,'선택형 (선택지)'!$M$19,'선택형 (선택결과)'!$C$3:$C$1000,1,'선택형 (선택결과)'!$D$3:$D$1000,1))+IF('선택형 (선택지)'!$M$20="",0,SUMIFS('선택형 (선택결과)'!$E$3:$E$1000,'선택형 (선택결과)'!$A$3:$A$1000,'선택형 (선택지)'!$M$20,'선택형 (선택결과)'!$C$3:$C$1000,1,'선택형 (선택결과)'!$D$3:$D$1000,1))+IF('선택형 (선택지)'!$M$21="",0,SUMIFS('선택형 (선택결과)'!$E$3:$E$1000,'선택형 (선택결과)'!$A$3:$A$1000,'선택형 (선택지)'!$M$21,'선택형 (선택결과)'!$C$3:$C$1000,1,'선택형 (선택결과)'!$D$3:$D$1000,1))+IF('선택형 (선택지)'!$M$22="",0,SUMIFS('선택형 (선택결과)'!$E$3:$E$1000,'선택형 (선택결과)'!$A$3:$A$1000,'선택형 (선택지)'!$M$22,'선택형 (선택결과)'!$C$3:$C$1000,1,'선택형 (선택결과)'!$D$3:$D$1000,1))+IF('선택형 (선택지)'!$M$23="",0,SUMIFS('선택형 (선택결과)'!$E$3:$E$1000,'선택형 (선택결과)'!$A$3:$A$1000,'선택형 (선택지)'!$M$23,'선택형 (선택결과)'!$C$3:$C$1000,1,'선택형 (선택결과)'!$D$3:$D$1000,1))+IF('선택형 (선택지)'!$M$24="",0,SUMIFS('선택형 (선택결과)'!$E$3:$E$1000,'선택형 (선택결과)'!$A$3:$A$1000,'선택형 (선택지)'!$M$24,'선택형 (선택결과)'!$C$3:$C$1000,1,'선택형 (선택결과)'!$D$3:$D$1000,1))+IF('선택형 (선택지)'!$M$25="",0,SUMIFS('선택형 (선택결과)'!$E$3:$E$1000,'선택형 (선택결과)'!$A$3:$A$1000,'선택형 (선택지)'!$M$25,'선택형 (선택결과)'!$C$3:$C$1000,1,'선택형 (선택결과)'!$D$3:$D$1000,1))+IF('선택형 (선택지)'!$M$26="",0,SUMIFS('선택형 (선택결과)'!$E$3:$E$1000,'선택형 (선택결과)'!$A$3:$A$1000,'선택형 (선택지)'!$M$26,'선택형 (선택결과)'!$C$3:$C$1000,1,'선택형 (선택결과)'!$D$3:$D$1000,1))+IF('선택형 (선택지)'!$M$27="",0,SUMIFS('선택형 (선택결과)'!$E$3:$E$1000,'선택형 (선택결과)'!$A$3:$A$1000,'선택형 (선택지)'!$M$27,'선택형 (선택결과)'!$C$3:$C$1000,1,'선택형 (선택결과)'!$D$3:$D$1000,1))+IF('선택형 (선택지)'!$M$28="",0,SUMIFS('선택형 (선택결과)'!$E$3:$E$1000,'선택형 (선택결과)'!$A$3:$A$1000,'선택형 (선택지)'!$M$28,'선택형 (선택결과)'!$C$3:$C$1000,1,'선택형 (선택결과)'!$D$3:$D$1000,1))+IF('선택형 (선택지)'!$M$29="",0,SUMIFS('선택형 (선택결과)'!$E$3:$E$1000,'선택형 (선택결과)'!$A$3:$A$1000,'선택형 (선택지)'!$M$29,'선택형 (선택결과)'!$C$3:$C$1000,1,'선택형 (선택결과)'!$D$3:$D$1000,1))+IF('선택형 (선택지)'!$M$30="",0,SUMIFS('선택형 (선택결과)'!$E$3:$E$1000,'선택형 (선택결과)'!$A$3:$A$1000,'선택형 (선택지)'!$M$30,'선택형 (선택결과)'!$C$3:$C$1000,1,'선택형 (선택결과)'!$D$3:$D$1000,1))+IF('선택형 (선택지)'!$M$31="",0,SUMIFS('선택형 (선택결과)'!$E$3:$E$1000,'선택형 (선택결과)'!$A$3:$A$1000,'선택형 (선택지)'!$M$31,'선택형 (선택결과)'!$C$3:$C$1000,1,'선택형 (선택결과)'!$D$3:$D$1000,1))+IF('선택형 (선택지)'!$M$32="",0,SUMIFS('선택형 (선택결과)'!$E$3:$E$1000,'선택형 (선택결과)'!$A$3:$A$1000,'선택형 (선택지)'!$M$32,'선택형 (선택결과)'!$C$3:$C$1000,1,'선택형 (선택결과)'!$D$3:$D$1000,1))+IF('선택형 (선택지)'!$M$33="",0,SUMIFS('선택형 (선택결과)'!$E$3:$E$1000,'선택형 (선택결과)'!$A$3:$A$1000,'선택형 (선택지)'!$M$33,'선택형 (선택결과)'!$C$3:$C$1000,1,'선택형 (선택결과)'!$D$3:$D$1000,1))+IF('선택형 (선택지)'!$M$34="",0,SUMIFS('선택형 (선택결과)'!$E$3:$E$1000,'선택형 (선택결과)'!$A$3:$A$1000,'선택형 (선택지)'!$M$34,'선택형 (선택결과)'!$C$3:$C$1000,1,'선택형 (선택결과)'!$D$3:$D$1000,1))+IF('선택형 (선택지)'!$M$35="",0,SUMIFS('선택형 (선택결과)'!$E$3:$E$1000,'선택형 (선택결과)'!$A$3:$A$1000,'선택형 (선택지)'!$M$35,'선택형 (선택결과)'!$C$3:$C$1000,1,'선택형 (선택결과)'!$D$3:$D$1000,1))+IF('선택형 (선택지)'!$M$36="",0,SUMIFS('선택형 (선택결과)'!$E$3:$E$1000,'선택형 (선택결과)'!$A$3:$A$1000,'선택형 (선택지)'!$M$36,'선택형 (선택결과)'!$C$3:$C$1000,1,'선택형 (선택결과)'!$D$3:$D$1000,1))+IF('선택형 (선택지)'!$M$37="",0,SUMIFS('선택형 (선택결과)'!$E$3:$E$1000,'선택형 (선택결과)'!$A$3:$A$1000,'선택형 (선택지)'!$M$37,'선택형 (선택결과)'!$C$3:$C$1000,1,'선택형 (선택결과)'!$D$3:$D$1000,1))+IF('선택형 (선택지)'!$M$38="",0,SUMIFS('선택형 (선택결과)'!$E$3:$E$1000,'선택형 (선택결과)'!$A$3:$A$1000,'선택형 (선택지)'!$M$38,'선택형 (선택결과)'!$C$3:$C$1000,1,'선택형 (선택결과)'!$D$3:$D$1000,1))+IF('선택형 (선택지)'!$M$39="",0,SUMIFS('선택형 (선택결과)'!$E$3:$E$1000,'선택형 (선택결과)'!$A$3:$A$1000,'선택형 (선택지)'!$M$39,'선택형 (선택결과)'!$C$3:$C$1000,1,'선택형 (선택결과)'!$D$3:$D$1000,1))+IF('선택형 (선택지)'!$M$40="",0,SUMIFS('선택형 (선택결과)'!$E$3:$E$1000,'선택형 (선택결과)'!$A$3:$A$1000,'선택형 (선택지)'!$M$40,'선택형 (선택결과)'!$C$3:$C$1000,1,'선택형 (선택결과)'!$D$3:$D$1000,1))+IF('선택형 (선택지)'!$M$41="",0,SUMIFS('선택형 (선택결과)'!$E$3:$E$1000,'선택형 (선택결과)'!$A$3:$A$1000,'선택형 (선택지)'!$M$41,'선택형 (선택결과)'!$C$3:$C$1000,1,'선택형 (선택결과)'!$D$3:$D$1000,1))+IF('선택형 (선택지)'!$M$42="",0,SUMIFS('선택형 (선택결과)'!$E$3:$E$1000,'선택형 (선택결과)'!$A$3:$A$1000,'선택형 (선택지)'!$M$42,'선택형 (선택결과)'!$C$3:$C$1000,1,'선택형 (선택결과)'!$D$3:$D$1000,1)) -> -7 | H4: =SUM(C4:G4) -> 61
