Workbook

Sheet 문서 개요
A2: 《Hero Influence》 전투 데이터 테이블
B4: 수정 날짜 | C4: 버전 | D4: 담당자 | E4: 수정 내역 | F4: 비고
B5: 46108 | C5: V1.0 | D5: 강현재 | E5: 아군 및 적군 유닛 임시 스테이터스 기입, 직업 스킬 기획
B6: 46114 | C6: V1.1 | D6: 강현재 | E6: 성장 시스템 및 테이블 필드 정의
B7: 46115 | C7: V1.2 | D7: 강현재 | E7: 무기 및 무기 스킬 콘텐츠
B8: 46119 | C8: V1.3 | D8: 강현재 | E8: 1. 복수 스킬 타깃 판정용 필드 추가: 스킬 복수 대상, 스킬 복수 대상 타입, 스킬 복수 대상 수 2. 적군 유닛 시트 및 필드 정의 추가: 경험치, 드롭 아이템 인덱스, 드롭 수량, 드롭 확률
B9: 46120 | C9: V2.0 | D9: 강현재 | E9: 1. 유닛 수 추가 → 단계별 스테이터스 정의 2. 스탯 시뮬레이터 재생성
B10: 46121 | C10: V2.1 | D10: 강현재 | E10: 3. 성장 시스템 수정 (유닛/유닛 그룹 분화 반영) 4. 적군 유닛 → 적군 유닛 그룹 개편 5. 1:1 전투 시뮬레이터
B11: 46125 | C11: V3.1 | D11: 강현재 | E11: 적 부대 AI 시트 추가
B12: 46132 | C12: V4.0 | D12: 강현재 | E12: 시민 호감도 시스템 추가 및 이에 따른 아군 유닛 스테이터스 구조 변경 1) 유닛-유닛그룹-부대 → 유닛-부대 구조 복귀 2) 성장 시스템 개편 3) 아군 유닛, 적군 유닛, 스탯 시뮬레이터, 전투 시뮬레이터 반영 및 기초 밸런스 4) 적군 부대 AI 간략화
B13: 46133 | C13: V4.1 | D13: 강현재 | E13: 스킬 코스트 추가
A15: 1. 문서 목적
B16: 이 문서는 《Hero Influence》의 전투 시스템에서 사용되는 유닛 스테이터스, 성장 구조, 시민 호감도(Influence), 적군 부대 AI 등 시스템을 정의하고, 이를 데이터 테이블 형태로 정리하여 프로토타입 구현 및 밸런스 조정을 가능하게 하는 것을 목적으로 한다.
A18: 2. 문서 기획 의도
B19: 본 데이터 정리 및 밸런스 조정의 목적은, 플레이어가 원활한 성장 곡선을 체감하며 전략적 선택의 재미를 경험하도록 하는 데 있다. 1) 아군 및 적군 유닛의 스테이터스와 성장 구조를 통해 플레이어가 전투를 통해 점진적으로 강해지는 성장을 체감하도록 한다. 2) 시민 호감도(Influence)를 전투 자원으로 활용하여, 플레이어가 매 턴마다 자원을 유지하며 안정적으로 싸울지, 혹은 소모하여 강한 스킬을 사용할지 선택하는 전략적 판단을 경험하도록 한다. 3) 데이터 테이블 기반 전투 시뮬레이션을 통해 다양한 상황에서의 전투 밸런스를 사전에 검증하고, 플레이어가 예측 가능한 규칙 속에서 결과를 이해하고 납득할 수 있는 전투 경험을 제공하는 것을 목표로 한다. 4) 호감도를 통해 전투력과 자원 관리가 연결된 구조를 설계하여, 플레이어가 탐사-성장-전투의 흐름 속에서 축적한 성과를 전투에서 직접적으로 활용하는 경험을 제공한다.
A21: 3. 문서 범위
B22: 이 문서는 다음 내용을 다룬다. 1) 스테이터스 정의 및 규칙 → '스테이터스' 시트 2) 성장 시스템 정의 및 랭크별 스테이터스 증가 규칙 + 필요 경험치 테이블 → '성장 시스템' 시트 3) 아군 직업별 스테이터스 → '아군 유닛' 시트 4) 적군 스테이터스 및 스킬 사용 우선 순위 테이블 → '적군 유닛' 시트 5) 적군 부대 행동 우선 순위 테이블 → '적군 부대 AI' 시트 6) 직업 스킬 테이블 → '직업 스킬' 시트 7) 무기 및 무기 스킬 테이블 → '무기' 시트 8) (밸런스) 랭크별 스테이터스 변동 계산 → '스탯 시뮬레이터' 시트 9) (밸런스) 전투 대미지 계산 → '전투 시뮬레이터' 시트 - 유닛 단위 전투 시뮬레이션을 통해 전투 결과, 턴 수, 피해량, 승패 등을 확인한다.
A24: 4. 문서 대상
B25: 이 문서는 다음을 대상으로 한다. 1) 전투 시스템 기획자 2) 전투 시스템 프로그래머 3) 탐사 적 부대 AI 시스템 프로그래머

Sheet 스테이터스
A2: 1. 유닛 단위 정의
B3: 1) 유닛
B4: 유닛(Unit)은 전투에서 직접 행동하는 최소 단위이며 (V2.0-3.0의 유닛-유닛 그룹-부대 구조에서 V1.0의 유닛-부대 구조로 복귀한다), 각 유닛은 랭크(기존 레벨 개념)에 따라 성장하는 독립적인 스테이터스(체력, 공격력, 방어력, 치명타율, 반격률, 피해 경감률, 스피드)와 호감도(기존 유닛수 대체)를 가진다. 유닛은 클래스에 따라 외형 및 보유 스킬, 역할이 구분된다.
B6: 2) 부대
B7: 부대는 2×3 슬롯으로 구성되며, 프로토타입 기준으로 플레이어 부대는 4개의 유닛 + 2개의 빈 슬롯으로 구성된다. 인카운터 전투는 1:1 부대 단위로 수행된다. 각 유닛의 유닛 공격력과 유닛 체력, 유닛 방어력을 합산해 부대 전투력을 표시한다. 필드 이동 시 부대 단위로 이동하게 된다.
A9: 2. 단위별 스테이터스
B10: 1) 유닛 스테이터스
B11: 스테이터스명 | C11: 설명 | D11: 규칙
B12: 유닛 랭크 | C12: 유닛이 경험치를 통해 올릴 수 있는 등급 A-Z 사이 대문자 알파벳으로 표시한다. 유닛이 다음 랭크에 도달할 때마다 다음 중 일부 효과가 적용된다. (구체적인 성장 공식 및 랭크별 받는 효과는 성장 시스템 시트 참조) 1. 일부 유닛 스테이터스(최대 체력, 공격력, 방어력)에 랭크업 보정치를 추가 2. 특정 랭크에 신규 직업 스킬 습득 3. 특정 랭크마다 유닛 최대 시민 호감도 증가 | D12: 매 랭크 업 시, 유닛 스테이터스 증가 Lv1 직업 스킬 (기본 스킬) Lv2 최대 시민 호감도 증가 Lv3 직업 스킬 Lv4 최대 시민 호감도 증가 Lv5 직업 스킬 Lv6 최대 시민 호감도 증가 Lv7 직업 스킬 Lv8 최대 시민 호감도 증가 Lv9 최대 시민 호감도 증가 Lv10 직업 스킬 Lv11 최대 시민 호감도 증가 Lv12 직업 스킬 Lv13 최대 시민 호감도 증가 Lv14 최대 시민 호감도 증가 Lv15 직업 스킬
B13: 유닛 체력 | C13: 유닛이 생존하기 위해 지닌 체력 | D13: * 유닛 최대 체력 > 0 * 유닛 최대 체력 > 유닛 현재 체력 * 유닛 현재 체력이 0일 경우 리타이어 상태 전환
B14: 유닛 공격력 | C14: 유닛이 지닌 공격력, 유닛 대미지 계산에 사용된다 | D14: * 기본 피해량 = (공격 유닛 공격력 - 피격 유닛 방어력) × 스킬 계수 × 유닛 시민 호감도 보정
B15: 유닛 방어력 | C15: 유닛이 지닌 방어력, 유닛 대미지 계산에 사용된다
B16: 유닛 시민 호감도 | C16: 시민 호감도(Influence)는 각 유닛이 보유하는 전투 자원으로, 시민의 지지를 통해 형성된 전투력의 크기를 나타낸다. 호감도는 유닛 단위로 개별 관리되며, 전투 및 탐사 과정에서 증가하거나 감소한다. 현재 호감도는 해당 유닛의 전투 성능에 직접적으로 영향을 주며, 스킬 계수에 반영된다. | D16: * 유닛 최대 호감도 > 유닛 현재 호감도 * 기본 유닛 호감도 100(현재)/200(최대) * 호감도 계수 = 현재 호감도 / 100 예시) 기본 시민 호감도 100일 때 호감도 보정 100% 0일 때 호감도 보정 0%, 200일 때 호감도 보정 200% * 유닛 현재 호감도가 0일 경우, 호감도 소모 스킬 사용 불가
B17: 치명타율 | C17: 유닛이 공격했을 때, 치명타가 발생할 확률 | D17: * 치명타 발생시, 주는 대미지 증가: 기본 피해량의 150% 대미지 증가 * 치명타율 최대 70%
B18: 반격율 | C18: 전열 유닛이 공격을 받았을 때 반격할 확률 | D18: * 반격 발생시, 상대에게 반격자 공격력의 50% 대미지 증가 * 반격률 최대 70%
B19: 피해 경감율 | C19: 후열 유닛이 공격을 받았을 때 대미지를 경감시킬 확률 | D19: * 피해 경감 발생 시, 받는 피해량을 50% 감소 * 피해경감율 최대 70%
B20: 스피드 | C20: 전투 시 유닛의 행동 순서를 1차적으로 정하기 위한 기준값 | D20: * 0 ~ 4 범위 내 정수
B22: 2) 부대 스테이터스 (인카운트 전투 진입 전 적군 부대의 전투력을 가늠하기 위해 사용)
B23: 스테이터스명 | C23: 설명 | D23: 규칙
B24: 부대 체력 | C24: 부대 내 모든 유닛의 현재 체력 합 | D24: * 모든 유닛의 현재 유닛 체력 합 × 부대 체력 계수(기본값 1)
B25: 부대 공격력 | C25: 부대 내 모든 유닛의 공격력 합, 탐험 필드 내 NPC간 전투에서 필드 기본 피해량 계산에 사용된다 | D25: * 모든 유닛의 현재 유닛 공격력 합 × 부대 공격력 계수(기본값 1)
B26: 부대 방어력 | C26: 부대 내 모든 유닛의 방어력 합 | D26: * 모든 유닛의 현재 유닛 방어력 합 × 부대 방어력 계수(기본값 1)
B27: 부대 전투력 | C27: 플레이어가 상대와 자신의 전력차를 가늠해 볼 수 있도록 부대 내 유닛들의 강함을 숫자로 표기 | D27: * 부대 전투력 = 부대 체력 + 부대 공격력 + 부대 방어력

Sheet 성장 시스템
A2: 1. 성장 시스템 방향성
B3: 《Hero Influence》의 전투는 게임의 핵심인 4X (탐험, 확장, 성장, 섬멸) 진행 중 발생하는 턴제 전투가 전체 게임 흐름을 크게 끊지 않도록 하는 것을 목표로 한다. 이에 따라 성장 시스템은 다음 4가지 방향성을 가진다. 1) 초반에는 1~2회, 중후반에는 2~3회의 인카운터 전투를 통해 유닛이 랭크업하도록 설계 2) 전투 템포를 유지하기 위해 체력 및 방어력의 성장률은 완만하게 설계 3) 공격력이 체력보다 상대적으로 빠르게 성장하도록 설계 4) 클래스 간 역할 구분은 유지하되, 모든 클래스가 전열과 후열 모두에서 활용 가능하도록 설계 - 동일 랭크 적 기준, 최소 1회의 공격을 생존할 수 있도록 체력 및 체력 성장률 설계 - 동일 랭크 적 기준, 1회 공격 시 최소 피해량이 대상 최대 체력의 10~25% 이상이 되도록 설계 3) 유닛의 기본 전투 성능은 랭크에 따라 결정되지만, 실제 전투 결과에 미치는 영향은 시민 호감도가 더 크게 작용하도록 설계
A5: 2. 랭크업 스테이터스 증가 규칙
B6: 1) 랭크업을 해도 수치가 변하지 않는 스테이터스는 다음과 같다. - 치명타율 - 반격률 - 피해 경감율 - 스피드 (상기 스테이터스는 랭크업으로는 증가하지 않으며, 장비 착용, 진형 효과, 스킬 효과 등으로만 변동) 2) 랭크업에 따라 수치가 증가하는 스테이터스는 다음과 같다. - 유닛 최대 체력 - 유닛 공격력 - 유닛 방어력 3) 유닛 랭크업 시, 유닛의 현재 체력은 최대 체력으로 회복된다. 4) 지정된 랭크 달성 직후, 최대 시민 호감도가 증가한다. (오르는 랭크 시점 및 양은 전투 경험치 테이블 참조) 5) 유닛 시민 현재 호감도는 증가하지 않으며, 기존 수치를 그대로 유지한다.
A8: 3. 유닛 랭크업 추가 스테이터스
B9: 1) 유닛 스테이터스는 랭크가 오를 때마다 랭크업 기본 보정치 + 클래스별 추가 보정치가 추가된다. 2) 랭크업 추가 보정치는 클래스마다 오르는 스테이터스 수치가 다르나 올라가는 총합은 동일하다. 3) 예시 - F랭크 워리어, 최대 체력 10 - E랭크 워리어, 최대 체력 = 10 + 1 (기본 보정치) + 3 (추가 보정치) = 14 - D랭크 워리어, 최대 체력 = 14 + 1 + 3 = 18
B11: 기본 보정치 | C11: 유닛 최대 체력 | D11: 유닛 공격력 | E11: 유닛 방어력
C12: 1 | D12: 1 | E12: 1
B14: 클래스별 추가 보정치 | C14: 유닛 최대 체력 | D14: 유닛 공격력 | E14: 유닛 방어력
B15: 워리어 | C15: 2 | D15: 1 | E15: 0
B16: 메이지 | C16: 0 | D16: 2 | E16: 0
B17: 아처 | C17: 1 | D17: 1 | E17: 0
B18: 클레릭 | C18: 1 | D18: 0 | E18: 1
B19: 나이트 | C19: 0 | D19: 1 | E19: 1
A21: 4. 경험치 획득 규칙
B22: 1) 경험치는 인카운트 전투 승리 시 획득한다. (전투 패배 시에는 획득하지 않는다.) 2) 얻는 총 경험치는 쓰러트린 모든 적의 경험치 합산이다. 3) 전투 승리 시 생존 상태의 모든 유닛은 총 경험치 ÷ 부대 내 전체 유닛 수(4) 만큼의 경험치를 균등하게 나눠 얻는다. 4) 딱 나눠 떨어지지 않을 경우, 남은 경험치는 누적 경험치가 가장 낮은 임의의 유닛에게 돌아간다. 5) 리타이어한 유닛 몫의 경험치는 상실된다. (의도: 특정 유닛을 의도적으로 리타이어 상태로 유지하여 경험치를 집중시키는 플레이를 방지하기 위함) 예시) 게임 시작 시 4인 부대 중 생존 유닛 3명 총 경험치: 30 A (생존): 7 B (생존): 7 C (생존): 9 (7 + 잔여 경함치 2) D (리타이어): 0 (경험치 7 상실)
A24: 5. 전투 경험치 테이블
F25: 4 | I25: 기본 최대 시민 호감도 | J25: 100
B26: 레벨 | C26: 랭크 표시 | D26: 유닛당 랭크업 필요 경험치 | E26: 동일 랭크 몬스터 1마리 당 평균 경험치 | F26: 적군 {}인 파티 기준 총 경험치 | G26: 4인 부대 아군 유닛당 획득 경험치 | H26: 랭크업 시 필요한 전투 수 | I26: 스킬 | J26: 최대 시민 호감도 추가 | K26: 신규 스킬 획득까지 필요한 전투 수 | L26: 무기 획득 추천 타이밍
B27: 1 | C27: N | D27: 0 | E27: 10 | F27: =E27*$F$25 -> 40 | G27: =F27/4 -> 10 | H27: 0 | I27: 기본 스킬 | L27: 기본 무기 | S27: 몬스터 수 최소값(2) → 랭크업당 2~6번 전투
B28: 2 | C28: M | D28: =D27+$E$27 -> 10 | H28: =(D28-D27)/$G$27 -> 1 | J28: 10
B29: 3 | C29: L | D29: =D28+$E$27 -> 20 | H29: =(D29-D28)/$G$27 -> 1 | I29: 신규 스킬 | K29: 2
B30: 4 | C30: K | D30: =D29+$E$30 -> 40 | E30: 20 | F30: =E30*$F$25 -> 80 | G30: =F30/4 -> 20 | H30: =(D30-D29)/$G$30 -> 1 | J30: 10 | L30: 신규 무기
B31: 5 | C31: J | D31: =D30+$E$30 -> 60 | H31: =(D31-D30)/$G$30 -> 1 | I31: 신규 스킬 | K31: 2
B32: 6 | C32: I | D32: =D31+$E$30 -> 80 | H32: =(D32-D31)/$G$30 -> 1 | J32: 10
B33: 7 | C33: H | D33: =D32+$E$33 -> 110 | E33: 30 | F33: =E33*$F$25 -> 120 | G33: =F33/4 -> 30 | H33: =(D33-D32)/$G$33 -> 1 | I33: 신규 스킬 | K33: 2
B34: 8 | C34: G | D34: =D33+$E$33 -> 140 | H34: =(D34-D33)/$G$33 -> 1 | J34: 10 | L34: 신규 무기
B35: 9 | C35: F | D35: =D34+$E$33 -> 170 | H35: =(D35-D34)/$G$33 -> 1 | J35: 10
B36: 10 | C36: E | D36: =D35+$E$36*2 -> 250 | E36: 40 | F36: =E36*$F$25 -> 160 | G36: =F36/4 -> 40 | H36: =(D36-D35)/$G$36 -> 2 | I36: 신규 스킬 | K36: 3
B37: 11 | C37: D | D37: =D36+$E$36*2 -> 330 | H37: =(D37-D36)/$G$36 -> 2 | J37: 10 | L37: 신규 무기
B38: 12 | C38: C | D38: =D37+$E$36*2 -> 410 | H38: =(D38-D37)/$G$36 -> 2 | I38: 신규 스킬 | K38: 2 | S38: 몬스터 수 평균값(4) → 랭크업당 1~3번 전투
B39: 13 | C39: B | D39: =D38+$E$39*3 -> 560 | E39: 50 | F39: =E39*$F$25 -> 200 | G39: =F39/4 -> 50 | H39: =(D39-D38)/$G$39 -> 3 | J39: 20
B40: 14 | C40: A | D40: =D39+$E$39*3 -> 710 | H40: =(D40-D39)/$G$39 -> 3 | J40: 20 | L40: 신규 무기
B41: 15 | C41: S | D41: =D40+$E$39*3 -> 860 | H41: =(D41-D40)/$G$39 -> 3 | I41: 신규 스킬 | K41: 3
B42: 총 전투 수 | H42: =SUM(H27:H41) -> 23 | J42: =SUM(J25:J41) -> 200
R48: 몬스터 수 최대값(5) → 랭크업당 1~2번 전투

Sheet 필드 정의
A2: 1. 인덱스
B3: 개발명 | C3: 필드명 | D3: 타입 | E3: 표기 규칙
B4: 아군 유닛 인덱스 | C4: ClassIndex | D4: int | E4: 1로 시작하는 다섯 자리 자연수로 표기, 예시) 10001
B5: 적군 유닛 인덱스 | C5: EnemyIndex | D5: int | E5: 2로 시작하는 다섯 자리 자연수로 표기, 예시) 20001
B6: 적군 부대 인덱스 | C6: EnemyArmyIndex | D6: int | E6: 3로 시작하는 다섯 자리 자연수로 표기, 예시) 30001
B7: 직업 스킬 인덱스 | C7: ClassSkillIndex | D7: int | E7: 네 자리 자연수로 표기, 예시) 1010 (맨 첫자리는 직업 코드: 1 워리어 2 아처 3 위저드 4 클레릭)
B8: 적군 스킬 인덱스 | C8: EnemySkillIndex | D8: int | E8: 2로 시작하는 여섯 자리 자연수로 표기, 예시) 210001
B9: 무기 인덱스 | C9: WeaponIndex | D9: int | E9: 3으로 시작하는 여섯 자리 자연수로 표기, 예시) 310001 (3 무기 + 1~3 장비 종류 + 0 + 1~9 직업 코드 + 01~99 인덱스)
B10: 무기 스킬 인덱스 | C10: WeaponSkillIndex | D10: int | E10: 3으로 시작하는 여섯 자리 자연수로 표기, 예시) 311010 (3 무기 + 1~3 장비 종류 + 1~9 직업 코드 + 001~999 인덱스)
A12: 2. 아군/적군 캐릭터 공통 스테이터스 (인카운트 전투 시 사용)
B13: 개발명 | C13: 필드명 | D13: 타입 | E13: 표기 규칙
B14: 유닛 최대 체력 | C14: UnitMaxHP | D14: int | E14: UnitMaxHP > 0
B15: 유닛 공격력 | C15: UnitATK | D15: int | E15: 999 > UnitATK > 0
B16: 유닛 방어력 | C16: UnitDEF | D16: int | E16: 999 > UnitDEF > 0
B17: 치명타율 | C17: CriticalRate | D17: int | E17: n % 단위로 표기, 70% ≥ CriticalRate
B18: 반격율 | C18: CounterRate | D18: int | E18: n % 단위로 표기, 70% ≥ CounterRate
B19: 피해 경감 확률 | C19: ReduceRate | D19: int | E19: n % 단위로 표기, 70% ≥ ReduceRate
B20: 스피드 | C20: Speed | D20: int | E20: 4 ≥ Speed ≥ 0
A22: 3. 스킬 공통 데이터
B23: 개발명 | C23: 필드명 | D23: 타입 | E23: 표기 규칙
B24: 스킬 효과 | C24: SkillEffect | D24: int | E24: 0 공격 스킬 (적군을 대상으로 함) 1 회복 스킬 (아군을 대상으로 함)
B25: 스킬 사정거리 | C25: SkillRange | D25: int | E25: 0 근거리 스킬 (전열이 있을 경우 전열을 우선) 1 원거리 스킬
B26: 스킬 대상 | C26: SkillTarget | D26: int | E26: 0 단일 대상 1 복수 대상(한 열, 2인 등) 2 전체 대상 0일 경우, 스킬 대상 1명을 고른다 1일 경우, 범위는 스킬 설명에 따라 선택한다 2일 경우, 대상 선택 없이 바로 실행한다
B27: 스킬 복수 대상 | C27: SkillMultiTarget | D27: list<int> | E27: 스킬 대상(SkillTarget)이 1인 경우 사용 복수 대상 스킬이 선택된 최초 타깃(0)을 기준으로 한 추가 타깃 후보 위치 목록 (범위 내 유닛이 존재하는 칸만 유효 타깃으로 처리, 범위 밖 무시) 근거리 스킬의 최초 선택 타깃은 기존 전열 우선 규칙을 따른다. * 추가 타깃 포지션 번호 타깃 중복: 0, 상단: 1, 우상단: 2, 우측: 3, 우하단: 4, 하단: 5, 좌하단: 6, 좌측: 7, 좌상단: 8
B28: 스킬 복수 대상 타입 | C28: SkillMultiTargetType | D28: int | E28: 스킬 대상(SkillTarget)이 1인 경우 사용 0 추가 타깃 후보 전체 적용 1 추가 타깃 후보 중 n명 랜덤 선택 | G28: 8 | H28: 1 | I28: 2
B29: 스킬 복수 추가 대상 수 | C29: SkillMultiTargetCount | D29: int | E29: 스킬 복수 대상 타입(SkillMultiTargetType)이 1인 경우 사용 | G29: 7 | H29: 타깃(0) | I29: 3
B30: 스킬 계수 | C30: SkillValue | D30: float | E30: 공격 스킬: 배율 단위 표시 (예: 1.5 → 150%) 회복 스킬: 고정 수치 표시 | G30: 6 | H30: 5 | I30: 4
B31: 추가 스킬 계수 | C31: SkillSubValue | D31: float | E31: 스킬 대상(SkillTarget)이 1인 경우 사용 서로 다른 계수를 가진 복수 범위 스킬, 여러 번 공격하는 스킬 등에 사용
B32: IP 코스트 | C32: IPCost | D32: int | E32: 스킬 사용에 필요한 IP 량
A34: 4. 아군 유닛
B35: 개발명 | C35: 필드명 | D35: 타입 | E35: 표기 규칙
B36: 아군 유닛 인덱스 | C36: ClassIndex | D36: int | E36: 1로 시작하는 다섯 자리 자연수로 표기, 예시) 10001
B37: 유닛명 (예정) | C37: HeroName | D37: string | E37: 히어로 이름
B38: 클래스명 | C38: ClassName | D38: string | E38: 서로 다른 스테이터스를 가진 직업군, 캐릭터 생성 시 선택
B39: 클래스 콘셉트 | C39: ClassConcept | D39: string | E39: 유닛 콘셉트 소개
B40: 히어로 타입 (예정) | C40: HeroType | D40: string | E40: 히어로 유형, 예시) 인간, 사이보그, 수인 등
B41: 캐릭터 공통 스테이터스
B42: 사용 가능 직업 스킬 | C42: ClassSkillIndexList | D42: list<int> | E42: 착용 가능한 직업 스킬 인덱스, 중괄호{} 내 공백 없이 숫자와 쉼표로 기입, 예시) 1010,1020,1030,1040,1050,1060,1070
B43: 사용 가능 무기 | C43: WeaponIndexList | D43: list<int> | E43: 착용 가능한 무기 인덱스, 중괄호{} 내 공백 없이 숫자와 쉼표로 기입, 예시) 310101,310102,310103,310104,310105,310106,310107
A45: 5. 적군 유닛
...

Sheet 아군 유닛
A1: ClassIndex | B1: ClassName | C1: ClassConcept | D1: UnitMaxHP | E1: UnitATK | F1: UnitDEF | G1: CriticalRate | H1: CounterRate | I1: ReduceRate | J1: Speed | K1: ClassSkill IndexList | L1: Weapon IndexList
A2: 아군 유닛 인덱스 | B2: 클래스명 | C2: 클래스 콘셉트 | D2: 유닛 최대 체력 | E2: 유닛 공격력 | F2: 유닛 방어력 | G2: 치명타율 | H2: 반격율 | I2: 피해 경감률 | J2: 스피드 | K2: 착용 가능 직업 스킬 인덱스 | L2: 착용 가능 무기 인덱스
A3: 10001 | B3: 워리어 | C3: 체력이 높은 근거리 병종 | D3: 7 | E3: 7 | F3: 6 | G3: 0.1 | H3: 0.25 | I3: 0.1 | J3: 1 | K3: {1010,1020,1030,1040,1050,1060,1070} | L3: {310101,310102,310103,310104,310105,310106,310107}
A4: 10002 | B4: 메이지 | C4: 단일 공격에 특화된 원거리 병종 | D4: 4 | E4: 12 | F4: 4 | G4: 0.3 | H4: 0.1 | I4: 0.2 | J4: 3 | K4: {2010,2020,2030,2040,2050,2060,2070} | L4: {310201,310202,310203,310204,310205,310206,310207}
A5: 10003 | B5: 아처 | C5: 다중 공격에 특화된 원거리 병종 | D5: 6 | E5: 12 | F5: 2 | G5: 0.2 | H5: 0.05 | I5: 0.1 | J5: 2 | K5: {3010,3020,3030,3040,3050,3060,3070} | L5: {310301,310302,310303,310304,310305,310306,310307}
A6: 10004 | B6: 클레릭 | C6: 회복이 가능한 원거리 병종 | D6: 6 | E6: 8 | F6: 6 | G6: 0.1 | H6: 0.1 | I6: 0.15 | J6: 2 | K6: {4010,4020,4030,4040,4050,4060,4070} | L6: {310401,310402,310403,310404,310405,310406,310407}
A7: 10005 | B7: 나이트 | C7: 평균적인 능력치를 지닌 근거리 병종 | D7: 6 | E7: 9 | F7: 5 | G7: 0.15 | H7: 0.15 | I7: 0.15 | J7: 2 | K7: {5010,5020,5030,5040,5050,5060,5070} | L7: {310501,310502,310503,310504,310505,310506,310507}

Sheet 적군 유닛
A1: EnemyIndex | B1: EnemyName | C1: EnemyConcept | D1: UnitMaxHP | E1: UnitATK | F1: UnitDEF | G1: CriticalRate | H1: CounterRate | I1: ReduceRate | J1: Speed | K1: EnemySkill1 Name | L1: EnemySkill1 Description | M1: EnemySkill1Effect | N1: EnemySkill1Range | O1: EnemySkill1Target | P1: EnemySkill1MultiTarget | Q1: EnemySkill1 MultiTargetType | R1: EnemySkill1 MultiTargetCount | S1: EnemySkill1Value | T1: EnemySkill2 Name | U1: EnemySkill2 Description | V1: EnemySkill2Effect | W1: EnemySkill2Range | X1: EnemySkill2Target | Y1: EnemySkill2MultiTarget | Z1: EnemySkill2 MultiTargetType | AA1: EnemySkill2 MultiTargetCount | AB1: EnemySkill2Value | AC1: UnitAI | AD1: ExperiencePoint | AE1: DropItem1Index | AF1: DropItem1Count | AG1: DropItem1Rate
A2: 적군 유닛 인덱스 | B2: 적군 유닛명 | C2: 적군 유닛 콘셉트 | D2: 유닛 최대 체력 | E2: 유닛 공격력 | F2: 유닛 방어력 | G2: 치명타율 | H2: 반격율 | I2: 회피율 | J2: 스피드 | K2: 적군 스킬1 스킬명 | L2: 적군 스킬1 설명 | M2: 적군 스킬 1 효과 (0 공격 1 회복) | N2: 적군 스킬 1 사정거리 (0 근거리 1 원거리) | O2: 적군 스킬 1 대상 (0 단일 1 복수 2 전체) | P2: 적군 스킬 1 복수 대상 (스킬 대상 1일 경우) | Q2: 적군 스킬 1 복수 대상 타입 (0 후보 전체 1 랜덤) (스킬 대상 1일 경우) | R2: 적군 스킬 1 복수 추가 대상 수 (스킬 대상 1일 경우) | S2: 적군 스킬 1 계수 | T2: 적군 스킬2 스킬명 | U2: 적군 스킬2 설명 | V2: 적군 스킬 2 효과 (0 공격 1 회복) | W2: 적군 스킬 12 사정거리 (0 근거리 1 원거리) | X2: 적군 스킬 2 대상 (0 단일 1 복수 2 전체) | Y2: 적군 스킬 2 복수 대상 (스킬 대상 1일 경우) | Z2: 적군 스킬 2 복수 대상 타입 (0 후보 전체 1 랜덤) (스킬 대상 1일 경우) | AA2: 적군 스킬 2 복수 추가 대상 수 (스킬 대상 1일 경우) | AB2: 적군 스킬 2 계수 | AC2: 적군 유닛 행동 규칙 | AD2: 경험치 | AE2: 드롭 아이템 1 인덱스 | AF2: 드롭 아이템 1 드롭 수량 | AG2: 드롭 아이템 1 드롭 확률
A3: 20001 | B3: LowerMonster | C3: 하급 몬스터 | D3: 12 | E3: 6 | F3: 6 | G3: 0.1 | H3: 0.1 | I3: 0.1 | J3: 2 | K3: 하급 몬스터 스킬1 | L3: 상대 전열 또는 후열 단일 공격 (전열 우선) | M3: 0 | N3: 1 | O3: 0 | S3: 1 | T3: 하급 몬스터 스킬2 | U3: 상대 1열을 전체 공격 (전열 우선) | V3: 0 | W3: 0 | X3: 1 | Y3: {1,5} | Z3: 0 | AB3: 0.5 | AC3: 70% 확률로 스킬1, 30% 확률로 스킬2 | AD3: 10 | AE3: {310101,310201,310301,310401} | AF3: 1 | AG3: 0.7
A4: 20002 | B4: MiddleMonster | C4: 중급 몬스터 | D4: 27 | E4: 22 | F4: 10 | G4: 0.2 | H4: 0.15 | I4: 0.15 | J4: 3 | K4: 중급 몬스터 스킬1 | L4: 상대 전열 또는 후열 단일 공격 | M4: 0 | N4: 2 | O4: 0 | S4: 1.3 | T4: 중급 몬스터 스킬2 | U4: 자신의 체력 50 단일 회복 | V4: 1 | X4: 0 | AB4: 50 | AC4: 일반 상황에서는 스킬1(50:50 확률로 젼열 또는 후열 타깃), 체력 60 이하 시 스킬2 | AD4: 20 | AE4: {310102,310202,310302,310402} | AF4: 1 | AG4: 0.5
A5: 20003 | B5: AdvancedMonster | C5: 상급 몬스터 | D5: 50 | E5: 42 | F5: 14 | G5: 0.25 | H5: 0.2 | I5: 0.2 | J5: 1 | K5: 상급 몬스터 스킬1 | L5: 상대 전열 또는 후열 단일 공격 | M5: 0 | N5: 2 | O5: 0 | S5: 1 | T5: 상급 몬스터 스킬2 | U5: 상대 전체 공격 | V5: 0 | W5: 1 | X5: 2 | AB5: 0.8 | AC5: 70% 확률로 스킬1 (70% 확률로 상대 후열 우선), 30% 확률로 스킬2 | AD5: 30 | AE5: {310103,310203,310303,310403} | AF5: 1 | AG5: 0.3

Sheet 적군 부대 AI
A1: EnemyArmy Index | B1: Enemy UnitGroup1 | C1: Enemy UnitGroup2 | D1: Enemy UnitGroup3 | E1: Enemy UnitGroup4 | F1: AIType | G1: Resource TargetRate | H1: Combat TargetRate | I1: Monster TargetRate | J1: Player TargetRate | K1: Recognition Range | L1: Move Distance
A2: 적군 부대 인덱스 | B2: 유닛 그룹1 | C2: 유닛 그룹2 | D2: 유닛 그룹3 | E2: 유닛 그룹4 | F2: AI 행동 패턴 (0: 공격형, 1: 균형형, 2: 안정형) | G2: 자원/생산지 우선 확률 (생산지 > 자원) | H2: 플레이어/플레이어 성 전투 우선 확률 (성 > 플레이어) | I2: 몬스터 우선 확률 | J2: 적 영지/부대 확률 | K2: 인식 범위 | L2: 이동 거리
A3: 30001 | B3: 20001 | C3: 20001 | D3: 20002 | F3: 0 | G3: 0.2 | H3: 0.8 | I3: 0.25 | J3: 0.75 | K3: 10 | L3: 5
A4: 30002 | B4: 20001 | C4: 20001 | D4: 20002 | F4: 1 | G4: 0.5 | H4: 0.5 | I4: 0.5 | J4: 0.5 | K4: 10 | L4: 5
A5: 30003 | B5: 20001 | C5: 20001 | D5: 20002 | F5: 2 | G5: 0.7 | H5: 0.3 | I5: 0.75 | J5: 0.25 | K5: 10 | L5: 5

Sheet 직업 스킬
A1: ClassSkillIndex | B1: Class | C1: ClassSkill AcquireLevel | D1: ClassSkillName | E1: ClassSkillDescription | F1: IPCost | G1: ClassSkillEffect | H1: ClassSkillRange | I1: ClassSkillTarget | J1: ClassSkillMultiTarget | K1: ClassSkill MultiTargetType | L1: ClassSkill MultiTargetCount | M1: ClassSkillValue | N1: ClassSkillSubValue
A2: 직업 스킬 인덱스 | B2: 직업명 | C2: 습득 레벨 | D2: 직업 스킬명 | E2: 직업 스킬 설명 | F2: IP 코스트 | G2: 직업 스킬 효과 (0 공격 1 회복) | H2: 직업 스킬 사정거리 (0 근거리 1 원거리) | I2: 직업 스킬 대상 (0 단일 1 복수 2 전체) | J2: 직업 스킬 복수 대상 (스킬 대상 1일 경우) | K2: 직업 스킬 복수 대상 타입 (0 후보 전체 1 랜덤) (스킬 대상 1일 경우) | L2: 직업 스킬 복수 추가 대상 수 (스킬 대상 1일 경우) | M2: 직업 스킬 계수 | N2: 직업 스킬 추가 계수 | P2: 스킬 복수 대상
A3: 1010 | B3: 워리어 | C3: 1 | D3: 도발 베기 | E3: 적 1명에게 120% 대미지를 입히고, 1턴 동안 해당 대상이 단일 공격 시 자신을 공격하게 한다. (적 전열이 있을 경우, 전열 우선 공격) | F3: 0 | G3: 0 | H3: 0 | I3: 0 | M3: 1.2 | P3: 8 | Q3: 1 | R3: 2
A4: 1020 | B4: 워리어 | C4: 3 | D4: 일렬 베기 | E4: 적 한 열에 100% 대미지를 입힌다. (적 전열이 있을 경우, 전열 우선 공격) | F4: 0 | G4: 0 | H4: 0 | I4: 1 | J4: {1,5} | K4: 0 | M4: 1 | P4: 7 | Q4: 타깃(0) | R4: 3
A5: 1030 | B5: 워리어 | C5: 5 | D5: 관통 | E5: 전열의 적 한 명에게 60% 대미지를 입히고, 해당 후열에 있는 적 한 명에게 추가로 80% 대미지를 입힌다. (전열의 적이 없을 경우 후열의 적 한 명만을 공격) | F5: 0 | G5: 0 | H5: 0 | I5: 0 | J5: {3} | K5: 0 | L5: 1 | M5: 0.6 | N5: 0.8 | P5: 6 | Q5: 5 | R5: 4
A6: 1040 | B6: 워리어 | C6: 7 | D6: 광역 도발 | E6: 적 한 열에 100% 대미지를 입히고, 1턴 동안 모든 적이 단일 공격 시 자신을 공격하게 한다. (적 전열이 있을 경우, 전열 우선 공격) | F6: 0 | G6: 0 | H6: 0 | I6: 1 | J6: {1,5} | K6: 0 | M6: 1
A7: 1050 | B7: 워리어 | C7: 10 | D7: 돌파 | E7: 적 1명에게 120% 대미지를 입힌다. (후열에 있는 적도 공격 가능하다.) | F7: 0 | G7: 0 | H7: 0 | I7: 0 | M7: 1.2
A8: 1060 | B8: 워리어 | C8: 12 | D8: 쌍렬 베기 | E8: 적 전열과 후열의 모든 적에게 60% 대미지를 준다. | F8: 0 | G8: 0 | H8: 0 | I8: 2 | M8: 0.6
A9: 1070 | B9: 워리어 | C9: 15 | D9: 불굴 | E9: 자신의 체력이 낮을수록 적 1명에게 높은 대미지를 입힌다. (기본 100% + 최대 체력 대비 현재 체력 20%가 낮아질 때마다 20% 추가, 최대 180%) | F9: 0 | G9: 0 | H9: 0 | I9: 0 | M9: 1
A10: 2010 | B10: 아처 | C10: 1 | D10: 정밀 사격 | E10: 적 1명에게 100% 대미지를 입힌다. | F10: 0 | G10: 0 | H10: 1 | I10: 0 | M10: 1
A11: 2020 | B11: 아처 | C11: 3 | D11: 전열 저격 | E11: 적 1명에게 100% 대미지를 입힌다. 전열의 적을 공격 시, 120% 대미지로 계산한다. | F11: 0 | G11: 0 | H11: 1 | I11: 0 | M11: 1.2
A12: 2030 | B12: 아처 | C12: 5 | D12: 후열 저격 | E12: 적 1명에게 100% 대미지를 입힌다. 후열의 적을 공격 시 대미지 계산 전 회피율을 20% 내린다. | F12: 0 | G12: 0 | H12: 1 | I12: 0 | M12: 1
A13: 2040 | B13: 아처 | C13: 7 | D13: 연속 사격 | E13: 적 1명에게 70% 대미지를 두 번 입힌다. (치명타, 회피율 판정은 각각 계산한다.) | F13: 0 | G13: 0 | H13: 1 | I13: 0 | J13: {0} | K13: 0 | M13: 0.7 | N13: 0.7
A14: 2050 | B14: 아처 | C14: 10 | D14: 급소 저격 | E14: 적 1명에게 100% 대미지를 입힌다. 체력 70% 이하 대상 공격 시 대미지 계산 전 치명타 확률을 20% 올린다. | F14: 0 | G14: 0 | H14: 1 | I14: 0 | M14: 1
A15: 2060 | B15: 아처 | C15: 12 | D15: 화살비 | E15: 적 전열과 후열의 모든 적에게 50% 대미지를 준다. | F15: 0 | G15: 0 | H15: 1 | I15: 2 | M15: 0.5
A16: 2070 | B16: 아처 | C16: 15 | D16: 최후의 일격 | E16: 적의 체력이 낮을 수록 높은 대미지를 입힌다. (기본 100% + 적의 최대 체력 대비 현재 체력 10%가 낮아질 때마다 10% 추가, 최대 180%) | F16: 0 | G16: 0 | H16: 1 | I16: 0 | M16: 1
A17: 3010 | B17: 메이지 | C17: 1 | D17: 파이어볼 | E17: 적 1명에게 100% 대미지를 입힌다. | F17: 0 | G17: 0 | H17: 1 | I17: 0 | M17: 1
A18: 3020 | B18: 메이지 | C18: 3 | D18: 번개 확산 | E18: 적 한 열에 80% 대미지를 입힌다. | F18: 0 | G18: 0 | H18: 1 | I18: 1 | J18: {1,5} | K18: 0 | M18: 0.8
A19: 3030 | B19: 메이지 | C19: 5 | D19: 마력 집중 | E19: 적 한 명에게 180% 대미지를 입힌다. 다음 자신의 턴 1턴을 건너뛴다. | F19: 0 | G19: 0 | H19: 1 | I19: 0 | M19: 1.8
A20: 3040 | B20: 메이지 | C20: 7 | D20: 연쇄 번개 | E20: 전열의 적 한 명에게 70% 대미지를 입히고, 인접한 적 한 명에게 추가로 50% 대미지를 입힌다. | F20: 0 | G20: 0 | H20: 1 | I20: 0 | J20: {1,3,5} | K20: 1 | L20: 1 | M20: 0.7 | N20: 0.5
A21: 3050 | B21: 메이지 | C21: 10 | D21: 메테오 | E21: 적 전열과 후열의 모든 적에게 60% 대미지를 준다. | F21: 0 | G21: 0 | H21: 1 | I21: 2 | M21: 0.6
A22: 3060 | B22: 메이지 | C22: 12 | D22: 마력 폭발 | E22: 적 1명에게 체력이 높을수록 높은 대미지를 입힌다. (기본 150% + 적의 최대 체력 대비 현재 체력 10%가 낮아질 때마다 10% 감소, 최소 100%) | F22: 0 | G22: 0 | H22: 1 | I22: 0 | M22: 1.5
A23: 3070 | B23: 메이지 | C23: 15 | D23: 붕괴 | E23: 이 공격을 맞는 적의 수가 적을수록 높은 대미지를 입힌다. (기본 100% + 전 진형의 빈 칸 하나당 20%, 최대 180%) | F23: 0 | G23: 0 | H23: 1 | I23: 2 | M23: 1
A24: 4010 | B24: 클레릭 | C24: 1 | D24: 힐 | E24: 아군 1명 체력 30% 회복, IP 10 고정 회복 | F24: 0 | G24: 1 | I24: 0
A25: 4020 | B25: 클레릭 | C25: 3 | D25: 신성탄 | E25: 적 1명에게 100% 대미지를 입히고, 입힌 대미지 만큼 아군의 1명의 IP 회복 (최대 20) | F25: 0 | G25: 0 | H25: 1 | I25: 0 | M25: 0.8
A26: 4030 | B26: 클레릭 | C26: 5 | D26: 긴급 치유 | E26: 아군 1명의 체력을 회복한다. (기본 5 + 최대 체력 대비 현재 체력 20%가 낮아질 때마다 15 추가, 최대 50) | F26: 0 | G26: 1 | I26: 0
A27: 4040 | B27: 클레릭 | C27: 7 | D27: 심판의 빛 | E27: 적 1명에게 100% 대미지를 입히고 체력을 회복할 수 없게 한다. | F27: 0 | G27: 0 | H27: 1 | I27: 0 | M27: 1
A28: 4050 | B28: 클레릭 | C28: 10 | D28: 광역 힐 | E28: 아군 1명의 체력을 10% 회복하고, 인접한 아군 1명의 체력을 10% 추가 회복한다. | F28: 0 | G28: 1 | I28: 0
A29: 4060 | B29: 클레릭 | C29: 12 | D29: 신성 폭발 | E29: 적 전열과 후열의 모든 적에게 50% 대미지를 준다. | F29: 0 | G29: 0 | H29: 1 | I29: 2 | M29: 0.5
A30: 4070 | B30: 클레릭 | C30: 15 | D30: 기적 | E30: 사망한 아군 1명을 체력 20%로 부활시킨다. (한 전투당 한 번만 사용 가능) | F30: 0 | G30: 1 | I30: 0
A31: 5010 | B31: 나이트 | C31: 1 | D31: 정면 베기 | E31: 적 1명에게 120% 대미지를 입힌다. 대상이 전열일 경우 150% 대미지를 입힌다. (적 전열이 있을 경우, 전열 우선 공격) | F31: 0 | G31: 0 | H31: 0 | I31: 0 | J31: {0} | K31: 0 | M31: 1.2 | N31: 0.3
A32: 5020 | B32: 나이트 | C32: 3 | D32: 검기 | E32: 적 1명에게 150% 대미지를 입힌다. (후열 공격 가능) | F32: 0 | G32: 0 | H32: 2 | I32: 0 | M32: 1.5
A33: 5030 | B33: 나이트 | C33: 5 | D33: 후열 돌파 | E33: 적의 후열에 100% 근접 대미지를 준다. 적의 후열이 없는 경우, 전열에 50% 대미지를 준다. | F33: 0 | G33: 0 | H33: 0 | I33: 1 | J33: {1,5} | K33: 0 | M33: 1
A34: 5040 | B34: 나이트 | C34: 7 | D34: 연속 베기 | E34: 적 1명에게 90% 대미지를 두 번 입힌다. (적 전열이 있을 경우, 전열 우선 공격, 치명타, 회피율 판정은 각각 계산한다.) | F34: 0 | G34: 0 | H34: 0 | I34: 0 | M34: 0.9 | N34: 0.9
A35: 5050 | B35: 나이트 | C35: 10 | D35: 급소 찌르기 | E35: 적 1명에게 치명타 확률이 20% 높은 120% 대미지를 입힌다. (적 전열이 있을 경우, 전열 우선 공격) | F35: 0 | G35: 0 | H35: 0 | I35: 0 | M35: 1.2
A36: 5060 | B36: 나이트 | C36: 12 | D36: 전술 베기 | E36: 적의 체력이 낮을 수록 높은 대미지를 입힌다. (기본 100% + 적의 최대 체력 대비 현재 체력 10%가 낮아질 때마다 10% 추가, 최대 150%)(적 전열이 있을 경우, 전열 우선 공격) | F36: 0 | G36: 0 | H36: 0 | I36: 0 | M36: 1.5
A37: 5070 | B37: 나이트 | C37: 15 | D37: 결투 | E37: 적 1명에게 120% 대미지를 입힌다. 아군과 적군이 각각 1명씩 남았을 경우 200% 대미지를 입힌다. | F37: 0 | G37: 0 | H37: 0 | I37: 0 | M37: 1.2

Sheet 장비 시스템
A2: 1. 장비 시스템 요약
B3: 장비 시스템은 캐릭터의 전투 성능을 보조하는 요소로, 프로토타입 단계에서는 무기만 사용한다. 무기는 공격력 증가와 전용 스킬을 제공하며, 장비 교체 및 강화는 영지에서 수행된다. (영지 시스템 작성 예정) 장비 데이터는 단일 구조로 관리하며, 인덱스를 통해 무기/방어구/장신구를 구분한다. 무기는 클래스당 기본 무기가 착용된 상태로 시작되며, 장비창에서 무기를 공란으로 둘 수 없다. 무기 내구도는 존재하지 존재하지 않는다. 몬스터는 장비를 착용하지 않은 것으로 간주한다. 향후 방어구 및 장신구가 추가될 예정이며, 클래스가 전열/후열에 관계없이 활용될 수 있도록 스테이터스를 보완하는 방향으로 확장한다.

Sheet 무기
A1: WeaponIndex | B1: Class | C1: WeaponName | D1: WaeponDescription | E1: BonusMaxHP | F1: BonusATK | G1: BonusDEF | H1: BonusCriticalRate | I1: BonusCounterRate | J1: BonusReduceRate | K1: BonusSpeed | L1: WeaponSkillIndex | M1: WeaponSkillName | N1: WeaponSkillDescription | O1: IPCost | P1: WeaponSkillEffect | Q1: WeaponSkillRange | R1: WeaponSkillTarget | S1: WeaponSkillMultiTarget | T1: WeaponSkill MultiTargetType | U1: WeaponSkill MultiTargetCount | V1: WeaponSkillValue | W1: WeaponSkillSubValue
A2: 무기 인덱스 | B2: 직업 | C2: 무기명 | D2: 무기 설명 | E2: 최대 체력 증가량 | F2: 공격력 증가량 | G2: 방어력 증가량 | H2: 치명타율 증가량 | I2: 반격율 증가량 | J2: 피해 경감 확률 증가량 | K2: 스피드 증가량 | L2: 무기 스킬 인덱스 | M2: 무기 스킬명 | N2: 무기 스킬 설명 | O2: IP 코스트 | P2: 무기 스킬 효과 (0 공격 1 회복) | Q2: 무기 스킬 사정거리 (0 근거리 1 원거리) | R2: 무기 스킬 대상 (0 단일 1 복수 2 전체) | S2: 무기 스킬 복수 대상 (스킬 대상 1일 경우) | T2: 무기 스킬 복수 대상 타입 (0 후보 전체 1 랜덤) (스킬 대상 1일 경우) | U2: 무기 스킬 복수 추가 대상 수 (스킬 대상 1일 경우) | V2: 무기 스킬 계수 | W2: 무기 스킬 추가 계수 | Y2: 스킬 복수 대상
A3: 310101 | B3: 워리어 | C3: 하급 도끼 | D3: 기본 제공 무기 | F3: 1 | L3: 311010 | M3: 강타 | N3: 적 유닛 1명에게 150% 대미지를 준다. (전열 우선) | O3: 10 | P3: 0 | Q3: 0 | R3: 0 | V3: 1.5 | Y3: 8 | Z3: 1 | AA3: 2
A4: 310102 | B4: 워리어 | C4: 중급 도끼 | D4: 후열 특화 무기 | F4: 2 | H4: 0.15 | L4: 311020 | M4: 기합 | N4: 적 유닛 1명에게 기합을 날려 원거리 대미지 180%를 준다. | O4: 30 | P4: 0 | Q4: 0 | R4: 0 | V4: 1.8 | Y4: 7 | Z4: 타깃(0) | AA4: 3
A5: 310103 | B5: 워리어 | C5: 상급 도끼 | D5: 최상급 무기 | F5: 3 | I5: 0.1 | L5: 311030 | M5: 회전 베기 | N5: 적 유닛 1명에게 250% 대미지를 준다. (전열 우선) | O5: 50 | P5: 0 | Q5: 0 | R5: 0 | V5: 2.5 | Y5: 6 | Z5: 5 | AA5: 4
A6: 310201 | B6: 아처 | C6: 하급 활 | D6: 기본 제공 무기 | F6: 1 | L6: 312010 | M6: 정밀 조준 | N6: 적 유닛 1명에게 150% 대미지를 준다. | O6: 10 | P6: 0 | Q6: 1 | R6: 0 | V6: 1.5
A7: 310202 | B7: 아처 | C7: 중급 활 | D7: 전열 특화 무기 | F7: 2 | I7: 0.15 | L7: 312020 | M7: 숏보우 | N7: 적 한 열의 적에게 화살을 발사하여 120% 대미지를 준다 (전열 우선) | O7: 30 | P7: 0 | Q7: 0 | R7: 1 | S7: {1,5} | T7: 0 | V7: 1.2
A8: 310203 | B8: 아처 | C8: 상급 활 | D8: 최상급 무기 | F8: 3 | H8: 0.1 | L8: 312030 | M8: 속사 | N8: 적 유닛 한 명에게 120% 대미지를 주는 화살을 두 발 발사한다. (확률 보정은 독립적으로 진행) | O8: 50 | P8: 0 | Q8: 1 | R8: 0 | V8: 1.2 | W8: 1.2
A9: 310301 | B9: 메이지 | C9: 하급 완드 | D9: 기본 제공 무기 | F9: 1 | L9: 313010 | M9: 매직 미사일 | N9: 적 유닛 1명에게 150% 대미지를 준다. | O9: 10 | P9: 0 | Q9: 1 | R9: 0 | V9: 1.5
A10: 310302 | B10: 메이지 | C10: 중급 완드 | D10: 전열 특화 무기 | F10: 2 | H10: 0.07 | I10: 0.07 | L10: 313020 | M10: 더블 클로 | N10: 적 1명에게 80% 대미지를 주고, 인접한 적 1명에게 추가로 80% 대미지를 준다. (근거리로 취급하나 후열 공격 가능) | O10: 30 | P10: 0 | Q10: 0 | R10: 1 | S10: {1,3,5} | T10: 1 | U10: 1 | V10: 0.8 | W10: 0.8
A11: 310303 | B11: 메이지 | C11: 상급 완드 | D11: 최상급 무기 | F11: 3 | H11: 0.05 | J11: 0.05 | L11: 313030 | M11: 마력 방출 | N11: 적 모든 유닛에게 120% 대미지를 준다. | O11: 50 | P11: 0 | Q11: 1 | R11: 2 | V11: 1.2
A12: 310401 | B12: 클레릭 | C12: 하급 스태프 | D12: 기본 제공 무기 | F12: 1 | L12: 314010 | M12: 성광 | N12: 적 유닛 1명에게 150% 대미지를 준다. | O12: 10 | P12: 0 | Q12: 1 | R12: 0 | V12: 1.5
A13: 310402 | B13: 클레릭 | C13: 중급 스태프 | D13: 공격 특화 무기 | F13: 5 | H13: 0.1 | L13: 314020 | M13: 신성한 주먹 | N13: 적 유닛 1명을 신성력을 두른 완드로 근접 타격하여 180% 대미지를 준다. (전열 우선) | O13: 30 | P13: 0 | Q13: 0 | R13: 0 | V13: 1.8
A14: 310403 | B14: 클레릭 | C14: 상급 스태프 | D14: 최상급 무기 | F14: 3 | J14: 0.1 | L14: 314030 | M14: 성스러운 일격 | N14: 적 모든 유닛에게 150% 대미지를 주고, 입힌 피해만큼 체력을 회복한다. | O14: 50 | P14: 0 | Q14: 1 | R14: 2 | V14: 1.5
A15: 310501 | B15: 나이트 | C15: 하급 검 | D15: 기본 제공 무기 | F15: 1 | L15: 315010 | M15: 베어가르기 | N15: 적 유닛 1명에게 150% 대미지를 준다. (전열 우선) | O15: 10 | P15: 0 | Q15: 0 | R15: 0 | V15: 1.5
A16: 310502 | B16: 나이트 | C16: 중급 검 | D16: 후열 특화 무기 | F16: 2 | H16: 0.07 | J16: 0.07 | L16: 315020 | M16: 환영 공격 | N16: 자신이 후열일 경우 후열 공격이 가능하다. 근거리 공격 180% 대미지를 준다. (후열이 아닌 경우 전열 우선) | O16: 30 | P16: 0 | Q16: 1 | R16: 0 | V16: 1.8
A17: 310503 | B17: 나이트 | C17: 상급 검 | D17: 최상급 무기 | F17: 3 | H17: 0.1 | L17: 315030 | M17: 강습 | N17: 적 유닛 1명에게 250% 대미지를 준다. (전열 우선) | O17: 50 | P17: 0 | Q17: 0 | R17: 0 | V17: 2.5

Sheet 스탯 시뮬레이터
A1: 범례 | B1: 타 시트에서 가져오는 값
B2: 이 시트에서 바꾸는 값
B3: 이 시트에서 계산되는 값
B4: 고정치
A5: 1. 아군 유닛 스테이터스
B6: 파티 멤버 | C6: 클래스명 | D6: 클래스 콘셉트 | E6: 유닛 랭크 | F6: 랭크 표시 | G6: 최대 시민 호감도 | H6: 유닛 최대 체력 | I6: 유닛 공격력 | J6: 유닛 방어력 | K6: 치명타율 | L6: 반격율 | M6: 피해 경감률 | N6: 스피드
B7: 1 | C7: ='전투 시뮬레이터'!C14 -> 워리어 | D7: =IFERROR(VLOOKUP($C7,'아군 유닛'!$B$2:$F$7,2,FALSE),"") -> 체력이 높은 근거리 병종 | E7: 1 | F7: =IFERROR(VLOOKUP($E7,'성장 시스템'!$B$27:$C$41,2,FALSE),"") -> N | G7: =IFERROR(VLOOKUP(E7,'랭크별 스킬'!$L$15:$M$29,2,FALSE),"") -> 100 | H7: =IFERROR(VLOOKUP($C7,'아군 유닛'!$B$2:$J$7,COLUMN(A1)+2,FALSE),"") -> 7 | I7: =IFERROR(VLOOKUP($C7,'아군 유닛'!$B$2:$J$7,COLUMN(B1)+2,FALSE),"") -> 7 | J7: =IFERROR(VLOOKUP($C7,'아군 유닛'!$B$2:$J$7,COLUMN(C1)+2,FALSE),"") -> 6 | K7: =IFERROR(VLOOKUP($C7,'아군 유닛'!$B$2:$J$7,COLUMN(D1)+2,FALSE),"") -> 0.1 | L7: =IFERROR(VLOOKUP($C7,'아군 유닛'!$B$2:$J$7,COLUMN(E1)+2,FALSE),"") -> 0.25 | M7: =IFERROR(VLOOKUP($C7,'아군 유닛'!$B$2:$J$7,COLUMN(F1)+2,FALSE),"") -> 0.1 | N7: =IFERROR(VLOOKUP($C7,'아군 유닛'!$B$2:$J$7,COLUMN(G1)+2,FALSE),"") -> 1
B8: 2 | C8: 메이지 | D8: =IFERROR(VLOOKUP($C8,'아군 유닛'!$B$2:$F$7,2,FALSE),"") -> 단일 공격에 특화된 원거리 병종 | E8: 1 | F8: =IFERROR(VLOOKUP($E8,'성장 시스템'!$B$27:$C$41,2,FALSE),"") -> N | G8: =IFERROR(VLOOKUP(E8,'랭크별 스킬'!$L$15:$M$29,2,FALSE),"") -> 100 | H8: =IFERROR(VLOOKUP($C8,'아군 유닛'!$B$2:$J$7,COLUMN(A1)+2,FALSE),"") -> 4 | I8: =IFERROR(VLOOKUP($C8,'아군 유닛'!$B$2:$J$7,COLUMN(B1)+2,FALSE),"") -> 12 | J8: =IFERROR(VLOOKUP($C8,'아군 유닛'!$B$2:$J$7,COLUMN(C1)+2,FALSE),"") -> 4 | K8: =IFERROR(VLOOKUP($C8,'아군 유닛'!$B$2:$J$7,COLUMN(D1)+2,FALSE),"") -> 0.3 | L8: =IFERROR(VLOOKUP($C8,'아군 유닛'!$B$2:$J$7,COLUMN(E1)+2,FALSE),"") -> 0.1 | M8: =IFERROR(VLOOKUP($C8,'아군 유닛'!$B$2:$J$7,COLUMN(F1)+2,FALSE),"") -> 0.2 | N8: =IFERROR(VLOOKUP($C8,'아군 유닛'!$B$2:$J$7,COLUMN(G1)+2,FALSE),"") -> 3
B9: 3 | C9: 아처 | D9: =IFERROR(VLOOKUP($C9,'아군 유닛'!$B$2:$F$7,2,FALSE),"") -> 다중 공격에 특화된 원거리 병종 | E9: 1 | F9: =IFERROR(VLOOKUP($E9,'성장 시스템'!$B$27:$C$41,2,FALSE),"") -> N | G9: =IFERROR(VLOOKUP(E9,'랭크별 스킬'!$L$15:$M$29,2,FALSE),"") -> 100 | H9: =IFERROR(VLOOKUP($C9,'아군 유닛'!$B$2:$J$7,COLUMN(A1)+2,FALSE),"") -> 6 | I9: =IFERROR(VLOOKUP($C9,'아군 유닛'!$B$2:$J$7,COLUMN(B1)+2,FALSE),"") -> 12 | J9: =IFERROR(VLOOKUP($C9,'아군 유닛'!$B$2:$J$7,COLUMN(C1)+2,FALSE),"") -> 2 | K9: =IFERROR(VLOOKUP($C9,'아군 유닛'!$B$2:$J$7,COLUMN(D1)+2,FALSE),"") -> 0.2 | L9: =IFERROR(VLOOKUP($C9,'아군 유닛'!$B$2:$J$7,COLUMN(E1)+2,FALSE),"") -> 0.05 | M9: =IFERROR(VLOOKUP($C9,'아군 유닛'!$B$2:$J$7,COLUMN(F1)+2,FALSE),"") -> 0.1 | N9: =IFERROR(VLOOKUP($C9,'아군 유닛'!$B$2:$J$7,COLUMN(G1)+2,FALSE),"") -> 2
B10: 4 | C10: 클레릭 | D10: =IFERROR(VLOOKUP($C10,'아군 유닛'!$B$2:$F$7,2,FALSE),"") -> 회복이 가능한 원거리 병종 | E10: 1 | F10: =IFERROR(VLOOKUP($E10,'성장 시스템'!$B$27:$C$41,2,FALSE),"") -> N | G10: =IFERROR(VLOOKUP(E10,'랭크별 스킬'!$L$15:$M$29,2,FALSE),"") -> 100 | H10: =IFERROR(VLOOKUP($C10,'아군 유닛'!$B$2:$J$7,COLUMN(A1)+2,FALSE),"") -> 6 | I10: =IFERROR(VLOOKUP($C10,'아군 유닛'!$B$2:$J$7,COLUMN(B1)+2,FALSE),"") -> 8 | J10: =IFERROR(VLOOKUP($C10,'아군 유닛'!$B$2:$J$7,COLUMN(C1)+2,FALSE),"") -> 6 | K10: =IFERROR(VLOOKUP($C10,'아군 유닛'!$B$2:$J$7,COLUMN(D1)+2,FALSE),"") -> 0.1 | L10: =IFERROR(VLOOKUP($C10,'아군 유닛'!$B$2:$J$7,COLUMN(E1)+2,FALSE),"") -> 0.1 | M10: =IFERROR(VLOOKUP($C10,'아군 유닛'!$B$2:$J$7,COLUMN(F1)+2,FALSE),"") -> 0.15 | N10: =IFERROR(VLOOKUP($C10,'아군 유닛'!$B$2:$J$7,COLUMN(G1)+2,FALSE),"") -> 2
A12: 2. 유닛 레벨업 스테이터스
B13: 파티 멤버 | C13: 클래스명 | D13: 클래스 콘셉트 | E13: 유닛 랭크 | F13: 랭크 표시 | G13: 최대 시민 호감도 | H13: 랭크업 유닛 최대 체력 = 유닛 최대 체력 + {(레벨업 기본 보정치 + 클래스 기본 보정치)} × 레벨 | I13: 랭크업 유닛 공격력 = 유닛 공격력 + {(레벨업 기본 보정치 + 클래스 기본 보정치)} × 레벨 | J13: 랭크업 유닛 방어력 = 유닛 방어력 + {(레벨업 기본 보정치 + 클래스 기본 보정치)} × 레벨
B14: 1 | C14: =$C$7 -> 워리어 | D14: =$D$7 -> 체력이 높은 근거리 병종 | E14: ='전투 시뮬레이터'!D14 -> 1 | F14: =IFERROR(VLOOKUP($E14,'성장 시스템'!$B$27:$C$41,2,FALSE),"") -> N | G14: =IFERROR(VLOOKUP(E14,'랭크별 스킬'!$L$15:$M$29,2,FALSE),"") -> 100 | H14: =H7+('성장 시스템'!$C$12+VLOOKUP($C$14,'성장 시스템'!$B$15:$E$19,2,FALSE))*($E$14-1) -> 7 | I14: =I7+('성장 시스템'!$C$12+VLOOKUP($C$14,'성장 시스템'!$B$15:$E$19,3,FALSE))*($E$14-1) -> 7 | J14: =J7+('성장 시스템'!$C$12+VLOOKUP($C$14,'성장 시스템'!$B$15:$E$19,4,FALSE))*($E$14-1) -> 6
B15: 2 | C15: =$C$8 -> 메이지 | D15: =$D$8 -> 단일 공격에 특화된 원거리 병종 | E15: 2 | F15: =IFERROR(VLOOKUP($E15,'성장 시스템'!$B$27:$C$41,2,FALSE),"") -> M | G15: =IFERROR(VLOOKUP(E15,'랭크별 스킬'!$L$15:$M$29,2,FALSE),"") -> 110 | H15: =H8+('성장 시스템'!$C$12+VLOOKUP($C15,'성장 시스템'!$B$15:$E$19,2,FALSE))*($E15-1) -> 5 | I15: =I8+('성장 시스템'!$C$12+VLOOKUP($C$15,'성장 시스템'!$B$15:$E$19,3,FALSE))*($E$15-1) -> 15 | J15: =J8+('성장 시스템'!$C$12+VLOOKUP($C$15,'성장 시스템'!$B$15:$E$19,4,FALSE))*($E$15-1) -> 5
B16: 3 | C16: =$C$9 -> 아처 | D16: =$D$9 -> 다중 공격에 특화된 원거리 병종 | E16: 3 | F16: =IFERROR(VLOOKUP($E16,'성장 시스템'!$B$27:$C$41,2,FALSE),"") -> L | G16: =IFERROR(VLOOKUP(E16,'랭크별 스킬'!$L$15:$M$29,2,FALSE),"") -> 110 | H16: =H9+('성장 시스템'!$C$12+VLOOKUP($C$16,'성장 시스템'!$B$15:$E$19,2,FALSE))*($E$16-1) -> 10 | I16: =I9+('성장 시스템'!$C$12+VLOOKUP($C$16,'성장 시스템'!$B$15:$E$19,3,FALSE))*($E$16-1) -> 16 | J16: =J9+('성장 시스템'!$C$12+VLOOKUP($C$16,'성장 시스템'!$B$15:$E$19,4,FALSE))*($E$16-1) -> 4
B17: 4 | C17: =$C$10 -> 클레릭 | D17: =$D$10 -> 회복이 가능한 원거리 병종 | E17: 4 | F17: =IFERROR(VLOOKUP($E17,'성장 시스템'!$B$27:$C$41,2,FALSE),"") -> K | G17: =IFERROR(VLOOKUP(E17,'랭크별 스킬'!$L$15:$M$29,2,FALSE),"") -> 120 | H17: =H10+('성장 시스템'!$C$12+VLOOKUP($C$17,'성장 시스템'!$B$15:$E$19,2,FALSE))*($E$17-1) -> 12 | I17: =I10+('성장 시스템'!$C$12+VLOOKUP($C$17,'성장 시스템'!$B$15:$E$19,3,FALSE))*($E$17-1) -> 11 | J17: =J10+('성장 시스템'!$C$12+VLOOKUP($C$17,'성장 시스템'!$B$15:$E$19,4,FALSE))*($E$17-1) -> 12
A19: 3. 유닛 무기 스테이터스
D20: 무기 추가 스테이터스
B21: 파티 멤버 | C21: 착용 무기 | D21: 최대 체력 증가량 | E21: 공격력 증가량 | F21: 방어력 증가량 | G21: 치명타율 증가량 | H21: 반격율 증가량 | I21: 피해 경감 확률 증가량 | J21: 스피드 증가량
B22: 1 | C22: 하급 도끼 | D22: =IFERROR(VLOOKUP($C22,무기!$C$2:$K$14,3,FALSE),"") -> 0 | E22: =IFERROR(VLOOKUP($C22,무기!$C$2:$K$14,4,FALSE),"") -> 1 | F22: =IFERROR(VLOOKUP($C22,무기!$C$2:$K$14,5,FALSE),"") -> 0 | G22: =IFERROR(VLOOKUP($C22,무기!$C$2:$K$14,6,FALSE),"") -> 0 | H22: =IFERROR(VLOOKUP($C22,무기!$C$2:$K$14,7,FALSE),"") -> 0 | I22: =IFERROR(VLOOKUP($C22,무기!$C$2:$K$14,8,FALSE),"") -> 0 | J22: =IFERROR(VLOOKUP($C22,무기!$C$2:$K$14,9,FALSE),"") -> 0
B23: 2 | C23: 하급 완드 | D23: =IFERROR(VLOOKUP($C23,무기!$C$2:$K$14,3,FALSE),"") -> 0 | E23: =IFERROR(VLOOKUP($C23,무기!$C$2:$K$14,4,FALSE),"") -> 1 | F23: =IFERROR(VLOOKUP($C23,무기!$C$2:$K$14,5,FALSE),"") -> 0 | G23: =IFERROR(VLOOKUP($C23,무기!$C$2:$K$14,6,FALSE),"") -> 0 | H23: =IFERROR(VLOOKUP($C23,무기!$C$2:$K$14,7,FALSE),"") -> 0 | I23: =IFERROR(VLOOKUP($C23,무기!$C$2:$K$14,8,FALSE),"") -> 0 | J23: =IFERROR(VLOOKUP($C23,무기!$C$2:$K$14,9,FALSE),"") -> 0
B24: 3 | C24: 하급 활 | D24: =IFERROR(VLOOKUP($C24,무기!$C$2:$K$14,3,FALSE),"") -> 0 | E24: =IFERROR(VLOOKUP($C24,무기!$C$2:$K$14,4,FALSE),"") -> 1 | F24: =IFERROR(VLOOKUP($C24,무기!$C$2:$K$14,5,FALSE),"") -> 0 | G24: =IFERROR(VLOOKUP($C24,무기!$C$2:$K$14,6,FALSE),"") -> 0 | H24: =IFERROR(VLOOKUP($C24,무기!$C$2:$K$14,7,FALSE),"") -> 0 | I24: =IFERROR(VLOOKUP($C24,무기!$C$2:$K$14,8,FALSE),"") -> 0 | J24: =IFERROR(VLOOKUP($C24,무기!$C$2:$K$14,9,FALSE),"") -> 0
B25: 4 | C25: 하급 스태프 | D25: =IFERROR(VLOOKUP($C25,무기!$C$2:$K$14,3,FALSE),"") -> 0 | E25: =IFERROR(VLOOKUP($C25,무기!$C$2:$K$14,4,FALSE),"") -> 1 | F25: =IFERROR(VLOOKUP($C25,무기!$C$2:$K$14,5,FALSE),"") -> 0 | G25: =IFERROR(VLOOKUP($C25,무기!$C$2:$K$14,6,FALSE),"") -> 0 | H25: =IFERROR(VLOOKUP($C25,무기!$C$2:$K$14,7,FALSE),"") -> 0 | I25: =IFERROR(VLOOKUP($C25,무기!$C$2:$K$14,8,FALSE),"") -> 0 | J25: =IFERROR(VLOOKUP($C25,무기!$C$2:$K$14,9,FALSE),"") -> 0
A27: 4. 유닛 스킬
B28: 파티 멤버 | C28: 클래스명 | D28: 유닛 레벨 | E28: 착용 직업 스킬 | F28: 착용 직업 스킬 설명 | G28: 착용 무기 | H28: 착용 무기 스킬 | I28: 착용 무기 스킬 설명
B29: 1 | C29: =$C$7 -> 워리어 | D29: =$E$14 -> 1 | E29: 도발 베기 | F29: =IFERROR(VLOOKUP($E29,'직업 스킬'!$D$3:$E$30,2,FALSE),"") -> 적 1명에게 120% 대미지를 입히고, 1턴 동안 해당 대상이 단일 공격 시 자신을 공격하게 한다. (적 전열이 있을 경우, 전열 우선 공격) | G29: =$C$22 -> 하급 도끼 | H29: =IFERROR(VLOOKUP($G29,무기!$C$3:$M$14,11,FALSE),"") -> 강타 | I29: =IFERROR(VLOOKUP($G29,무기!$C$3:$N$14,12,FALSE),"") -> 적 유닛 1명에게 150% 대미지를 준다. (전열 우선)
B30: 2 | C30: =$C$8 -> 메이지 | D30: =$E$15 -> 2 | E30: 파이어볼 | F30: =IFERROR(VLOOKUP($E30,'직업 스킬'!$D$3:$E$30,2,FALSE),"") -> 적 1명에게 100% 대미지를 입힌다. | G30: =$C$23 -> 하급 완드 | H30: =IFERROR(VLOOKUP($G30,무기!$C$3:$M$14,11,FALSE),"") -> 매직 미사일 | I30: =IFERROR(VLOOKUP($G30,무기!$C$3:$N$14,12,FALSE),"") -> 적 유닛 1명에게 150% 대미지를 준다.
B31: 3 | C31: =$C$9 -> 아처 | D31: =$E$16 -> 3 | E31: 정밀 사격 | F31: =IFERROR(VLOOKUP($E31,'직업 스킬'!$D$3:$E$30,2,FALSE),"") -> 적 1명에게 100% 대미지를 입힌다. | G31: =$C$24 -> 하급 활 | H31: =IFERROR(VLOOKUP($G31,무기!$C$3:$M$14,11,FALSE),"") -> 정밀 조준 | I31: =IFERROR(VLOOKUP($G31,무기!$C$3:$N$14,12,FALSE),"") -> 적 유닛 1명에게 150% 대미지를 준다.
B32: 4 | C32: =$C$10 -> 클레릭 | D32: =$E$17 -> 4 | E32: 힐 | F32: =IFERROR(VLOOKUP($E32,'직업 스킬'!$D$3:$E$30,2,FALSE),"") -> 아군 1명 체력 30% 회복, IP 10 고정 회복 | G32: =$C$25 -> 하급 스태프 | H32: =IFERROR(VLOOKUP($G32,무기!$C$3:$M$14,11,FALSE),"") -> 성광 | I32: =IFERROR(VLOOKUP($G32,무기!$C$3:$N$14,12,FALSE),"") -> 적 유닛 1명에게 150% 대미지를 준다.
A34: 5. 최종 스테이터스
E35: 캐릭터 최종 스테이터스
B36: 파티 멤버 | C36: 클래스명 | D36: 유닛 레벨 | E36: 최대 체력 | F36: 공격력 | G36: 방어력 | H36: 치명타율 | I36: 반격율 | J36: 피해 경감률 | K36: 스피드 | L36: 착용 직업 스킬 | M36: 착용 무기 | N36: 착용 무기 스킬
B37: 1 | C37: =$C$7 -> 워리어 | D37: =$E$14 -> 1 | E37: =SUM(H14,D22) -> 7 | F37: =SUM(I14,E22) -> 8 | G37: =SUM(J14,F22) -> 6 | H37: =MIN(SUM(K7,G22),70%) -> 0.1 | I37: =MIN(SUM(L7,H22),70%) -> 0.25 | J37: =MIN(SUM(M7,I22),70%) -> 0.1 | K37: =SUM(N7,J22) -> 1 | L37: =$E$29 -> 도발 베기 | M37: =$C$22 -> 하급 도끼 | N37: =$H$29 -> 강타
B38: 2 | C38: =$C$8 -> 메이지 | D38: =$E$15 -> 2 | E38: =SUM(H15,D23) -> 5 | F38: =SUM(I15,E23) -> 16 | G38: =SUM(J15,F23) -> 5 | H38: =MIN(SUM(K8,G23),70%) -> 0.3 | I38: =MIN(SUM(L8,H23),70%) -> 0.1 | J38: =MIN(SUM(M8,I23),70%) -> 0.2 | K38: =SUM(N8,J23) -> 3 | L38: =$E$30 -> 파이어볼 | M38: =$C$23 -> 하급 완드 | N38: =$H$30 -> 매직 미사일
B39: 3 | C39: =$C$9 -> 아처 | D39: =$E$16 -> 3 | E39: =SUM(H16,D24) -> 10 | F39: =SUM(I16,E24) -> 17 | G39: =SUM(J16,F24) -> 4 | H39: =MIN(SUM(K9,G24),70%) -> 0.2 | I39: =MIN(SUM(L9,H24),70%) -> 0.05 | J39: =MIN(SUM(M9,I24),70%) -> 0.1 | K39: =SUM(N9,J24) -> 2 | L39: =$E$31 -> 정밀 사격 | M39: =$C$24 -> 하급 활 | N39: =$H$31 -> 정밀 조준
B40: 4 | C40: =$C$10 -> 클레릭 | D40: =$E$17 -> 4 | E40: =SUM(H17,D25) -> 12 | F40: =SUM(I17,E25) -> 12 | G40: =SUM(J17,F25) -> 12 | H40: =MIN(SUM(K10,G25),70%) -> 0.1 | I40: =MIN(SUM(L10,H25),70%) -> 0.1 | J40: =MIN(SUM(M10,I25),70%) -> 0.15 | K40: =SUM(N10,J25) -> 2 | L40: =$E$32 -> 힐 | M40: =$C$25 -> 하급 스태프 | N40: =$H$32 -> 성광

Sheet 전투 시뮬레이터
A2: 1. 전투 시뮬레이터 목표 및 개요 (1:1 기준)
B3: 본 시뮬레이터는 1:1 전투 기준에서 클래스별 전투 성능과 전투 소요 턴을 검증하기 위한 도구이다. 프로토타입 기준 목표 전투 시간은 다음과 같다: - 공격형 클래스: 2~3턴 내 승리 - 밸런스형 클래스: 3~4턴 내 승리 - 방어형 클래스: 4~6턴 내 승리
A5: 2. 대미지 계산 공식
B6: 기본 대미지는 다음 순서로 계산한다. 1) 공격력과 방어력의 차이를 구한다. damageBase = 공격력 - 방어력 2) 스킬 계수를 곱한다. damageBase = damageBase × 스킬 계수 3) 호감도 보정치를 곱한다. damageBase = damageBase × (현재 호감도 / 100) 4) 계산 결과를 정수로 변환한다. 소수점이 발생할 경우, 소수 첫째 자리에서 반올림한다. (예: 14.4 → 14, 16.5 → 17) 최종 대미지는 다음 규칙을 따른다. 1) 기본 대미지가 2 미만일 경우, 2로 고정한다. (음수 포함) 2) 그 외의 경우, 기본 대미지를 그대로 사용한다.
A8: 2. 전투 시뮬레이터
B9: 범례 | C9: 타 시트에서 가져오는 값
C10: 이 시트에서 바꾸는 값
C11: 이 시트에서 계산되는 값 | O11: 기본 대미지 최소치
C12: 고정치 | G12: 최종 스테이터스 | O12: 2
C13: 유닛명 | D13: 유닛 레벨 | E13: 최대 호감도 | F13: 현재 호감도 | G13: 최종 체력 | H13: 최종 공격력 | I13: 최종 방어력 | J13: 최종 치명타율 (미사용) | K13: 최종 반격율 (미사용) | L13: 최종 회피율 (미사용) | M13: 최종 스피드 (미사용) | N13: 스킬 계수 | O13: 기본 대미지
B14: 아군 유닛 그룹 | C14: 워리어 | D14: 1 | E14: =VLOOKUP(D14,'스탯 시뮬레이터'!E14:G14,3,FALSE) -> 100 | F14: 100 | G14: =IFERROR(VLOOKUP($C14,'스탯 시뮬레이터'!$C$37:$K$37,COLUMN(A1)+2,FALSE),"") -> 7 | H14: =IFERROR(VLOOKUP($C14,'스탯 시뮬레이터'!$C$37:$K$37,COLUMN(B1)+2,FALSE),"") -> 8 | I14: =IFERROR(VLOOKUP($C14,'스탯 시뮬레이터'!$C$37:$K$37,COLUMN(C1)+2,FALSE),"") -> 6 | J14: =IFERROR(VLOOKUP($C14,'스탯 시뮬레이터'!$C$37:$K$37,COLUMN(D1)+2,FALSE),"") -> 0.1 | K14: =IFERROR(VLOOKUP($C14,'스탯 시뮬레이터'!$C$37:$K$37,COLUMN(E1)+2,FALSE),"") -> 0.25 | L14: =IFERROR(VLOOKUP($C14,'스탯 시뮬레이터'!$C$37:$K$37,COLUMN(F1)+2,FALSE),"") -> 0.1 | M14: =IFERROR(VLOOKUP($C14,'스탯 시뮬레이터'!$C$37:$K$37,COLUMN(G1)+2,FALSE),"") -> 1 | N14: 1 | O14: =MAX(ROUND((H14-I15)*N14*F14/100, 0), O12) -> 2
B15: 적군 유닛 그룹 | C15: LowerMonster | G15: =IFERROR(VLOOKUP($C15,'적군 유닛'!$B$3:$J$5,COLUMN(A1)+2,FALSE),"") -> 12 | H15: =IFERROR(VLOOKUP($C15,'적군 유닛'!$B$3:$J$5,COLUMN(B1)+2,FALSE),"") -> 6 | I15: =IFERROR(VLOOKUP($C15,'적군 유닛'!$B$3:$J$5,COLUMN(C1)+2,FALSE),"") -> 6 | J15: =IFERROR(VLOOKUP($C15,'적군 유닛'!$B$3:$J$5,COLUMN(D1)+2,FALSE),"") -> 0.1 | K15: =IFERROR(VLOOKUP($C15,'적군 유닛'!$B$3:$J$5,COLUMN(E1)+2,FALSE),"") -> 0.1 | L15: =IFERROR(VLOOKUP($C15,'적군 유닛'!$B$3:$J$5,COLUMN(F1)+2,FALSE),"") -> 0.1 | M15: =IFERROR(VLOOKUP($C15,'적군 유닛'!$B$3:$J$5,COLUMN(G1)+2,FALSE),"") -> 2 | N15: 1 | O15: =MAX(ROUND((H15-I14)*N15,0),O12) -> 2
B19: 턴수 | C19: 적 > 아군 공격 시 남은 아군 체력 | D19: 아군 > 적 공격 시 남은 적 체력
B20: 0 | C20: =G14 -> 7 | D20: =G15 -> 12
B21: 1 | C21: =C20-$O$15 -> 5 | D21: =D20-$O$14 -> 10
B22: 2 | C22: =C21-$O$15 -> 3 | D22: =D21-$O$14 -> 8
B23: 3 | C23: =C22-$O$15 -> 1 | D23: =D22-$O$14 -> 6
B24: 4 | C24: =C23-$O$15 -> -1 | D24: =D23-$O$14 -> 4
B25: 5 | C25: =C24-$O$15 -> -3 | D25: =D24-$O$14 -> 2
B26: 6 | C26: =C25-$O$15 -> -5 | D26: =D25-$O$14 -> 0
B27: 7 | C27: =C26-$O$15 -> -7 | D27: =D26-$O$14 -> -2
B28: 8 | C28: =C27-$O$15 -> -9 | D28: =D27-$O$14 -> -4
B29: 9 | C29: =C28-$O$15 -> -11 | D29: =D28-$O$14 -> -6
B30: 10 | C30: =C29-$O$15 -> -13 | D30: =D29-$O$14 -> -8
B31: 걸린 턴 | C31: =COUNTIF(C20:C30,">0")+1 -> 5 | D31: =COUNTIF(D20:D30,">0")+1 -> 7

Sheet 랭크별 스킬
A1: 현재 클래스 | B1: 현재 랭크 | C1: 사용 가능 스킬1 | D1: 사용 가능 스킬2 | E1: 사용 가능 스킬3 | F1: 사용 가능 스킬4 | G1: 사용 가능 스킬5 | H1: 사용 가능 스킬6 | I1: 사용 가능 스킬7 | L1: 현재 클래스 | M1: 착용 가능 무기1 | N1: 착용 가능 무기2 | O1: 착용 가능 무기3
A2: ='스탯 시뮬레이터'!C7 -> 워리어 | B2: ='스탯 시뮬레이터'!E14 -> 1 | C2: =IFERROR(INDEX($C$8:$I$114,$J2,COLUMN(A1))&"","") -> 도발 베기 | D2: =IFERROR(INDEX($C$8:$I$114,$J2,COLUMN(B1))&"","") | E2: =IFERROR(INDEX($C$8:$I$114,$J2,COLUMN(C1))&"","") | F2: =IFERROR(INDEX($C$8:$I$114,$J2,COLUMN(D1))&"","") | G2: =IFERROR(INDEX($C$8:$I$114,$J2,COLUMN(E1))&"","") | H2: =IFERROR(INDEX($C$8:$I$114,$J2,COLUMN(F1))&"","") | I2: =IFERROR(INDEX($C$8:$I$114,$J2,COLUMN(G1))&"","") | J2: {=MATCH(1,($A$8:$A$114=$A2)*($B$8:$B$114=$B2),0)} -> 1 | L2: =A2 -> 워리어 | M2: =IFERROR(VLOOKUP($L2,$L$8:$O$12,COLUMN(A1)+1,FALSE),"") -> 하급 도끼 | N2: =IFERROR(VLOOKUP($L2,$L$8:$O$12,COLUMN(B1)+1,FALSE),"") -> 중급 도끼 | O2: =IFERROR(VLOOKUP($L2,$L$8:$O$12,COLUMN(C1)+1,FALSE),"") -> 상급 도끼
A3: ='스탯 시뮬레이터'!C8 -> 메이지 | B3: ='스탯 시뮬레이터'!E15 -> 2 | C3: =IFERROR(INDEX($C$8:$I$114,$J3,COLUMN(A2))&"","") -> 파이어볼 | D3: =IFERROR(INDEX($C$8:$I$114,$J3,COLUMN(B2))&"","") | E3: =IFERROR(INDEX($C$8:$I$114,$J3,COLUMN(C2))&"","") | F3: =IFERROR(INDEX($C$8:$I$114,$J3,COLUMN(D2))&"","") | G3: =IFERROR(INDEX($C$8:$I$114,$J3,COLUMN(E2))&"","") | H3: =IFERROR(INDEX($C$8:$I$114,$J3,COLUMN(F2))&"","") | I3: =IFERROR(INDEX($C$8:$I$114,$J3,COLUMN(G2))&"","") | J3: {=MATCH(1,($A$8:$A$114=$A3)*($B$8:$B$114=$B3),0)} -> 32 | L3: =A3 -> 메이지 | M3: =IFERROR(VLOOKUP($L3,$L$8:$O$12,COLUMN(A2)+1,FALSE),"") -> 하급 완드 | N3: =IFERROR(VLOOKUP($L3,$L$8:$O$12,COLUMN(B2)+1,FALSE),"") -> 중급 완드 | O3: =IFERROR(VLOOKUP($L3,$L$8:$O$12,COLUMN(C2)+1,FALSE),"") -> 상급 완드
A4: ='스탯 시뮬레이터'!C9 -> 아처 | B4: ='스탯 시뮬레이터'!E16 -> 3 | C4: =IFERROR(INDEX($C$8:$I$114,$J4,COLUMN(A3))&"","") -> 정밀 사격 | D4: =IFERROR(INDEX($C$8:$I$114,$J4,COLUMN(B3))&"","") -> 전열 저격 | E4: =IFERROR(INDEX($C$8:$I$114,$J4,COLUMN(C3))&"","") | F4: =IFERROR(INDEX($C$8:$I$114,$J4,COLUMN(D3))&"","") | G4: =IFERROR(INDEX($C$8:$I$114,$J4,COLUMN(E3))&"","") | H4: =IFERROR(INDEX($C$8:$I$114,$J4,COLUMN(F3))&"","") | I4: =IFERROR(INDEX($C$8:$I$114,$J4,COLUMN(G3))&"","") | J4: {=MATCH(1,($A$8:$A$114=$A4)*($B$8:$B$114=$B4),0)} -> 18 | L4: =A4 -> 아처 | M4: =IFERROR(VLOOKUP($L4,$L$8:$O$12,COLUMN(A3)+1,FALSE),"") -> 하급 활 | N4: =IFERROR(VLOOKUP($L4,$L$8:$O$12,COLUMN(B3)+1,FALSE),"") -> 중급 활 | O4: =IFERROR(VLOOKUP($L4,$L$8:$O$12,COLUMN(C3)+1,FALSE),"") -> 상급 활
A5: ='스탯 시뮬레이터'!C10 -> 클레릭 | B5: ='스탯 시뮬레이터'!E17 -> 4 | C5: =IFERROR(INDEX($C$8:$I$114,$J5,COLUMN(A4))&"","") -> 힐 | D5: =IFERROR(INDEX($C$8:$I$114,$J5,COLUMN(B4))&"","") -> 신성탄 | E5: =IFERROR(INDEX($C$8:$I$114,$J5,COLUMN(C4))&"","") | F5: =IFERROR(INDEX($C$8:$I$114,$J5,COLUMN(D4))&"","") | G5: =IFERROR(INDEX($C$8:$I$114,$J5,COLUMN(E4))&"","") | H5: =IFERROR(INDEX($C$8:$I$114,$J5,COLUMN(F4))&"","") | I5: =IFERROR(INDEX($C$8:$I$114,$J5,COLUMN(G4))&"","") | J5: {=MATCH(1,($A$8:$A$114=$A5)*($B$8:$B$114=$B5),0)} -> 49 | L5: =A5 -> 클레릭 | M5: =IFERROR(VLOOKUP($L5,$L$8:$O$12,COLUMN(A4)+1,FALSE),"") -> 하급 스태프 | N5: =IFERROR(VLOOKUP($L5,$L$8:$O$12,COLUMN(B4)+1,FALSE),"") -> 중급 스태프 | O5: =IFERROR(VLOOKUP($L5,$L$8:$O$12,COLUMN(C4)+1,FALSE),"") -> 상급 스태프
A7: 클래스명 | B7: 현재 랭크 | C7: 사용 가능 스킬1 | D7: 사용 가능 스킬2 | E7: 사용 가능 스킬3 | F7: 사용 가능 스킬4 | G7: 사용 가능 스킬5 | H7: 사용 가능 스킬6 | I7: 사용 가능 스킬7 | L7: 현재 클래스 | M7: 착용 가능 무기1 | N7: 착용 가능 무기2 | O7: 착용 가능 무기3
A8: 워리어 | B8: 1 | C8: 도발 베기 | L8: 워리어 | M8: 하급 도끼 | N8: 중급 도끼 | O8: 상급 도끼
A9: 워리어 | B9: 2 | C9: 도발 베기 | L9: 아처 | M9: 하급 활 | N9: 중급 활 | O9: 상급 활
A10: 워리어 | B10: 3 | C10: 도발 베기 | D10: 일렬 베기 | L10: 메이지 | M10: 하급 완드 | N10: 중급 완드 | O10: 상급 완드
A11: 워리어 | B11: 4 | C11: 도발 베기 | D11: 일렬 베기 | L11: 클레릭 | M11: 하급 스태프 | N11: 중급 스태프 | O11: 상급 스태프
A12: 워리어 | B12: 5 | C12: 도발 베기 | D12: 일렬 베기 | E12: 관통 | L12: 나이트 | M12: 하급 검 | N12: 중급 검 | O12: 상급 검
A13: 워리어 | B13: 6 | C13: 도발 베기 | D13: 일렬 베기 | E13: 관통
A14: 워리어 | B14: 7 | C14: 도발 베기 | D14: 일렬 베기 | E14: 관통 | F14: 광역 도발 | L14: 랭크 | M14: 최대 호감도
A15: 워리어 | B15: 8 | C15: 도발 베기 | D15: 일렬 베기 | E15: 관통 | F15: 광역 도발 | L15: 1 | M15: 100
A16: 워리어 | B16: 9 | C16: 도발 베기 | D16: 일렬 베기 | E16: 관통 | F16: 광역 도발 | L16: 2 | M16: 110
A17: 워리어 | B17: 10 | C17: 도발 베기 | D17: 일렬 베기 | E17: 관통 | F17: 광역 도발 | G17: 돌파 | L17: 3 | M17: 110
A18: 워리어 | B18: 11 | C18: 도발 베기 | D18: 일렬 베기 | E18: 관통 | F18: 광역 도발 | G18: 돌파 | L18: 4 | M18: 120
A19: 워리어 | B19: 12 | C19: 도발 베기 | D19: 일렬 베기 | E19: 관통 | F19: 광역 도발 | G19: 돌파 | H19: 쌍렬 베기 | L19: 5 | M19: 120
A20: 워리어 | B20: 13 | C20: 도발 베기 | D20: 일렬 베기 | E20: 관통 | F20: 광역 도발 | G20: 돌파 | H20: 쌍렬 베기 | L20: 6 | M20: 130
A21: 워리어 | B21: 14 | C21: 도발 베기 | D21: 일렬 베기 | E21: 관통 | F21: 광역 도발 | G21: 돌파 | H21: 쌍렬 베기 | L21: 7 | M21: 130
A22: 워리어 | B22: 15 | C22: 도발 베기 | D22: 일렬 베기 | E22: 관통 | F22: 광역 도발 | G22: 돌파 | H22: 쌍렬 베기 | I22: 불굴 | L22: 8 | M22: 140
A23: 아처 | B23: 1 | C23: 정밀 사격 | L23: 9 | M23: 150
A24: 아처 | B24: 2 | C24: 정밀 사격 | L24: 10 | M24: 150
A25: 아처 | B25: 3 | C25: 정밀 사격 | D25: 전열 저격 | L25: 11 | M25: 160
A26: 아처 | B26: 4 | C26: 정밀 사격 | D26: 전열 저격 | L26: 12 | M26: 160
A27: 아처 | B27: 5 | C27: 정밀 사격 | D27: 전열 저격 | E27: 후열 저격 | L27: 13 | M27: 180
A28: 아처 | B28: 6 | C28: 정밀 사격 | D28: 전열 저격 | E28: 후열 저격 | L28: 14 | M28: 200
A29: 아처 | B29: 7 | C29: 정밀 사격 | D29: 전열 저격 | E29: 후열 저격 | F29: 연속 사격 | L29: 15 | M29: 200
A30: 아처 | B30: 8 | C30: 정밀 사격 | D30: 전열 저격 | E30: 후열 저격 | F30: 연속 사격
A31: 아처 | B31: 9 | C31: 정밀 사격 | D31: 전열 저격 | E31: 후열 저격 | F31: 연속 사격
A32: 아처 | B32: 10 | C32: 정밀 사격 | D32: 전열 저격 | E32: 후열 저격 | F32: 연속 사격 | G32: 급소 저격
A33: 아처 | B33: 11 | C33: 정밀 사격 | D33: 전열 저격 | E33: 후열 저격 | F33: 연속 사격 | G33: 급소 저격
A34: 아처 | B34: 12 | C34: 정밀 사격 | D34: 전열 저격 | E34: 후열 저격 | F34: 연속 사격 | G34: 급소 저격 | H34: 화살비
A35: 아처 | B35: 13 | C35: 정밀 사격 | D35: 전열 저격 | E35: 후열 저격 | F35: 연속 사격 | G35: 급소 저격 | H35: 화살비
A36: 아처 | B36: 14 | C36: 정밀 사격 | D36: 전열 저격 | E36: 후열 저격 | F36: 연속 사격 | G36: 급소 저격 | H36: 화살비
A37: 아처 | B37: 15 | C37: 정밀 사격 | D37: 전열 저격 | E37: 후열 저격 | F37: 연속 사격 | G37: 급소 저격 | H37: 화살비 | I37: 최후의 일격
A38: 메이지 | B38: 1 | C38: 파이어볼
A39: 메이지 | B39: 2 | C39: 파이어볼
A40: 메이지 | B40: 3 | C40: 파이어볼 | D40: 번개 확산
A41: 메이지 | B41: 4 | C41: 파이어볼 | D41: 번개 확산
...
